{
 "cells": [
  {
   "cell_type": "code",
   "execution_count": 1,
   "metadata": {},
   "outputs": [],
   "source": [
    "# Dependencies\n",
    "import numpy as np\n",
    "import pandas as pd\n",
    "%matplotlib inline\n",
    "from matplotlib import style\n",
    "style.use('fivethirtyeight')\n",
    "import matplotlib.pyplot as plt\n",
    "\n",
    "# Python SQL toolkit and Object Relational Mapper\n",
    "import sqlalchemy\n",
    "from sqlalchemy.ext.automap import automap_base\n",
    "from sqlalchemy.orm import Session\n",
    "from sqlalchemy import create_engine, func"
   ]
  },
  {
   "cell_type": "code",
   "execution_count": 2,
   "metadata": {},
   "outputs": [],
   "source": [
    "# Create the engine to connect to the SQLite file \n",
    "engine = create_engine(\"sqlite:///hawaii.sqlite\")\n",
    "\n",
    "# reflect an existing database into a new model\n",
    "Base = automap_base()\n",
    "# reflect the tables\n",
    "Base.prepare(engine, reflect=True)\n",
    "\n",
    "# Save references to each table\n",
    "Measurment = Base.classes.measurement\n",
    "Station = Base.classes.station"
   ]
  },
  {
   "cell_type": "code",
   "execution_count": 3,
   "metadata": {},
   "outputs": [],
   "source": [
    "# Create our session (link) from Python to the DB\n",
    "session = Session(engine)"
   ]
  },
  {
   "cell_type": "markdown",
   "metadata": {},
   "source": [
    "## D1: Determine the Summary Statistics for June"
   ]
  },
  {
   "cell_type": "code",
   "execution_count": 4,
   "metadata": {},
   "outputs": [],
   "source": [
    "# 1. Import the sqlalchemy extract function.\n",
    "from sqlalchemy import extract\n",
    "\n",
    "# 2. Write a query that filters the Measurement table to retrieve the temperatures for the month of June. \n",
    "june_results = session.query(Measurment.date, Measurment.tobs, Measurment.prcp).\\\n",
    "    filter(extract('month', Measurment.date)==6)"
   ]
  },
  {
   "cell_type": "code",
   "execution_count": 5,
   "metadata": {},
   "outputs": [
    {
     "data": {
      "text/plain": [
       "list"
      ]
     },
     "execution_count": 5,
     "metadata": {},
     "output_type": "execute_result"
    }
   ],
   "source": [
    "#  3. Convert the June temperatures to a list.\n",
    "june_results = session.query(Measurment.date, Measurment.tobs, Measurment.prcp).\\\n",
    "    filter(extract('month', Measurment.date)==6).all()\n",
    "type(june_results)"
   ]
  },
  {
   "cell_type": "code",
   "execution_count": 6,
   "metadata": {},
   "outputs": [
    {
     "data": {
      "text/plain": [
       "pandas.core.frame.DataFrame"
      ]
     },
     "execution_count": 6,
     "metadata": {},
     "output_type": "execute_result"
    }
   ],
   "source": [
    "# 4. Create a DataFrame from the list of temperatures for the month of June. \n",
    "june_df = pd.DataFrame(june_results, columns = [\"Date\", \"June Temps\", \"June Precipitaion\"])\n",
    "type(june_df)"
   ]
  },
  {
   "cell_type": "code",
   "execution_count": 7,
   "metadata": {},
   "outputs": [
    {
     "data": {
      "text/html": [
       "<div>\n",
       "<style scoped>\n",
       "    .dataframe tbody tr th:only-of-type {\n",
       "        vertical-align: middle;\n",
       "    }\n",
       "\n",
       "    .dataframe tbody tr th {\n",
       "        vertical-align: top;\n",
       "    }\n",
       "\n",
       "    .dataframe thead th {\n",
       "        text-align: right;\n",
       "    }\n",
       "</style>\n",
       "<table border=\"1\" class=\"dataframe\">\n",
       "  <thead>\n",
       "    <tr style=\"text-align: right;\">\n",
       "      <th></th>\n",
       "      <th>June Temps</th>\n",
       "      <th>June Precipitaion</th>\n",
       "    </tr>\n",
       "  </thead>\n",
       "  <tbody>\n",
       "    <tr>\n",
       "      <th>count</th>\n",
       "      <td>1700.000000</td>\n",
       "      <td>1574.000000</td>\n",
       "    </tr>\n",
       "    <tr>\n",
       "      <th>mean</th>\n",
       "      <td>74.944118</td>\n",
       "      <td>0.136360</td>\n",
       "    </tr>\n",
       "    <tr>\n",
       "      <th>std</th>\n",
       "      <td>3.257417</td>\n",
       "      <td>0.335731</td>\n",
       "    </tr>\n",
       "    <tr>\n",
       "      <th>min</th>\n",
       "      <td>64.000000</td>\n",
       "      <td>0.000000</td>\n",
       "    </tr>\n",
       "    <tr>\n",
       "      <th>25%</th>\n",
       "      <td>73.000000</td>\n",
       "      <td>0.000000</td>\n",
       "    </tr>\n",
       "    <tr>\n",
       "      <th>50%</th>\n",
       "      <td>75.000000</td>\n",
       "      <td>0.020000</td>\n",
       "    </tr>\n",
       "    <tr>\n",
       "      <th>75%</th>\n",
       "      <td>77.000000</td>\n",
       "      <td>0.120000</td>\n",
       "    </tr>\n",
       "    <tr>\n",
       "      <th>max</th>\n",
       "      <td>85.000000</td>\n",
       "      <td>4.430000</td>\n",
       "    </tr>\n",
       "  </tbody>\n",
       "</table>\n",
       "</div>"
      ],
      "text/plain": [
       "        June Temps  June Precipitaion\n",
       "count  1700.000000        1574.000000\n",
       "mean     74.944118           0.136360\n",
       "std       3.257417           0.335731\n",
       "min      64.000000           0.000000\n",
       "25%      73.000000           0.000000\n",
       "50%      75.000000           0.020000\n",
       "75%      77.000000           0.120000\n",
       "max      85.000000           4.430000"
      ]
     },
     "execution_count": 7,
     "metadata": {},
     "output_type": "execute_result"
    }
   ],
   "source": [
    "# 5. Calculate and print out the summary statistics for the June temperature DataFrame.\n",
    "june_df.describe()"
   ]
  },
  {
   "cell_type": "markdown",
   "metadata": {},
   "source": [
    "## D2: Determine the Summary Statistics for December"
   ]
  },
  {
   "cell_type": "code",
   "execution_count": 8,
   "metadata": {},
   "outputs": [],
   "source": [
    "# 6. Write a query that filters the Measurement table to retrieve the temperatures for the month of December.\n",
    "december_results = session.query(Measurment.date, Measurment.tobs, Measurment.prcp).\\\n",
    "    filter(extract('month', Measurment.date)==12)"
   ]
  },
  {
   "cell_type": "code",
   "execution_count": 9,
   "metadata": {},
   "outputs": [
    {
     "data": {
      "text/plain": [
       "list"
      ]
     },
     "execution_count": 9,
     "metadata": {},
     "output_type": "execute_result"
    }
   ],
   "source": [
    "# 7. Convert the December temperatures to a list.\n",
    "december_results = session.query(Measurment.date, Measurment.tobs, Measurment.prcp).\\\n",
    "    filter(extract('month', Measurment.date)==12).all()\n",
    "type(december_results)"
   ]
  },
  {
   "cell_type": "code",
   "execution_count": 10,
   "metadata": {},
   "outputs": [
    {
     "data": {
      "text/plain": [
       "pandas.core.frame.DataFrame"
      ]
     },
     "execution_count": 10,
     "metadata": {},
     "output_type": "execute_result"
    }
   ],
   "source": [
    "# 8. Create a DataFrame from the list of temperatures for the month of December. \n",
    "december_df = pd.DataFrame(december_results, columns = [\"Date\", \"December Temps\", \"December Precipitaion\"])\n",
    "type(december_df)"
   ]
  },
  {
   "cell_type": "code",
   "execution_count": 12,
   "metadata": {},
   "outputs": [
    {
     "data": {
      "text/html": [
       "<div>\n",
       "<style scoped>\n",
       "    .dataframe tbody tr th:only-of-type {\n",
       "        vertical-align: middle;\n",
       "    }\n",
       "\n",
       "    .dataframe tbody tr th {\n",
       "        vertical-align: top;\n",
       "    }\n",
       "\n",
       "    .dataframe thead th {\n",
       "        text-align: right;\n",
       "    }\n",
       "</style>\n",
       "<table border=\"1\" class=\"dataframe\">\n",
       "  <thead>\n",
       "    <tr style=\"text-align: right;\">\n",
       "      <th></th>\n",
       "      <th>December Temps</th>\n",
       "      <th>December Precipitaion</th>\n",
       "    </tr>\n",
       "  </thead>\n",
       "  <tbody>\n",
       "    <tr>\n",
       "      <th>count</th>\n",
       "      <td>1517.000000</td>\n",
       "      <td>1405.000000</td>\n",
       "    </tr>\n",
       "    <tr>\n",
       "      <th>mean</th>\n",
       "      <td>71.041529</td>\n",
       "      <td>0.216819</td>\n",
       "    </tr>\n",
       "    <tr>\n",
       "      <th>std</th>\n",
       "      <td>3.745920</td>\n",
       "      <td>0.541399</td>\n",
       "    </tr>\n",
       "    <tr>\n",
       "      <th>min</th>\n",
       "      <td>56.000000</td>\n",
       "      <td>0.000000</td>\n",
       "    </tr>\n",
       "    <tr>\n",
       "      <th>25%</th>\n",
       "      <td>69.000000</td>\n",
       "      <td>0.000000</td>\n",
       "    </tr>\n",
       "    <tr>\n",
       "      <th>50%</th>\n",
       "      <td>71.000000</td>\n",
       "      <td>0.030000</td>\n",
       "    </tr>\n",
       "    <tr>\n",
       "      <th>75%</th>\n",
       "      <td>74.000000</td>\n",
       "      <td>0.150000</td>\n",
       "    </tr>\n",
       "    <tr>\n",
       "      <th>max</th>\n",
       "      <td>83.000000</td>\n",
       "      <td>6.420000</td>\n",
       "    </tr>\n",
       "  </tbody>\n",
       "</table>\n",
       "</div>"
      ],
      "text/plain": [
       "       December Temps  December Precipitaion\n",
       "count     1517.000000            1405.000000\n",
       "mean        71.041529               0.216819\n",
       "std          3.745920               0.541399\n",
       "min         56.000000               0.000000\n",
       "25%         69.000000               0.000000\n",
       "50%         71.000000               0.030000\n",
       "75%         74.000000               0.150000\n",
       "max         83.000000               6.420000"
      ]
     },
     "execution_count": 12,
     "metadata": {},
     "output_type": "execute_result"
    },
    {
     "name": "stderr",
     "output_type": "stream",
     "text": [
      "Exception in callback BaseSelectorEventLoop._read_from_self()\n",
      "handle: <Handle BaseSelectorEventLoop._read_from_self()>\n",
      "Traceback (most recent call last):\n",
      "  File \"C:\\Users\\donmc\\anaconda3\\envs\\PythonData\\lib\\asyncio\\events.py\", line 145, in _run\n",
      "    self._callback(*self._args)\n",
      "  File \"C:\\Users\\donmc\\anaconda3\\envs\\PythonData\\lib\\asyncio\\selector_events.py\", line 141, in _read_from_self\n",
      "    data = self._ssock.recv(4096)\n",
      "ConnectionResetError: [WinError 10054] An existing connection was forcibly closed by the remote host\n",
      "Exception in callback BaseSelectorEventLoop._read_from_self()\n",
      "handle: <Handle BaseSelectorEventLoop._read_from_self()>\n",
      "Traceback (most recent call last):\n",
      "  File \"C:\\Users\\donmc\\anaconda3\\envs\\PythonData\\lib\\asyncio\\events.py\", line 145, in _run\n",
      "    self._callback(*self._args)\n",
      "  File \"C:\\Users\\donmc\\anaconda3\\envs\\PythonData\\lib\\asyncio\\selector_events.py\", line 141, in _read_from_self\n",
      "    data = self._ssock.recv(4096)\n",
      "ConnectionResetError: [WinError 10054] An existing connection was forcibly closed by the remote host\n",
      "Exception in callback BaseSelectorEventLoop._read_from_self()\n",
      "handle: <Handle BaseSelectorEventLoop._read_from_self()>\n",
      "Traceback (most recent call last):\n",
      "  File \"C:\\Users\\donmc\\anaconda3\\envs\\PythonData\\lib\\asyncio\\events.py\", line 145, in _run\n",
      "    self._callback(*self._args)\n",
      "  File \"C:\\Users\\donmc\\anaconda3\\envs\\PythonData\\lib\\asyncio\\selector_events.py\", line 141, in _read_from_self\n",
      "    data = self._ssock.recv(4096)\n",
      "ConnectionResetError: [WinError 10054] An existing connection was forcibly closed by the remote host\n",
      "Exception in callback BaseSelectorEventLoop._read_from_self()\n",
      "handle: <Handle BaseSelectorEventLoop._read_from_self()>\n",
      "Traceback (most recent call last):\n",
      "  File \"C:\\Users\\donmc\\anaconda3\\envs\\PythonData\\lib\\asyncio\\events.py\", line 145, in _run\n",
      "    self._callback(*self._args)\n",
      "  File \"C:\\Users\\donmc\\anaconda3\\envs\\PythonData\\lib\\asyncio\\selector_events.py\", line 141, in _read_from_self\n",
      "    data = self._ssock.recv(4096)\n",
      "ConnectionResetError: [WinError 10054] An existing connection was forcibly closed by the remote host\n",
      "Exception in callback BaseSelectorEventLoop._read_from_self()\n",
      "handle: <Handle BaseSelectorEventLoop._read_from_self()>\n",
      "Traceback (most recent call last):\n",
      "  File \"C:\\Users\\donmc\\anaconda3\\envs\\PythonData\\lib\\asyncio\\events.py\", line 145, in _run\n",
      "    self._callback(*self._args)\n",
      "  File \"C:\\Users\\donmc\\anaconda3\\envs\\PythonData\\lib\\asyncio\\selector_events.py\", line 141, in _read_from_self\n",
      "    data = self._ssock.recv(4096)\n",
      "ConnectionResetError: [WinError 10054] An existing connection was forcibly closed by the remote host\n",
      "Exception in callback BaseSelectorEventLoop._read_from_self()\n",
      "handle: <Handle BaseSelectorEventLoop._read_from_self()>\n",
      "Traceback (most recent call last):\n",
      "  File \"C:\\Users\\donmc\\anaconda3\\envs\\PythonData\\lib\\asyncio\\events.py\", line 145, in _run\n",
      "    self._callback(*self._args)\n",
      "  File \"C:\\Users\\donmc\\anaconda3\\envs\\PythonData\\lib\\asyncio\\selector_events.py\", line 141, in _read_from_self\n",
      "    data = self._ssock.recv(4096)\n",
      "ConnectionResetError: [WinError 10054] An existing connection was forcibly closed by the remote host\n",
      "Exception in callback BaseSelectorEventLoop._read_from_self()\n",
      "handle: <Handle BaseSelectorEventLoop._read_from_self()>\n",
      "Traceback (most recent call last):\n",
      "  File \"C:\\Users\\donmc\\anaconda3\\envs\\PythonData\\lib\\asyncio\\events.py\", line 145, in _run\n",
      "    self._callback(*self._args)\n",
      "  File \"C:\\Users\\donmc\\anaconda3\\envs\\PythonData\\lib\\asyncio\\selector_events.py\", line 141, in _read_from_self\n",
      "    data = self._ssock.recv(4096)\n",
      "ConnectionResetError: [WinError 10054] An existing connection was forcibly closed by the remote host\n",
      "Exception in callback BaseSelectorEventLoop._read_from_self()\n",
      "handle: <Handle BaseSelectorEventLoop._read_from_self()>\n",
      "Traceback (most recent call last):\n",
      "  File \"C:\\Users\\donmc\\anaconda3\\envs\\PythonData\\lib\\asyncio\\events.py\", line 145, in _run\n",
      "    self._callback(*self._args)\n",
      "  File \"C:\\Users\\donmc\\anaconda3\\envs\\PythonData\\lib\\asyncio\\selector_events.py\", line 141, in _read_from_self\n",
      "    data = self._ssock.recv(4096)\n",
      "ConnectionResetError: [WinError 10054] An existing connection was forcibly closed by the remote host\n",
      "Exception in callback BaseSelectorEventLoop._read_from_self()\n",
      "handle: <Handle BaseSelectorEventLoop._read_from_self()>\n",
      "Traceback (most recent call last):\n",
      "  File \"C:\\Users\\donmc\\anaconda3\\envs\\PythonData\\lib\\asyncio\\events.py\", line 145, in _run\n",
      "    self._callback(*self._args)\n",
      "  File \"C:\\Users\\donmc\\anaconda3\\envs\\PythonData\\lib\\asyncio\\selector_events.py\", line 141, in _read_from_self\n",
      "    data = self._ssock.recv(4096)\n",
      "ConnectionResetError: [WinError 10054] An existing connection was forcibly closed by the remote host\n",
      "Exception in callback BaseSelectorEventLoop._read_from_self()\n",
      "handle: <Handle BaseSelectorEventLoop._read_from_self()>\n",
      "Traceback (most recent call last):\n",
      "  File \"C:\\Users\\donmc\\anaconda3\\envs\\PythonData\\lib\\asyncio\\events.py\", line 145, in _run\n",
      "    self._callback(*self._args)\n",
      "  File \"C:\\Users\\donmc\\anaconda3\\envs\\PythonData\\lib\\asyncio\\selector_events.py\", line 141, in _read_from_self\n",
      "    data = self._ssock.recv(4096)\n",
      "ConnectionResetError: [WinError 10054] An existing connection was forcibly closed by the remote host\n",
      "Exception in callback BaseSelectorEventLoop._read_from_self()\n",
      "handle: <Handle BaseSelectorEventLoop._read_from_self()>\n",
      "Traceback (most recent call last):\n",
      "  File \"C:\\Users\\donmc\\anaconda3\\envs\\PythonData\\lib\\asyncio\\events.py\", line 145, in _run\n",
      "    self._callback(*self._args)\n",
      "  File \"C:\\Users\\donmc\\anaconda3\\envs\\PythonData\\lib\\asyncio\\selector_events.py\", line 141, in _read_from_self\n",
      "    data = self._ssock.recv(4096)\n",
      "ConnectionResetError: [WinError 10054] An existing connection was forcibly closed by the remote host\n",
      "Exception in callback BaseSelectorEventLoop._read_from_self()\n",
      "handle: <Handle BaseSelectorEventLoop._read_from_self()>\n",
      "Traceback (most recent call last):\n",
      "  File \"C:\\Users\\donmc\\anaconda3\\envs\\PythonData\\lib\\asyncio\\events.py\", line 145, in _run\n",
      "    self._callback(*self._args)\n",
      "  File \"C:\\Users\\donmc\\anaconda3\\envs\\PythonData\\lib\\asyncio\\selector_events.py\", line 141, in _read_from_self\n",
      "    data = self._ssock.recv(4096)\n",
      "ConnectionResetError: [WinError 10054] An existing connection was forcibly closed by the remote host\n",
      "Exception in callback BaseSelectorEventLoop._read_from_self()\n",
      "handle: <Handle BaseSelectorEventLoop._read_from_self()>\n",
      "Traceback (most recent call last):\n",
      "  File \"C:\\Users\\donmc\\anaconda3\\envs\\PythonData\\lib\\asyncio\\events.py\", line 145, in _run\n",
      "    self._callback(*self._args)\n",
      "  File \"C:\\Users\\donmc\\anaconda3\\envs\\PythonData\\lib\\asyncio\\selector_events.py\", line 141, in _read_from_self\n",
      "    data = self._ssock.recv(4096)\n",
      "ConnectionResetError: [WinError 10054] An existing connection was forcibly closed by the remote host\n",
      "Exception in callback BaseSelectorEventLoop._read_from_self()\n",
      "handle: <Handle BaseSelectorEventLoop._read_from_self()>\n",
      "Traceback (most recent call last):\n",
      "  File \"C:\\Users\\donmc\\anaconda3\\envs\\PythonData\\lib\\asyncio\\events.py\", line 145, in _run\n",
      "    self._callback(*self._args)\n",
      "  File \"C:\\Users\\donmc\\anaconda3\\envs\\PythonData\\lib\\asyncio\\selector_events.py\", line 141, in _read_from_self\n",
      "    data = self._ssock.recv(4096)\n",
      "ConnectionResetError: [WinError 10054] An existing connection was forcibly closed by the remote host\n",
      "Exception in callback BaseSelectorEventLoop._read_from_self()\n",
      "handle: <Handle BaseSelectorEventLoop._read_from_self()>\n",
      "Traceback (most recent call last):\n",
      "  File \"C:\\Users\\donmc\\anaconda3\\envs\\PythonData\\lib\\asyncio\\events.py\", line 145, in _run\n",
      "    self._callback(*self._args)\n",
      "  File \"C:\\Users\\donmc\\anaconda3\\envs\\PythonData\\lib\\asyncio\\selector_events.py\", line 141, in _read_from_self\n",
      "    data = self._ssock.recv(4096)\n",
      "ConnectionResetError: [WinError 10054] An existing connection was forcibly closed by the remote host\n",
      "Exception in callback BaseSelectorEventLoop._read_from_self()\n",
      "handle: <Handle BaseSelectorEventLoop._read_from_self()>\n",
      "Traceback (most recent call last):\n",
      "  File \"C:\\Users\\donmc\\anaconda3\\envs\\PythonData\\lib\\asyncio\\events.py\", line 145, in _run\n",
      "    self._callback(*self._args)\n",
      "  File \"C:\\Users\\donmc\\anaconda3\\envs\\PythonData\\lib\\asyncio\\selector_events.py\", line 141, in _read_from_self\n",
      "    data = self._ssock.recv(4096)\n",
      "ConnectionResetError: [WinError 10054] An existing connection was forcibly closed by the remote host\n"
     ]
    },
    {
     "name": "stderr",
     "output_type": "stream",
     "text": [
      "Exception in callback BaseSelectorEventLoop._read_from_self()\n",
      "handle: <Handle BaseSelectorEventLoop._read_from_self()>\n",
      "Traceback (most recent call last):\n",
      "  File \"C:\\Users\\donmc\\anaconda3\\envs\\PythonData\\lib\\asyncio\\events.py\", line 145, in _run\n",
      "    self._callback(*self._args)\n",
      "  File \"C:\\Users\\donmc\\anaconda3\\envs\\PythonData\\lib\\asyncio\\selector_events.py\", line 141, in _read_from_self\n",
      "    data = self._ssock.recv(4096)\n",
      "ConnectionResetError: [WinError 10054] An existing connection was forcibly closed by the remote host\n",
      "Exception in callback BaseSelectorEventLoop._read_from_self()\n",
      "handle: <Handle BaseSelectorEventLoop._read_from_self()>\n",
      "Traceback (most recent call last):\n",
      "  File \"C:\\Users\\donmc\\anaconda3\\envs\\PythonData\\lib\\asyncio\\events.py\", line 145, in _run\n",
      "    self._callback(*self._args)\n",
      "  File \"C:\\Users\\donmc\\anaconda3\\envs\\PythonData\\lib\\asyncio\\selector_events.py\", line 141, in _read_from_self\n",
      "    data = self._ssock.recv(4096)\n",
      "ConnectionResetError: [WinError 10054] An existing connection was forcibly closed by the remote host\n",
      "Exception in callback BaseSelectorEventLoop._read_from_self()\n",
      "handle: <Handle BaseSelectorEventLoop._read_from_self()>\n",
      "Traceback (most recent call last):\n",
      "  File \"C:\\Users\\donmc\\anaconda3\\envs\\PythonData\\lib\\asyncio\\events.py\", line 145, in _run\n",
      "    self._callback(*self._args)\n",
      "  File \"C:\\Users\\donmc\\anaconda3\\envs\\PythonData\\lib\\asyncio\\selector_events.py\", line 141, in _read_from_self\n",
      "    data = self._ssock.recv(4096)\n",
      "ConnectionResetError: [WinError 10054] An existing connection was forcibly closed by the remote host\n",
      "Exception in callback BaseSelectorEventLoop._read_from_self()\n",
      "handle: <Handle BaseSelectorEventLoop._read_from_self()>\n",
      "Traceback (most recent call last):\n",
      "  File \"C:\\Users\\donmc\\anaconda3\\envs\\PythonData\\lib\\asyncio\\events.py\", line 145, in _run\n",
      "    self._callback(*self._args)\n",
      "  File \"C:\\Users\\donmc\\anaconda3\\envs\\PythonData\\lib\\asyncio\\selector_events.py\", line 141, in _read_from_self\n",
      "    data = self._ssock.recv(4096)\n",
      "ConnectionResetError: [WinError 10054] An existing connection was forcibly closed by the remote host\n",
      "Exception in callback BaseSelectorEventLoop._read_from_self()\n",
      "handle: <Handle BaseSelectorEventLoop._read_from_self()>\n",
      "Traceback (most recent call last):\n",
      "  File \"C:\\Users\\donmc\\anaconda3\\envs\\PythonData\\lib\\asyncio\\events.py\", line 145, in _run\n",
      "    self._callback(*self._args)\n",
      "  File \"C:\\Users\\donmc\\anaconda3\\envs\\PythonData\\lib\\asyncio\\selector_events.py\", line 141, in _read_from_self\n",
      "    data = self._ssock.recv(4096)\n",
      "ConnectionResetError: [WinError 10054] An existing connection was forcibly closed by the remote host\n",
      "Exception in callback BaseSelectorEventLoop._read_from_self()\n",
      "handle: <Handle BaseSelectorEventLoop._read_from_self()>\n",
      "Traceback (most recent call last):\n",
      "  File \"C:\\Users\\donmc\\anaconda3\\envs\\PythonData\\lib\\asyncio\\events.py\", line 145, in _run\n",
      "    self._callback(*self._args)\n",
      "  File \"C:\\Users\\donmc\\anaconda3\\envs\\PythonData\\lib\\asyncio\\selector_events.py\", line 141, in _read_from_self\n",
      "    data = self._ssock.recv(4096)\n",
      "ConnectionResetError: [WinError 10054] An existing connection was forcibly closed by the remote host\n",
      "Exception in callback BaseSelectorEventLoop._read_from_self()\n",
      "handle: <Handle BaseSelectorEventLoop._read_from_self()>\n",
      "Traceback (most recent call last):\n",
      "  File \"C:\\Users\\donmc\\anaconda3\\envs\\PythonData\\lib\\asyncio\\events.py\", line 145, in _run\n",
      "    self._callback(*self._args)\n",
      "  File \"C:\\Users\\donmc\\anaconda3\\envs\\PythonData\\lib\\asyncio\\selector_events.py\", line 141, in _read_from_self\n",
      "    data = self._ssock.recv(4096)\n",
      "ConnectionResetError: [WinError 10054] An existing connection was forcibly closed by the remote host\n",
      "Exception in callback BaseSelectorEventLoop._read_from_self()\n",
      "handle: <Handle BaseSelectorEventLoop._read_from_self()>\n",
      "Traceback (most recent call last):\n",
      "  File \"C:\\Users\\donmc\\anaconda3\\envs\\PythonData\\lib\\asyncio\\events.py\", line 145, in _run\n",
      "    self._callback(*self._args)\n",
      "  File \"C:\\Users\\donmc\\anaconda3\\envs\\PythonData\\lib\\asyncio\\selector_events.py\", line 141, in _read_from_self\n",
      "    data = self._ssock.recv(4096)\n",
      "ConnectionResetError: [WinError 10054] An existing connection was forcibly closed by the remote host\n",
      "Exception in callback BaseSelectorEventLoop._read_from_self()\n",
      "handle: <Handle BaseSelectorEventLoop._read_from_self()>\n",
      "Traceback (most recent call last):\n",
      "  File \"C:\\Users\\donmc\\anaconda3\\envs\\PythonData\\lib\\asyncio\\events.py\", line 145, in _run\n",
      "    self._callback(*self._args)\n",
      "  File \"C:\\Users\\donmc\\anaconda3\\envs\\PythonData\\lib\\asyncio\\selector_events.py\", line 141, in _read_from_self\n",
      "    data = self._ssock.recv(4096)\n",
      "ConnectionResetError: [WinError 10054] An existing connection was forcibly closed by the remote host\n",
      "Exception in callback BaseSelectorEventLoop._read_from_self()\n",
      "handle: <Handle BaseSelectorEventLoop._read_from_self()>\n",
      "Traceback (most recent call last):\n",
      "  File \"C:\\Users\\donmc\\anaconda3\\envs\\PythonData\\lib\\asyncio\\events.py\", line 145, in _run\n",
      "    self._callback(*self._args)\n",
      "  File \"C:\\Users\\donmc\\anaconda3\\envs\\PythonData\\lib\\asyncio\\selector_events.py\", line 141, in _read_from_self\n",
      "    data = self._ssock.recv(4096)\n",
      "ConnectionResetError: [WinError 10054] An existing connection was forcibly closed by the remote host\n",
      "Exception in callback BaseSelectorEventLoop._read_from_self()\n",
      "handle: <Handle BaseSelectorEventLoop._read_from_self()>\n",
      "Traceback (most recent call last):\n",
      "  File \"C:\\Users\\donmc\\anaconda3\\envs\\PythonData\\lib\\asyncio\\events.py\", line 145, in _run\n",
      "    self._callback(*self._args)\n",
      "  File \"C:\\Users\\donmc\\anaconda3\\envs\\PythonData\\lib\\asyncio\\selector_events.py\", line 141, in _read_from_self\n",
      "    data = self._ssock.recv(4096)\n",
      "ConnectionResetError: [WinError 10054] An existing connection was forcibly closed by the remote host\n",
      "Exception in callback BaseSelectorEventLoop._read_from_self()\n",
      "handle: <Handle BaseSelectorEventLoop._read_from_self()>\n",
      "Traceback (most recent call last):\n",
      "  File \"C:\\Users\\donmc\\anaconda3\\envs\\PythonData\\lib\\asyncio\\events.py\", line 145, in _run\n",
      "    self._callback(*self._args)\n",
      "  File \"C:\\Users\\donmc\\anaconda3\\envs\\PythonData\\lib\\asyncio\\selector_events.py\", line 141, in _read_from_self\n",
      "    data = self._ssock.recv(4096)\n",
      "ConnectionResetError: [WinError 10054] An existing connection was forcibly closed by the remote host\n",
      "Exception in callback BaseSelectorEventLoop._read_from_self()\n",
      "handle: <Handle BaseSelectorEventLoop._read_from_self()>\n",
      "Traceback (most recent call last):\n",
      "  File \"C:\\Users\\donmc\\anaconda3\\envs\\PythonData\\lib\\asyncio\\events.py\", line 145, in _run\n",
      "    self._callback(*self._args)\n",
      "  File \"C:\\Users\\donmc\\anaconda3\\envs\\PythonData\\lib\\asyncio\\selector_events.py\", line 141, in _read_from_self\n",
      "    data = self._ssock.recv(4096)\n",
      "ConnectionResetError: [WinError 10054] An existing connection was forcibly closed by the remote host\n",
      "Exception in callback BaseSelectorEventLoop._read_from_self()\n",
      "handle: <Handle BaseSelectorEventLoop._read_from_self()>\n",
      "Traceback (most recent call last):\n",
      "  File \"C:\\Users\\donmc\\anaconda3\\envs\\PythonData\\lib\\asyncio\\events.py\", line 145, in _run\n",
      "    self._callback(*self._args)\n",
      "  File \"C:\\Users\\donmc\\anaconda3\\envs\\PythonData\\lib\\asyncio\\selector_events.py\", line 141, in _read_from_self\n",
      "    data = self._ssock.recv(4096)\n",
      "ConnectionResetError: [WinError 10054] An existing connection was forcibly closed by the remote host\n",
      "Exception in callback BaseSelectorEventLoop._read_from_self()\n",
      "handle: <Handle BaseSelectorEventLoop._read_from_self()>\n",
      "Traceback (most recent call last):\n",
      "  File \"C:\\Users\\donmc\\anaconda3\\envs\\PythonData\\lib\\asyncio\\events.py\", line 145, in _run\n",
      "    self._callback(*self._args)\n",
      "  File \"C:\\Users\\donmc\\anaconda3\\envs\\PythonData\\lib\\asyncio\\selector_events.py\", line 141, in _read_from_self\n",
      "    data = self._ssock.recv(4096)\n",
      "ConnectionResetError: [WinError 10054] An existing connection was forcibly closed by the remote host\n",
      "Exception in callback BaseSelectorEventLoop._read_from_self()\n",
      "handle: <Handle BaseSelectorEventLoop._read_from_self()>\n",
      "Traceback (most recent call last):\n",
      "  File \"C:\\Users\\donmc\\anaconda3\\envs\\PythonData\\lib\\asyncio\\events.py\", line 145, in _run\n",
      "    self._callback(*self._args)\n",
      "  File \"C:\\Users\\donmc\\anaconda3\\envs\\PythonData\\lib\\asyncio\\selector_events.py\", line 141, in _read_from_self\n",
      "    data = self._ssock.recv(4096)\n",
      "ConnectionResetError: [WinError 10054] An existing connection was forcibly closed by the remote host\n"
     ]
    },
    {
     "name": "stderr",
     "output_type": "stream",
     "text": [
      "Exception in callback BaseSelectorEventLoop._read_from_self()\n",
      "handle: <Handle BaseSelectorEventLoop._read_from_self()>\n",
      "Traceback (most recent call last):\n",
      "  File \"C:\\Users\\donmc\\anaconda3\\envs\\PythonData\\lib\\asyncio\\events.py\", line 145, in _run\n",
      "    self._callback(*self._args)\n",
      "  File \"C:\\Users\\donmc\\anaconda3\\envs\\PythonData\\lib\\asyncio\\selector_events.py\", line 141, in _read_from_self\n",
      "    data = self._ssock.recv(4096)\n",
      "ConnectionResetError: [WinError 10054] An existing connection was forcibly closed by the remote host\n",
      "Exception in callback BaseSelectorEventLoop._read_from_self()\n",
      "handle: <Handle BaseSelectorEventLoop._read_from_self()>\n",
      "Traceback (most recent call last):\n",
      "  File \"C:\\Users\\donmc\\anaconda3\\envs\\PythonData\\lib\\asyncio\\events.py\", line 145, in _run\n",
      "    self._callback(*self._args)\n",
      "  File \"C:\\Users\\donmc\\anaconda3\\envs\\PythonData\\lib\\asyncio\\selector_events.py\", line 141, in _read_from_self\n",
      "    data = self._ssock.recv(4096)\n",
      "ConnectionResetError: [WinError 10054] An existing connection was forcibly closed by the remote host\n",
      "Exception in callback BaseSelectorEventLoop._read_from_self()\n",
      "handle: <Handle BaseSelectorEventLoop._read_from_self()>\n",
      "Traceback (most recent call last):\n",
      "  File \"C:\\Users\\donmc\\anaconda3\\envs\\PythonData\\lib\\asyncio\\events.py\", line 145, in _run\n",
      "    self._callback(*self._args)\n",
      "  File \"C:\\Users\\donmc\\anaconda3\\envs\\PythonData\\lib\\asyncio\\selector_events.py\", line 141, in _read_from_self\n",
      "    data = self._ssock.recv(4096)\n",
      "ConnectionResetError: [WinError 10054] An existing connection was forcibly closed by the remote host\n",
      "Exception in callback BaseSelectorEventLoop._read_from_self()\n",
      "handle: <Handle BaseSelectorEventLoop._read_from_self()>\n",
      "Traceback (most recent call last):\n",
      "  File \"C:\\Users\\donmc\\anaconda3\\envs\\PythonData\\lib\\asyncio\\events.py\", line 145, in _run\n",
      "    self._callback(*self._args)\n",
      "  File \"C:\\Users\\donmc\\anaconda3\\envs\\PythonData\\lib\\asyncio\\selector_events.py\", line 141, in _read_from_self\n",
      "    data = self._ssock.recv(4096)\n",
      "ConnectionResetError: [WinError 10054] An existing connection was forcibly closed by the remote host\n",
      "Exception in callback BaseSelectorEventLoop._read_from_self()\n",
      "handle: <Handle BaseSelectorEventLoop._read_from_self()>\n",
      "Traceback (most recent call last):\n",
      "  File \"C:\\Users\\donmc\\anaconda3\\envs\\PythonData\\lib\\asyncio\\events.py\", line 145, in _run\n",
      "    self._callback(*self._args)\n",
      "  File \"C:\\Users\\donmc\\anaconda3\\envs\\PythonData\\lib\\asyncio\\selector_events.py\", line 141, in _read_from_self\n",
      "    data = self._ssock.recv(4096)\n",
      "ConnectionResetError: [WinError 10054] An existing connection was forcibly closed by the remote host\n",
      "Exception in callback BaseSelectorEventLoop._read_from_self()\n",
      "handle: <Handle BaseSelectorEventLoop._read_from_self()>\n",
      "Traceback (most recent call last):\n",
      "  File \"C:\\Users\\donmc\\anaconda3\\envs\\PythonData\\lib\\asyncio\\events.py\", line 145, in _run\n",
      "    self._callback(*self._args)\n",
      "  File \"C:\\Users\\donmc\\anaconda3\\envs\\PythonData\\lib\\asyncio\\selector_events.py\", line 141, in _read_from_self\n",
      "    data = self._ssock.recv(4096)\n",
      "ConnectionResetError: [WinError 10054] An existing connection was forcibly closed by the remote host\n",
      "Exception in callback BaseSelectorEventLoop._read_from_self()\n",
      "handle: <Handle BaseSelectorEventLoop._read_from_self()>\n",
      "Traceback (most recent call last):\n",
      "  File \"C:\\Users\\donmc\\anaconda3\\envs\\PythonData\\lib\\asyncio\\events.py\", line 145, in _run\n",
      "    self._callback(*self._args)\n",
      "  File \"C:\\Users\\donmc\\anaconda3\\envs\\PythonData\\lib\\asyncio\\selector_events.py\", line 141, in _read_from_self\n",
      "    data = self._ssock.recv(4096)\n",
      "ConnectionResetError: [WinError 10054] An existing connection was forcibly closed by the remote host\n",
      "Exception in callback BaseSelectorEventLoop._read_from_self()\n",
      "handle: <Handle BaseSelectorEventLoop._read_from_self()>\n",
      "Traceback (most recent call last):\n",
      "  File \"C:\\Users\\donmc\\anaconda3\\envs\\PythonData\\lib\\asyncio\\events.py\", line 145, in _run\n",
      "    self._callback(*self._args)\n",
      "  File \"C:\\Users\\donmc\\anaconda3\\envs\\PythonData\\lib\\asyncio\\selector_events.py\", line 141, in _read_from_self\n",
      "    data = self._ssock.recv(4096)\n",
      "ConnectionResetError: [WinError 10054] An existing connection was forcibly closed by the remote host\n",
      "Exception in callback BaseSelectorEventLoop._read_from_self()\n",
      "handle: <Handle BaseSelectorEventLoop._read_from_self()>\n",
      "Traceback (most recent call last):\n",
      "  File \"C:\\Users\\donmc\\anaconda3\\envs\\PythonData\\lib\\asyncio\\events.py\", line 145, in _run\n",
      "    self._callback(*self._args)\n",
      "  File \"C:\\Users\\donmc\\anaconda3\\envs\\PythonData\\lib\\asyncio\\selector_events.py\", line 141, in _read_from_self\n",
      "    data = self._ssock.recv(4096)\n",
      "ConnectionResetError: [WinError 10054] An existing connection was forcibly closed by the remote host\n",
      "Exception in callback BaseSelectorEventLoop._read_from_self()\n",
      "handle: <Handle BaseSelectorEventLoop._read_from_self()>\n",
      "Traceback (most recent call last):\n",
      "  File \"C:\\Users\\donmc\\anaconda3\\envs\\PythonData\\lib\\asyncio\\events.py\", line 145, in _run\n",
      "    self._callback(*self._args)\n",
      "  File \"C:\\Users\\donmc\\anaconda3\\envs\\PythonData\\lib\\asyncio\\selector_events.py\", line 141, in _read_from_self\n",
      "    data = self._ssock.recv(4096)\n",
      "ConnectionResetError: [WinError 10054] An existing connection was forcibly closed by the remote host\n",
      "Exception in callback BaseSelectorEventLoop._read_from_self()\n",
      "handle: <Handle BaseSelectorEventLoop._read_from_self()>\n",
      "Traceback (most recent call last):\n",
      "  File \"C:\\Users\\donmc\\anaconda3\\envs\\PythonData\\lib\\asyncio\\events.py\", line 145, in _run\n",
      "    self._callback(*self._args)\n",
      "  File \"C:\\Users\\donmc\\anaconda3\\envs\\PythonData\\lib\\asyncio\\selector_events.py\", line 141, in _read_from_self\n",
      "    data = self._ssock.recv(4096)\n",
      "ConnectionResetError: [WinError 10054] An existing connection was forcibly closed by the remote host\n",
      "Exception in callback BaseSelectorEventLoop._read_from_self()\n",
      "handle: <Handle BaseSelectorEventLoop._read_from_self()>\n",
      "Traceback (most recent call last):\n",
      "  File \"C:\\Users\\donmc\\anaconda3\\envs\\PythonData\\lib\\asyncio\\events.py\", line 145, in _run\n",
      "    self._callback(*self._args)\n",
      "  File \"C:\\Users\\donmc\\anaconda3\\envs\\PythonData\\lib\\asyncio\\selector_events.py\", line 141, in _read_from_self\n",
      "    data = self._ssock.recv(4096)\n",
      "ConnectionResetError: [WinError 10054] An existing connection was forcibly closed by the remote host\n",
      "Exception in callback BaseSelectorEventLoop._read_from_self()\n",
      "handle: <Handle BaseSelectorEventLoop._read_from_self()>\n",
      "Traceback (most recent call last):\n",
      "  File \"C:\\Users\\donmc\\anaconda3\\envs\\PythonData\\lib\\asyncio\\events.py\", line 145, in _run\n",
      "    self._callback(*self._args)\n",
      "  File \"C:\\Users\\donmc\\anaconda3\\envs\\PythonData\\lib\\asyncio\\selector_events.py\", line 141, in _read_from_self\n",
      "    data = self._ssock.recv(4096)\n",
      "ConnectionResetError: [WinError 10054] An existing connection was forcibly closed by the remote host\n",
      "Exception in callback BaseSelectorEventLoop._read_from_self()\n",
      "handle: <Handle BaseSelectorEventLoop._read_from_self()>\n",
      "Traceback (most recent call last):\n",
      "  File \"C:\\Users\\donmc\\anaconda3\\envs\\PythonData\\lib\\asyncio\\events.py\", line 145, in _run\n",
      "    self._callback(*self._args)\n",
      "  File \"C:\\Users\\donmc\\anaconda3\\envs\\PythonData\\lib\\asyncio\\selector_events.py\", line 141, in _read_from_self\n",
      "    data = self._ssock.recv(4096)\n",
      "ConnectionResetError: [WinError 10054] An existing connection was forcibly closed by the remote host\n",
      "Exception in callback BaseSelectorEventLoop._read_from_self()\n",
      "handle: <Handle BaseSelectorEventLoop._read_from_self()>\n",
      "Traceback (most recent call last):\n",
      "  File \"C:\\Users\\donmc\\anaconda3\\envs\\PythonData\\lib\\asyncio\\events.py\", line 145, in _run\n",
      "    self._callback(*self._args)\n",
      "  File \"C:\\Users\\donmc\\anaconda3\\envs\\PythonData\\lib\\asyncio\\selector_events.py\", line 141, in _read_from_self\n",
      "    data = self._ssock.recv(4096)\n",
      "ConnectionResetError: [WinError 10054] An existing connection was forcibly closed by the remote host\n",
      "Exception in callback BaseSelectorEventLoop._read_from_self()\n",
      "handle: <Handle BaseSelectorEventLoop._read_from_self()>\n",
      "Traceback (most recent call last):\n",
      "  File \"C:\\Users\\donmc\\anaconda3\\envs\\PythonData\\lib\\asyncio\\events.py\", line 145, in _run\n",
      "    self._callback(*self._args)\n",
      "  File \"C:\\Users\\donmc\\anaconda3\\envs\\PythonData\\lib\\asyncio\\selector_events.py\", line 141, in _read_from_self\n",
      "    data = self._ssock.recv(4096)\n",
      "ConnectionResetError: [WinError 10054] An existing connection was forcibly closed by the remote host\n"
     ]
    },
    {
     "name": "stderr",
     "output_type": "stream",
     "text": [
      "Exception in callback BaseSelectorEventLoop._read_from_self()\n",
      "handle: <Handle BaseSelectorEventLoop._read_from_self()>\n",
      "Traceback (most recent call last):\n",
      "  File \"C:\\Users\\donmc\\anaconda3\\envs\\PythonData\\lib\\asyncio\\events.py\", line 145, in _run\n",
      "    self._callback(*self._args)\n",
      "  File \"C:\\Users\\donmc\\anaconda3\\envs\\PythonData\\lib\\asyncio\\selector_events.py\", line 141, in _read_from_self\n",
      "    data = self._ssock.recv(4096)\n",
      "ConnectionResetError: [WinError 10054] An existing connection was forcibly closed by the remote host\n",
      "Exception in callback BaseSelectorEventLoop._read_from_self()\n",
      "handle: <Handle BaseSelectorEventLoop._read_from_self()>\n",
      "Traceback (most recent call last):\n",
      "  File \"C:\\Users\\donmc\\anaconda3\\envs\\PythonData\\lib\\asyncio\\events.py\", line 145, in _run\n",
      "    self._callback(*self._args)\n",
      "  File \"C:\\Users\\donmc\\anaconda3\\envs\\PythonData\\lib\\asyncio\\selector_events.py\", line 141, in _read_from_self\n",
      "    data = self._ssock.recv(4096)\n",
      "ConnectionResetError: [WinError 10054] An existing connection was forcibly closed by the remote host\n",
      "Exception in callback BaseSelectorEventLoop._read_from_self()\n",
      "handle: <Handle BaseSelectorEventLoop._read_from_self()>\n",
      "Traceback (most recent call last):\n",
      "  File \"C:\\Users\\donmc\\anaconda3\\envs\\PythonData\\lib\\asyncio\\events.py\", line 145, in _run\n",
      "    self._callback(*self._args)\n",
      "  File \"C:\\Users\\donmc\\anaconda3\\envs\\PythonData\\lib\\asyncio\\selector_events.py\", line 141, in _read_from_self\n",
      "    data = self._ssock.recv(4096)\n",
      "ConnectionResetError: [WinError 10054] An existing connection was forcibly closed by the remote host\n",
      "Exception in callback BaseSelectorEventLoop._read_from_self()\n",
      "handle: <Handle BaseSelectorEventLoop._read_from_self()>\n",
      "Traceback (most recent call last):\n",
      "  File \"C:\\Users\\donmc\\anaconda3\\envs\\PythonData\\lib\\asyncio\\events.py\", line 145, in _run\n",
      "    self._callback(*self._args)\n",
      "  File \"C:\\Users\\donmc\\anaconda3\\envs\\PythonData\\lib\\asyncio\\selector_events.py\", line 141, in _read_from_self\n",
      "    data = self._ssock.recv(4096)\n",
      "ConnectionResetError: [WinError 10054] An existing connection was forcibly closed by the remote host\n",
      "Exception in callback BaseSelectorEventLoop._read_from_self()\n",
      "handle: <Handle BaseSelectorEventLoop._read_from_self()>\n",
      "Traceback (most recent call last):\n",
      "  File \"C:\\Users\\donmc\\anaconda3\\envs\\PythonData\\lib\\asyncio\\events.py\", line 145, in _run\n",
      "    self._callback(*self._args)\n",
      "  File \"C:\\Users\\donmc\\anaconda3\\envs\\PythonData\\lib\\asyncio\\selector_events.py\", line 141, in _read_from_self\n",
      "    data = self._ssock.recv(4096)\n",
      "ConnectionResetError: [WinError 10054] An existing connection was forcibly closed by the remote host\n",
      "Exception in callback BaseSelectorEventLoop._read_from_self()\n",
      "handle: <Handle BaseSelectorEventLoop._read_from_self()>\n",
      "Traceback (most recent call last):\n",
      "  File \"C:\\Users\\donmc\\anaconda3\\envs\\PythonData\\lib\\asyncio\\events.py\", line 145, in _run\n",
      "    self._callback(*self._args)\n",
      "  File \"C:\\Users\\donmc\\anaconda3\\envs\\PythonData\\lib\\asyncio\\selector_events.py\", line 141, in _read_from_self\n",
      "    data = self._ssock.recv(4096)\n",
      "ConnectionResetError: [WinError 10054] An existing connection was forcibly closed by the remote host\n",
      "Exception in callback BaseSelectorEventLoop._read_from_self()\n",
      "handle: <Handle BaseSelectorEventLoop._read_from_self()>\n",
      "Traceback (most recent call last):\n",
      "  File \"C:\\Users\\donmc\\anaconda3\\envs\\PythonData\\lib\\asyncio\\events.py\", line 145, in _run\n",
      "    self._callback(*self._args)\n",
      "  File \"C:\\Users\\donmc\\anaconda3\\envs\\PythonData\\lib\\asyncio\\selector_events.py\", line 141, in _read_from_self\n",
      "    data = self._ssock.recv(4096)\n",
      "ConnectionResetError: [WinError 10054] An existing connection was forcibly closed by the remote host\n",
      "Exception in callback BaseSelectorEventLoop._read_from_self()\n",
      "handle: <Handle BaseSelectorEventLoop._read_from_self()>\n",
      "Traceback (most recent call last):\n",
      "  File \"C:\\Users\\donmc\\anaconda3\\envs\\PythonData\\lib\\asyncio\\events.py\", line 145, in _run\n",
      "    self._callback(*self._args)\n",
      "  File \"C:\\Users\\donmc\\anaconda3\\envs\\PythonData\\lib\\asyncio\\selector_events.py\", line 141, in _read_from_self\n",
      "    data = self._ssock.recv(4096)\n",
      "ConnectionResetError: [WinError 10054] An existing connection was forcibly closed by the remote host\n",
      "Exception in callback BaseSelectorEventLoop._read_from_self()\n",
      "handle: <Handle BaseSelectorEventLoop._read_from_self()>\n",
      "Traceback (most recent call last):\n",
      "  File \"C:\\Users\\donmc\\anaconda3\\envs\\PythonData\\lib\\asyncio\\events.py\", line 145, in _run\n",
      "    self._callback(*self._args)\n",
      "  File \"C:\\Users\\donmc\\anaconda3\\envs\\PythonData\\lib\\asyncio\\selector_events.py\", line 141, in _read_from_self\n",
      "    data = self._ssock.recv(4096)\n",
      "ConnectionResetError: [WinError 10054] An existing connection was forcibly closed by the remote host\n",
      "Exception in callback BaseSelectorEventLoop._read_from_self()\n",
      "handle: <Handle BaseSelectorEventLoop._read_from_self()>\n",
      "Traceback (most recent call last):\n",
      "  File \"C:\\Users\\donmc\\anaconda3\\envs\\PythonData\\lib\\asyncio\\events.py\", line 145, in _run\n",
      "    self._callback(*self._args)\n",
      "  File \"C:\\Users\\donmc\\anaconda3\\envs\\PythonData\\lib\\asyncio\\selector_events.py\", line 141, in _read_from_self\n",
      "    data = self._ssock.recv(4096)\n",
      "ConnectionResetError: [WinError 10054] An existing connection was forcibly closed by the remote host\n",
      "Exception in callback BaseSelectorEventLoop._read_from_self()\n",
      "handle: <Handle BaseSelectorEventLoop._read_from_self()>\n",
      "Traceback (most recent call last):\n",
      "  File \"C:\\Users\\donmc\\anaconda3\\envs\\PythonData\\lib\\asyncio\\events.py\", line 145, in _run\n",
      "    self._callback(*self._args)\n",
      "  File \"C:\\Users\\donmc\\anaconda3\\envs\\PythonData\\lib\\asyncio\\selector_events.py\", line 141, in _read_from_self\n",
      "    data = self._ssock.recv(4096)\n",
      "ConnectionResetError: [WinError 10054] An existing connection was forcibly closed by the remote host\n",
      "Exception in callback BaseSelectorEventLoop._read_from_self()\n",
      "handle: <Handle BaseSelectorEventLoop._read_from_self()>\n",
      "Traceback (most recent call last):\n",
      "  File \"C:\\Users\\donmc\\anaconda3\\envs\\PythonData\\lib\\asyncio\\events.py\", line 145, in _run\n",
      "    self._callback(*self._args)\n",
      "  File \"C:\\Users\\donmc\\anaconda3\\envs\\PythonData\\lib\\asyncio\\selector_events.py\", line 141, in _read_from_self\n",
      "    data = self._ssock.recv(4096)\n",
      "ConnectionResetError: [WinError 10054] An existing connection was forcibly closed by the remote host\n",
      "Exception in callback BaseSelectorEventLoop._read_from_self()\n",
      "handle: <Handle BaseSelectorEventLoop._read_from_self()>\n",
      "Traceback (most recent call last):\n",
      "  File \"C:\\Users\\donmc\\anaconda3\\envs\\PythonData\\lib\\asyncio\\events.py\", line 145, in _run\n",
      "    self._callback(*self._args)\n",
      "  File \"C:\\Users\\donmc\\anaconda3\\envs\\PythonData\\lib\\asyncio\\selector_events.py\", line 141, in _read_from_self\n",
      "    data = self._ssock.recv(4096)\n",
      "ConnectionResetError: [WinError 10054] An existing connection was forcibly closed by the remote host\n",
      "Exception in callback BaseSelectorEventLoop._read_from_self()\n",
      "handle: <Handle BaseSelectorEventLoop._read_from_self()>\n",
      "Traceback (most recent call last):\n",
      "  File \"C:\\Users\\donmc\\anaconda3\\envs\\PythonData\\lib\\asyncio\\events.py\", line 145, in _run\n",
      "    self._callback(*self._args)\n",
      "  File \"C:\\Users\\donmc\\anaconda3\\envs\\PythonData\\lib\\asyncio\\selector_events.py\", line 141, in _read_from_self\n",
      "    data = self._ssock.recv(4096)\n",
      "ConnectionResetError: [WinError 10054] An existing connection was forcibly closed by the remote host\n",
      "Exception in callback BaseSelectorEventLoop._read_from_self()\n",
      "handle: <Handle BaseSelectorEventLoop._read_from_self()>\n",
      "Traceback (most recent call last):\n",
      "  File \"C:\\Users\\donmc\\anaconda3\\envs\\PythonData\\lib\\asyncio\\events.py\", line 145, in _run\n",
      "    self._callback(*self._args)\n",
      "  File \"C:\\Users\\donmc\\anaconda3\\envs\\PythonData\\lib\\asyncio\\selector_events.py\", line 141, in _read_from_self\n",
      "    data = self._ssock.recv(4096)\n",
      "ConnectionResetError: [WinError 10054] An existing connection was forcibly closed by the remote host\n",
      "Exception in callback BaseSelectorEventLoop._read_from_self()\n",
      "handle: <Handle BaseSelectorEventLoop._read_from_self()>\n",
      "Traceback (most recent call last):\n",
      "  File \"C:\\Users\\donmc\\anaconda3\\envs\\PythonData\\lib\\asyncio\\events.py\", line 145, in _run\n",
      "    self._callback(*self._args)\n",
      "  File \"C:\\Users\\donmc\\anaconda3\\envs\\PythonData\\lib\\asyncio\\selector_events.py\", line 141, in _read_from_self\n",
      "    data = self._ssock.recv(4096)\n",
      "ConnectionResetError: [WinError 10054] An existing connection was forcibly closed by the remote host\n"
     ]
    },
    {
     "name": "stderr",
     "output_type": "stream",
     "text": [
      "Exception in callback BaseSelectorEventLoop._read_from_self()\n",
      "handle: <Handle BaseSelectorEventLoop._read_from_self()>\n",
      "Traceback (most recent call last):\n",
      "  File \"C:\\Users\\donmc\\anaconda3\\envs\\PythonData\\lib\\asyncio\\events.py\", line 145, in _run\n",
      "    self._callback(*self._args)\n",
      "  File \"C:\\Users\\donmc\\anaconda3\\envs\\PythonData\\lib\\asyncio\\selector_events.py\", line 141, in _read_from_self\n",
      "    data = self._ssock.recv(4096)\n",
      "ConnectionResetError: [WinError 10054] An existing connection was forcibly closed by the remote host\n",
      "Exception in callback BaseSelectorEventLoop._read_from_self()\n",
      "handle: <Handle BaseSelectorEventLoop._read_from_self()>\n",
      "Traceback (most recent call last):\n",
      "  File \"C:\\Users\\donmc\\anaconda3\\envs\\PythonData\\lib\\asyncio\\events.py\", line 145, in _run\n",
      "    self._callback(*self._args)\n",
      "  File \"C:\\Users\\donmc\\anaconda3\\envs\\PythonData\\lib\\asyncio\\selector_events.py\", line 141, in _read_from_self\n",
      "    data = self._ssock.recv(4096)\n",
      "ConnectionResetError: [WinError 10054] An existing connection was forcibly closed by the remote host\n",
      "Exception in callback BaseSelectorEventLoop._read_from_self()\n",
      "handle: <Handle BaseSelectorEventLoop._read_from_self()>\n",
      "Traceback (most recent call last):\n",
      "  File \"C:\\Users\\donmc\\anaconda3\\envs\\PythonData\\lib\\asyncio\\events.py\", line 145, in _run\n",
      "    self._callback(*self._args)\n",
      "  File \"C:\\Users\\donmc\\anaconda3\\envs\\PythonData\\lib\\asyncio\\selector_events.py\", line 141, in _read_from_self\n",
      "    data = self._ssock.recv(4096)\n",
      "ConnectionResetError: [WinError 10054] An existing connection was forcibly closed by the remote host\n",
      "Exception in callback BaseSelectorEventLoop._read_from_self()\n",
      "handle: <Handle BaseSelectorEventLoop._read_from_self()>\n",
      "Traceback (most recent call last):\n",
      "  File \"C:\\Users\\donmc\\anaconda3\\envs\\PythonData\\lib\\asyncio\\events.py\", line 145, in _run\n",
      "    self._callback(*self._args)\n",
      "  File \"C:\\Users\\donmc\\anaconda3\\envs\\PythonData\\lib\\asyncio\\selector_events.py\", line 141, in _read_from_self\n",
      "    data = self._ssock.recv(4096)\n",
      "ConnectionResetError: [WinError 10054] An existing connection was forcibly closed by the remote host\n",
      "Exception in callback BaseSelectorEventLoop._read_from_self()\n",
      "handle: <Handle BaseSelectorEventLoop._read_from_self()>\n",
      "Traceback (most recent call last):\n",
      "  File \"C:\\Users\\donmc\\anaconda3\\envs\\PythonData\\lib\\asyncio\\events.py\", line 145, in _run\n",
      "    self._callback(*self._args)\n",
      "  File \"C:\\Users\\donmc\\anaconda3\\envs\\PythonData\\lib\\asyncio\\selector_events.py\", line 141, in _read_from_self\n",
      "    data = self._ssock.recv(4096)\n",
      "ConnectionResetError: [WinError 10054] An existing connection was forcibly closed by the remote host\n",
      "Exception in callback BaseSelectorEventLoop._read_from_self()\n",
      "handle: <Handle BaseSelectorEventLoop._read_from_self()>\n",
      "Traceback (most recent call last):\n",
      "  File \"C:\\Users\\donmc\\anaconda3\\envs\\PythonData\\lib\\asyncio\\events.py\", line 145, in _run\n",
      "    self._callback(*self._args)\n",
      "  File \"C:\\Users\\donmc\\anaconda3\\envs\\PythonData\\lib\\asyncio\\selector_events.py\", line 141, in _read_from_self\n",
      "    data = self._ssock.recv(4096)\n",
      "ConnectionResetError: [WinError 10054] An existing connection was forcibly closed by the remote host\n",
      "Exception in callback BaseSelectorEventLoop._read_from_self()\n",
      "handle: <Handle BaseSelectorEventLoop._read_from_self()>\n",
      "Traceback (most recent call last):\n",
      "  File \"C:\\Users\\donmc\\anaconda3\\envs\\PythonData\\lib\\asyncio\\events.py\", line 145, in _run\n",
      "    self._callback(*self._args)\n",
      "  File \"C:\\Users\\donmc\\anaconda3\\envs\\PythonData\\lib\\asyncio\\selector_events.py\", line 141, in _read_from_self\n",
      "    data = self._ssock.recv(4096)\n",
      "ConnectionResetError: [WinError 10054] An existing connection was forcibly closed by the remote host\n",
      "Exception in callback BaseSelectorEventLoop._read_from_self()\n",
      "handle: <Handle BaseSelectorEventLoop._read_from_self()>\n",
      "Traceback (most recent call last):\n",
      "  File \"C:\\Users\\donmc\\anaconda3\\envs\\PythonData\\lib\\asyncio\\events.py\", line 145, in _run\n",
      "    self._callback(*self._args)\n",
      "  File \"C:\\Users\\donmc\\anaconda3\\envs\\PythonData\\lib\\asyncio\\selector_events.py\", line 141, in _read_from_self\n",
      "    data = self._ssock.recv(4096)\n",
      "ConnectionResetError: [WinError 10054] An existing connection was forcibly closed by the remote host\n",
      "Exception in callback BaseSelectorEventLoop._read_from_self()\n",
      "handle: <Handle BaseSelectorEventLoop._read_from_self()>\n",
      "Traceback (most recent call last):\n",
      "  File \"C:\\Users\\donmc\\anaconda3\\envs\\PythonData\\lib\\asyncio\\events.py\", line 145, in _run\n",
      "    self._callback(*self._args)\n",
      "  File \"C:\\Users\\donmc\\anaconda3\\envs\\PythonData\\lib\\asyncio\\selector_events.py\", line 141, in _read_from_self\n",
      "    data = self._ssock.recv(4096)\n",
      "ConnectionResetError: [WinError 10054] An existing connection was forcibly closed by the remote host\n",
      "Exception in callback BaseSelectorEventLoop._read_from_self()\n",
      "handle: <Handle BaseSelectorEventLoop._read_from_self()>\n",
      "Traceback (most recent call last):\n",
      "  File \"C:\\Users\\donmc\\anaconda3\\envs\\PythonData\\lib\\asyncio\\events.py\", line 145, in _run\n",
      "    self._callback(*self._args)\n",
      "  File \"C:\\Users\\donmc\\anaconda3\\envs\\PythonData\\lib\\asyncio\\selector_events.py\", line 141, in _read_from_self\n",
      "    data = self._ssock.recv(4096)\n",
      "ConnectionResetError: [WinError 10054] An existing connection was forcibly closed by the remote host\n",
      "Exception in callback BaseSelectorEventLoop._read_from_self()\n",
      "handle: <Handle BaseSelectorEventLoop._read_from_self()>\n",
      "Traceback (most recent call last):\n",
      "  File \"C:\\Users\\donmc\\anaconda3\\envs\\PythonData\\lib\\asyncio\\events.py\", line 145, in _run\n",
      "    self._callback(*self._args)\n",
      "  File \"C:\\Users\\donmc\\anaconda3\\envs\\PythonData\\lib\\asyncio\\selector_events.py\", line 141, in _read_from_self\n",
      "    data = self._ssock.recv(4096)\n",
      "ConnectionResetError: [WinError 10054] An existing connection was forcibly closed by the remote host\n",
      "Exception in callback BaseSelectorEventLoop._read_from_self()\n",
      "handle: <Handle BaseSelectorEventLoop._read_from_self()>\n",
      "Traceback (most recent call last):\n",
      "  File \"C:\\Users\\donmc\\anaconda3\\envs\\PythonData\\lib\\asyncio\\events.py\", line 145, in _run\n",
      "    self._callback(*self._args)\n",
      "  File \"C:\\Users\\donmc\\anaconda3\\envs\\PythonData\\lib\\asyncio\\selector_events.py\", line 141, in _read_from_self\n",
      "    data = self._ssock.recv(4096)\n",
      "ConnectionResetError: [WinError 10054] An existing connection was forcibly closed by the remote host\n",
      "Exception in callback BaseSelectorEventLoop._read_from_self()\n",
      "handle: <Handle BaseSelectorEventLoop._read_from_self()>\n",
      "Traceback (most recent call last):\n",
      "  File \"C:\\Users\\donmc\\anaconda3\\envs\\PythonData\\lib\\asyncio\\events.py\", line 145, in _run\n",
      "    self._callback(*self._args)\n",
      "  File \"C:\\Users\\donmc\\anaconda3\\envs\\PythonData\\lib\\asyncio\\selector_events.py\", line 141, in _read_from_self\n",
      "    data = self._ssock.recv(4096)\n",
      "ConnectionResetError: [WinError 10054] An existing connection was forcibly closed by the remote host\n",
      "Exception in callback BaseSelectorEventLoop._read_from_self()\n",
      "handle: <Handle BaseSelectorEventLoop._read_from_self()>\n",
      "Traceback (most recent call last):\n",
      "  File \"C:\\Users\\donmc\\anaconda3\\envs\\PythonData\\lib\\asyncio\\events.py\", line 145, in _run\n",
      "    self._callback(*self._args)\n",
      "  File \"C:\\Users\\donmc\\anaconda3\\envs\\PythonData\\lib\\asyncio\\selector_events.py\", line 141, in _read_from_self\n",
      "    data = self._ssock.recv(4096)\n",
      "ConnectionResetError: [WinError 10054] An existing connection was forcibly closed by the remote host\n",
      "Exception in callback BaseSelectorEventLoop._read_from_self()\n",
      "handle: <Handle BaseSelectorEventLoop._read_from_self()>\n",
      "Traceback (most recent call last):\n",
      "  File \"C:\\Users\\donmc\\anaconda3\\envs\\PythonData\\lib\\asyncio\\events.py\", line 145, in _run\n",
      "    self._callback(*self._args)\n",
      "  File \"C:\\Users\\donmc\\anaconda3\\envs\\PythonData\\lib\\asyncio\\selector_events.py\", line 141, in _read_from_self\n",
      "    data = self._ssock.recv(4096)\n",
      "ConnectionResetError: [WinError 10054] An existing connection was forcibly closed by the remote host\n",
      "Exception in callback BaseSelectorEventLoop._read_from_self()\n",
      "handle: <Handle BaseSelectorEventLoop._read_from_self()>\n",
      "Traceback (most recent call last):\n",
      "  File \"C:\\Users\\donmc\\anaconda3\\envs\\PythonData\\lib\\asyncio\\events.py\", line 145, in _run\n",
      "    self._callback(*self._args)\n",
      "  File \"C:\\Users\\donmc\\anaconda3\\envs\\PythonData\\lib\\asyncio\\selector_events.py\", line 141, in _read_from_self\n",
      "    data = self._ssock.recv(4096)\n",
      "ConnectionResetError: [WinError 10054] An existing connection was forcibly closed by the remote host\n"
     ]
    },
    {
     "name": "stderr",
     "output_type": "stream",
     "text": [
      "Exception in callback BaseSelectorEventLoop._read_from_self()\n",
      "handle: <Handle BaseSelectorEventLoop._read_from_self()>\n",
      "Traceback (most recent call last):\n",
      "  File \"C:\\Users\\donmc\\anaconda3\\envs\\PythonData\\lib\\asyncio\\events.py\", line 145, in _run\n",
      "    self._callback(*self._args)\n",
      "  File \"C:\\Users\\donmc\\anaconda3\\envs\\PythonData\\lib\\asyncio\\selector_events.py\", line 141, in _read_from_self\n",
      "    data = self._ssock.recv(4096)\n",
      "ConnectionResetError: [WinError 10054] An existing connection was forcibly closed by the remote host\n",
      "Exception in callback BaseSelectorEventLoop._read_from_self()\n",
      "handle: <Handle BaseSelectorEventLoop._read_from_self()>\n",
      "Traceback (most recent call last):\n",
      "  File \"C:\\Users\\donmc\\anaconda3\\envs\\PythonData\\lib\\asyncio\\events.py\", line 145, in _run\n",
      "    self._callback(*self._args)\n",
      "  File \"C:\\Users\\donmc\\anaconda3\\envs\\PythonData\\lib\\asyncio\\selector_events.py\", line 141, in _read_from_self\n",
      "    data = self._ssock.recv(4096)\n",
      "ConnectionResetError: [WinError 10054] An existing connection was forcibly closed by the remote host\n",
      "Exception in callback BaseSelectorEventLoop._read_from_self()\n",
      "handle: <Handle BaseSelectorEventLoop._read_from_self()>\n",
      "Traceback (most recent call last):\n",
      "  File \"C:\\Users\\donmc\\anaconda3\\envs\\PythonData\\lib\\asyncio\\events.py\", line 145, in _run\n",
      "    self._callback(*self._args)\n",
      "  File \"C:\\Users\\donmc\\anaconda3\\envs\\PythonData\\lib\\asyncio\\selector_events.py\", line 141, in _read_from_self\n",
      "    data = self._ssock.recv(4096)\n",
      "ConnectionResetError: [WinError 10054] An existing connection was forcibly closed by the remote host\n",
      "Exception in callback BaseSelectorEventLoop._read_from_self()\n",
      "handle: <Handle BaseSelectorEventLoop._read_from_self()>\n",
      "Traceback (most recent call last):\n",
      "  File \"C:\\Users\\donmc\\anaconda3\\envs\\PythonData\\lib\\asyncio\\events.py\", line 145, in _run\n",
      "    self._callback(*self._args)\n",
      "  File \"C:\\Users\\donmc\\anaconda3\\envs\\PythonData\\lib\\asyncio\\selector_events.py\", line 141, in _read_from_self\n",
      "    data = self._ssock.recv(4096)\n",
      "ConnectionResetError: [WinError 10054] An existing connection was forcibly closed by the remote host\n",
      "Exception in callback BaseSelectorEventLoop._read_from_self()\n",
      "handle: <Handle BaseSelectorEventLoop._read_from_self()>\n",
      "Traceback (most recent call last):\n",
      "  File \"C:\\Users\\donmc\\anaconda3\\envs\\PythonData\\lib\\asyncio\\events.py\", line 145, in _run\n",
      "    self._callback(*self._args)\n",
      "  File \"C:\\Users\\donmc\\anaconda3\\envs\\PythonData\\lib\\asyncio\\selector_events.py\", line 141, in _read_from_self\n",
      "    data = self._ssock.recv(4096)\n",
      "ConnectionResetError: [WinError 10054] An existing connection was forcibly closed by the remote host\n",
      "Exception in callback BaseSelectorEventLoop._read_from_self()\n",
      "handle: <Handle BaseSelectorEventLoop._read_from_self()>\n",
      "Traceback (most recent call last):\n",
      "  File \"C:\\Users\\donmc\\anaconda3\\envs\\PythonData\\lib\\asyncio\\events.py\", line 145, in _run\n",
      "    self._callback(*self._args)\n",
      "  File \"C:\\Users\\donmc\\anaconda3\\envs\\PythonData\\lib\\asyncio\\selector_events.py\", line 141, in _read_from_self\n",
      "    data = self._ssock.recv(4096)\n",
      "ConnectionResetError: [WinError 10054] An existing connection was forcibly closed by the remote host\n",
      "Exception in callback BaseSelectorEventLoop._read_from_self()\n",
      "handle: <Handle BaseSelectorEventLoop._read_from_self()>\n",
      "Traceback (most recent call last):\n",
      "  File \"C:\\Users\\donmc\\anaconda3\\envs\\PythonData\\lib\\asyncio\\events.py\", line 145, in _run\n",
      "    self._callback(*self._args)\n",
      "  File \"C:\\Users\\donmc\\anaconda3\\envs\\PythonData\\lib\\asyncio\\selector_events.py\", line 141, in _read_from_self\n",
      "    data = self._ssock.recv(4096)\n",
      "ConnectionResetError: [WinError 10054] An existing connection was forcibly closed by the remote host\n",
      "Exception in callback BaseSelectorEventLoop._read_from_self()\n",
      "handle: <Handle BaseSelectorEventLoop._read_from_self()>\n",
      "Traceback (most recent call last):\n",
      "  File \"C:\\Users\\donmc\\anaconda3\\envs\\PythonData\\lib\\asyncio\\events.py\", line 145, in _run\n",
      "    self._callback(*self._args)\n",
      "  File \"C:\\Users\\donmc\\anaconda3\\envs\\PythonData\\lib\\asyncio\\selector_events.py\", line 141, in _read_from_self\n",
      "    data = self._ssock.recv(4096)\n",
      "ConnectionResetError: [WinError 10054] An existing connection was forcibly closed by the remote host\n",
      "Exception in callback BaseSelectorEventLoop._read_from_self()\n",
      "handle: <Handle BaseSelectorEventLoop._read_from_self()>\n",
      "Traceback (most recent call last):\n",
      "  File \"C:\\Users\\donmc\\anaconda3\\envs\\PythonData\\lib\\asyncio\\events.py\", line 145, in _run\n",
      "    self._callback(*self._args)\n",
      "  File \"C:\\Users\\donmc\\anaconda3\\envs\\PythonData\\lib\\asyncio\\selector_events.py\", line 141, in _read_from_self\n",
      "    data = self._ssock.recv(4096)\n",
      "ConnectionResetError: [WinError 10054] An existing connection was forcibly closed by the remote host\n",
      "Exception in callback BaseSelectorEventLoop._read_from_self()\n",
      "handle: <Handle BaseSelectorEventLoop._read_from_self()>\n",
      "Traceback (most recent call last):\n",
      "  File \"C:\\Users\\donmc\\anaconda3\\envs\\PythonData\\lib\\asyncio\\events.py\", line 145, in _run\n",
      "    self._callback(*self._args)\n",
      "  File \"C:\\Users\\donmc\\anaconda3\\envs\\PythonData\\lib\\asyncio\\selector_events.py\", line 141, in _read_from_self\n",
      "    data = self._ssock.recv(4096)\n",
      "ConnectionResetError: [WinError 10054] An existing connection was forcibly closed by the remote host\n",
      "Exception in callback BaseSelectorEventLoop._read_from_self()\n",
      "handle: <Handle BaseSelectorEventLoop._read_from_self()>\n",
      "Traceback (most recent call last):\n",
      "  File \"C:\\Users\\donmc\\anaconda3\\envs\\PythonData\\lib\\asyncio\\events.py\", line 145, in _run\n",
      "    self._callback(*self._args)\n",
      "  File \"C:\\Users\\donmc\\anaconda3\\envs\\PythonData\\lib\\asyncio\\selector_events.py\", line 141, in _read_from_self\n",
      "    data = self._ssock.recv(4096)\n",
      "ConnectionResetError: [WinError 10054] An existing connection was forcibly closed by the remote host\n",
      "Exception in callback BaseSelectorEventLoop._read_from_self()\n",
      "handle: <Handle BaseSelectorEventLoop._read_from_self()>\n",
      "Traceback (most recent call last):\n",
      "  File \"C:\\Users\\donmc\\anaconda3\\envs\\PythonData\\lib\\asyncio\\events.py\", line 145, in _run\n",
      "    self._callback(*self._args)\n",
      "  File \"C:\\Users\\donmc\\anaconda3\\envs\\PythonData\\lib\\asyncio\\selector_events.py\", line 141, in _read_from_self\n",
      "    data = self._ssock.recv(4096)\n",
      "ConnectionResetError: [WinError 10054] An existing connection was forcibly closed by the remote host\n",
      "Exception in callback BaseSelectorEventLoop._read_from_self()\n",
      "handle: <Handle BaseSelectorEventLoop._read_from_self()>\n",
      "Traceback (most recent call last):\n",
      "  File \"C:\\Users\\donmc\\anaconda3\\envs\\PythonData\\lib\\asyncio\\events.py\", line 145, in _run\n",
      "    self._callback(*self._args)\n",
      "  File \"C:\\Users\\donmc\\anaconda3\\envs\\PythonData\\lib\\asyncio\\selector_events.py\", line 141, in _read_from_self\n",
      "    data = self._ssock.recv(4096)\n",
      "ConnectionResetError: [WinError 10054] An existing connection was forcibly closed by the remote host\n",
      "Exception in callback BaseSelectorEventLoop._read_from_self()\n",
      "handle: <Handle BaseSelectorEventLoop._read_from_self()>\n",
      "Traceback (most recent call last):\n",
      "  File \"C:\\Users\\donmc\\anaconda3\\envs\\PythonData\\lib\\asyncio\\events.py\", line 145, in _run\n",
      "    self._callback(*self._args)\n",
      "  File \"C:\\Users\\donmc\\anaconda3\\envs\\PythonData\\lib\\asyncio\\selector_events.py\", line 141, in _read_from_self\n",
      "    data = self._ssock.recv(4096)\n",
      "ConnectionResetError: [WinError 10054] An existing connection was forcibly closed by the remote host\n",
      "Exception in callback BaseSelectorEventLoop._read_from_self()\n",
      "handle: <Handle BaseSelectorEventLoop._read_from_self()>\n",
      "Traceback (most recent call last):\n",
      "  File \"C:\\Users\\donmc\\anaconda3\\envs\\PythonData\\lib\\asyncio\\events.py\", line 145, in _run\n",
      "    self._callback(*self._args)\n",
      "  File \"C:\\Users\\donmc\\anaconda3\\envs\\PythonData\\lib\\asyncio\\selector_events.py\", line 141, in _read_from_self\n",
      "    data = self._ssock.recv(4096)\n",
      "ConnectionResetError: [WinError 10054] An existing connection was forcibly closed by the remote host\n",
      "Exception in callback BaseSelectorEventLoop._read_from_self()\n",
      "handle: <Handle BaseSelectorEventLoop._read_from_self()>\n",
      "Traceback (most recent call last):\n",
      "  File \"C:\\Users\\donmc\\anaconda3\\envs\\PythonData\\lib\\asyncio\\events.py\", line 145, in _run\n",
      "    self._callback(*self._args)\n",
      "  File \"C:\\Users\\donmc\\anaconda3\\envs\\PythonData\\lib\\asyncio\\selector_events.py\", line 141, in _read_from_self\n",
      "    data = self._ssock.recv(4096)\n",
      "ConnectionResetError: [WinError 10054] An existing connection was forcibly closed by the remote host\n"
     ]
    },
    {
     "name": "stderr",
     "output_type": "stream",
     "text": [
      "Exception in callback BaseSelectorEventLoop._read_from_self()\n",
      "handle: <Handle BaseSelectorEventLoop._read_from_self()>\n",
      "Traceback (most recent call last):\n",
      "  File \"C:\\Users\\donmc\\anaconda3\\envs\\PythonData\\lib\\asyncio\\events.py\", line 145, in _run\n",
      "    self._callback(*self._args)\n",
      "  File \"C:\\Users\\donmc\\anaconda3\\envs\\PythonData\\lib\\asyncio\\selector_events.py\", line 141, in _read_from_self\n",
      "    data = self._ssock.recv(4096)\n",
      "ConnectionResetError: [WinError 10054] An existing connection was forcibly closed by the remote host\n",
      "Exception in callback BaseSelectorEventLoop._read_from_self()\n",
      "handle: <Handle BaseSelectorEventLoop._read_from_self()>\n",
      "Traceback (most recent call last):\n",
      "  File \"C:\\Users\\donmc\\anaconda3\\envs\\PythonData\\lib\\asyncio\\events.py\", line 145, in _run\n",
      "    self._callback(*self._args)\n",
      "  File \"C:\\Users\\donmc\\anaconda3\\envs\\PythonData\\lib\\asyncio\\selector_events.py\", line 141, in _read_from_self\n",
      "    data = self._ssock.recv(4096)\n",
      "ConnectionResetError: [WinError 10054] An existing connection was forcibly closed by the remote host\n",
      "Exception in callback BaseSelectorEventLoop._read_from_self()\n",
      "handle: <Handle BaseSelectorEventLoop._read_from_self()>\n",
      "Traceback (most recent call last):\n",
      "  File \"C:\\Users\\donmc\\anaconda3\\envs\\PythonData\\lib\\asyncio\\events.py\", line 145, in _run\n",
      "    self._callback(*self._args)\n",
      "  File \"C:\\Users\\donmc\\anaconda3\\envs\\PythonData\\lib\\asyncio\\selector_events.py\", line 141, in _read_from_self\n",
      "    data = self._ssock.recv(4096)\n",
      "ConnectionResetError: [WinError 10054] An existing connection was forcibly closed by the remote host\n",
      "Exception in callback BaseSelectorEventLoop._read_from_self()\n",
      "handle: <Handle BaseSelectorEventLoop._read_from_self()>\n",
      "Traceback (most recent call last):\n",
      "  File \"C:\\Users\\donmc\\anaconda3\\envs\\PythonData\\lib\\asyncio\\events.py\", line 145, in _run\n",
      "    self._callback(*self._args)\n",
      "  File \"C:\\Users\\donmc\\anaconda3\\envs\\PythonData\\lib\\asyncio\\selector_events.py\", line 141, in _read_from_self\n",
      "    data = self._ssock.recv(4096)\n",
      "ConnectionResetError: [WinError 10054] An existing connection was forcibly closed by the remote host\n",
      "Exception in callback BaseSelectorEventLoop._read_from_self()\n",
      "handle: <Handle BaseSelectorEventLoop._read_from_self()>\n",
      "Traceback (most recent call last):\n",
      "  File \"C:\\Users\\donmc\\anaconda3\\envs\\PythonData\\lib\\asyncio\\events.py\", line 145, in _run\n",
      "    self._callback(*self._args)\n",
      "  File \"C:\\Users\\donmc\\anaconda3\\envs\\PythonData\\lib\\asyncio\\selector_events.py\", line 141, in _read_from_self\n",
      "    data = self._ssock.recv(4096)\n",
      "ConnectionResetError: [WinError 10054] An existing connection was forcibly closed by the remote host\n",
      "Exception in callback BaseSelectorEventLoop._read_from_self()\n",
      "handle: <Handle BaseSelectorEventLoop._read_from_self()>\n",
      "Traceback (most recent call last):\n",
      "  File \"C:\\Users\\donmc\\anaconda3\\envs\\PythonData\\lib\\asyncio\\events.py\", line 145, in _run\n",
      "    self._callback(*self._args)\n",
      "  File \"C:\\Users\\donmc\\anaconda3\\envs\\PythonData\\lib\\asyncio\\selector_events.py\", line 141, in _read_from_self\n",
      "    data = self._ssock.recv(4096)\n",
      "ConnectionResetError: [WinError 10054] An existing connection was forcibly closed by the remote host\n",
      "Exception in callback BaseSelectorEventLoop._read_from_self()\n",
      "handle: <Handle BaseSelectorEventLoop._read_from_self()>\n",
      "Traceback (most recent call last):\n",
      "  File \"C:\\Users\\donmc\\anaconda3\\envs\\PythonData\\lib\\asyncio\\events.py\", line 145, in _run\n",
      "    self._callback(*self._args)\n",
      "  File \"C:\\Users\\donmc\\anaconda3\\envs\\PythonData\\lib\\asyncio\\selector_events.py\", line 141, in _read_from_self\n",
      "    data = self._ssock.recv(4096)\n",
      "ConnectionResetError: [WinError 10054] An existing connection was forcibly closed by the remote host\n",
      "Exception in callback BaseSelectorEventLoop._read_from_self()\n",
      "handle: <Handle BaseSelectorEventLoop._read_from_self()>\n",
      "Traceback (most recent call last):\n",
      "  File \"C:\\Users\\donmc\\anaconda3\\envs\\PythonData\\lib\\asyncio\\events.py\", line 145, in _run\n",
      "    self._callback(*self._args)\n",
      "  File \"C:\\Users\\donmc\\anaconda3\\envs\\PythonData\\lib\\asyncio\\selector_events.py\", line 141, in _read_from_self\n",
      "    data = self._ssock.recv(4096)\n",
      "ConnectionResetError: [WinError 10054] An existing connection was forcibly closed by the remote host\n",
      "Exception in callback BaseSelectorEventLoop._read_from_self()\n",
      "handle: <Handle BaseSelectorEventLoop._read_from_self()>\n",
      "Traceback (most recent call last):\n",
      "  File \"C:\\Users\\donmc\\anaconda3\\envs\\PythonData\\lib\\asyncio\\events.py\", line 145, in _run\n",
      "    self._callback(*self._args)\n",
      "  File \"C:\\Users\\donmc\\anaconda3\\envs\\PythonData\\lib\\asyncio\\selector_events.py\", line 141, in _read_from_self\n",
      "    data = self._ssock.recv(4096)\n",
      "ConnectionResetError: [WinError 10054] An existing connection was forcibly closed by the remote host\n",
      "Exception in callback BaseSelectorEventLoop._read_from_self()\n",
      "handle: <Handle BaseSelectorEventLoop._read_from_self()>\n",
      "Traceback (most recent call last):\n",
      "  File \"C:\\Users\\donmc\\anaconda3\\envs\\PythonData\\lib\\asyncio\\events.py\", line 145, in _run\n",
      "    self._callback(*self._args)\n",
      "  File \"C:\\Users\\donmc\\anaconda3\\envs\\PythonData\\lib\\asyncio\\selector_events.py\", line 141, in _read_from_self\n",
      "    data = self._ssock.recv(4096)\n",
      "ConnectionResetError: [WinError 10054] An existing connection was forcibly closed by the remote host\n",
      "Exception in callback BaseSelectorEventLoop._read_from_self()\n",
      "handle: <Handle BaseSelectorEventLoop._read_from_self()>\n",
      "Traceback (most recent call last):\n",
      "  File \"C:\\Users\\donmc\\anaconda3\\envs\\PythonData\\lib\\asyncio\\events.py\", line 145, in _run\n",
      "    self._callback(*self._args)\n",
      "  File \"C:\\Users\\donmc\\anaconda3\\envs\\PythonData\\lib\\asyncio\\selector_events.py\", line 141, in _read_from_self\n",
      "    data = self._ssock.recv(4096)\n",
      "ConnectionResetError: [WinError 10054] An existing connection was forcibly closed by the remote host\n",
      "Exception in callback BaseSelectorEventLoop._read_from_self()\n",
      "handle: <Handle BaseSelectorEventLoop._read_from_self()>\n",
      "Traceback (most recent call last):\n",
      "  File \"C:\\Users\\donmc\\anaconda3\\envs\\PythonData\\lib\\asyncio\\events.py\", line 145, in _run\n",
      "    self._callback(*self._args)\n",
      "  File \"C:\\Users\\donmc\\anaconda3\\envs\\PythonData\\lib\\asyncio\\selector_events.py\", line 141, in _read_from_self\n",
      "    data = self._ssock.recv(4096)\n",
      "ConnectionResetError: [WinError 10054] An existing connection was forcibly closed by the remote host\n",
      "Exception in callback BaseSelectorEventLoop._read_from_self()\n",
      "handle: <Handle BaseSelectorEventLoop._read_from_self()>\n",
      "Traceback (most recent call last):\n",
      "  File \"C:\\Users\\donmc\\anaconda3\\envs\\PythonData\\lib\\asyncio\\events.py\", line 145, in _run\n",
      "    self._callback(*self._args)\n",
      "  File \"C:\\Users\\donmc\\anaconda3\\envs\\PythonData\\lib\\asyncio\\selector_events.py\", line 141, in _read_from_self\n",
      "    data = self._ssock.recv(4096)\n",
      "ConnectionResetError: [WinError 10054] An existing connection was forcibly closed by the remote host\n",
      "Exception in callback BaseSelectorEventLoop._read_from_self()\n",
      "handle: <Handle BaseSelectorEventLoop._read_from_self()>\n",
      "Traceback (most recent call last):\n",
      "  File \"C:\\Users\\donmc\\anaconda3\\envs\\PythonData\\lib\\asyncio\\events.py\", line 145, in _run\n",
      "    self._callback(*self._args)\n",
      "  File \"C:\\Users\\donmc\\anaconda3\\envs\\PythonData\\lib\\asyncio\\selector_events.py\", line 141, in _read_from_self\n",
      "    data = self._ssock.recv(4096)\n",
      "ConnectionResetError: [WinError 10054] An existing connection was forcibly closed by the remote host\n",
      "Exception in callback BaseSelectorEventLoop._read_from_self()\n",
      "handle: <Handle BaseSelectorEventLoop._read_from_self()>\n",
      "Traceback (most recent call last):\n",
      "  File \"C:\\Users\\donmc\\anaconda3\\envs\\PythonData\\lib\\asyncio\\events.py\", line 145, in _run\n",
      "    self._callback(*self._args)\n",
      "  File \"C:\\Users\\donmc\\anaconda3\\envs\\PythonData\\lib\\asyncio\\selector_events.py\", line 141, in _read_from_self\n",
      "    data = self._ssock.recv(4096)\n",
      "ConnectionResetError: [WinError 10054] An existing connection was forcibly closed by the remote host\n",
      "Exception in callback BaseSelectorEventLoop._read_from_self()\n",
      "handle: <Handle BaseSelectorEventLoop._read_from_self()>\n",
      "Traceback (most recent call last):\n",
      "  File \"C:\\Users\\donmc\\anaconda3\\envs\\PythonData\\lib\\asyncio\\events.py\", line 145, in _run\n",
      "    self._callback(*self._args)\n",
      "  File \"C:\\Users\\donmc\\anaconda3\\envs\\PythonData\\lib\\asyncio\\selector_events.py\", line 141, in _read_from_self\n",
      "    data = self._ssock.recv(4096)\n",
      "ConnectionResetError: [WinError 10054] An existing connection was forcibly closed by the remote host\n"
     ]
    },
    {
     "name": "stderr",
     "output_type": "stream",
     "text": [
      "Exception in callback BaseSelectorEventLoop._read_from_self()\n",
      "handle: <Handle BaseSelectorEventLoop._read_from_self()>\n",
      "Traceback (most recent call last):\n",
      "  File \"C:\\Users\\donmc\\anaconda3\\envs\\PythonData\\lib\\asyncio\\events.py\", line 145, in _run\n",
      "    self._callback(*self._args)\n",
      "  File \"C:\\Users\\donmc\\anaconda3\\envs\\PythonData\\lib\\asyncio\\selector_events.py\", line 141, in _read_from_self\n",
      "    data = self._ssock.recv(4096)\n",
      "ConnectionResetError: [WinError 10054] An existing connection was forcibly closed by the remote host\n",
      "Exception in callback BaseSelectorEventLoop._read_from_self()\n",
      "handle: <Handle BaseSelectorEventLoop._read_from_self()>\n",
      "Traceback (most recent call last):\n",
      "  File \"C:\\Users\\donmc\\anaconda3\\envs\\PythonData\\lib\\asyncio\\events.py\", line 145, in _run\n",
      "    self._callback(*self._args)\n",
      "  File \"C:\\Users\\donmc\\anaconda3\\envs\\PythonData\\lib\\asyncio\\selector_events.py\", line 141, in _read_from_self\n",
      "    data = self._ssock.recv(4096)\n",
      "ConnectionResetError: [WinError 10054] An existing connection was forcibly closed by the remote host\n",
      "Exception in callback BaseSelectorEventLoop._read_from_self()\n",
      "handle: <Handle BaseSelectorEventLoop._read_from_self()>\n",
      "Traceback (most recent call last):\n",
      "  File \"C:\\Users\\donmc\\anaconda3\\envs\\PythonData\\lib\\asyncio\\events.py\", line 145, in _run\n",
      "    self._callback(*self._args)\n",
      "  File \"C:\\Users\\donmc\\anaconda3\\envs\\PythonData\\lib\\asyncio\\selector_events.py\", line 141, in _read_from_self\n",
      "    data = self._ssock.recv(4096)\n",
      "ConnectionResetError: [WinError 10054] An existing connection was forcibly closed by the remote host\n",
      "Exception in callback BaseSelectorEventLoop._read_from_self()\n",
      "handle: <Handle BaseSelectorEventLoop._read_from_self()>\n",
      "Traceback (most recent call last):\n",
      "  File \"C:\\Users\\donmc\\anaconda3\\envs\\PythonData\\lib\\asyncio\\events.py\", line 145, in _run\n",
      "    self._callback(*self._args)\n",
      "  File \"C:\\Users\\donmc\\anaconda3\\envs\\PythonData\\lib\\asyncio\\selector_events.py\", line 141, in _read_from_self\n",
      "    data = self._ssock.recv(4096)\n",
      "ConnectionResetError: [WinError 10054] An existing connection was forcibly closed by the remote host\n",
      "Exception in callback BaseSelectorEventLoop._read_from_self()\n",
      "handle: <Handle BaseSelectorEventLoop._read_from_self()>\n",
      "Traceback (most recent call last):\n",
      "  File \"C:\\Users\\donmc\\anaconda3\\envs\\PythonData\\lib\\asyncio\\events.py\", line 145, in _run\n",
      "    self._callback(*self._args)\n",
      "  File \"C:\\Users\\donmc\\anaconda3\\envs\\PythonData\\lib\\asyncio\\selector_events.py\", line 141, in _read_from_self\n",
      "    data = self._ssock.recv(4096)\n",
      "ConnectionResetError: [WinError 10054] An existing connection was forcibly closed by the remote host\n",
      "Exception in callback BaseSelectorEventLoop._read_from_self()\n",
      "handle: <Handle BaseSelectorEventLoop._read_from_self()>\n",
      "Traceback (most recent call last):\n",
      "  File \"C:\\Users\\donmc\\anaconda3\\envs\\PythonData\\lib\\asyncio\\events.py\", line 145, in _run\n",
      "    self._callback(*self._args)\n",
      "  File \"C:\\Users\\donmc\\anaconda3\\envs\\PythonData\\lib\\asyncio\\selector_events.py\", line 141, in _read_from_self\n",
      "    data = self._ssock.recv(4096)\n",
      "ConnectionResetError: [WinError 10054] An existing connection was forcibly closed by the remote host\n",
      "Exception in callback BaseSelectorEventLoop._read_from_self()\n",
      "handle: <Handle BaseSelectorEventLoop._read_from_self()>\n",
      "Traceback (most recent call last):\n",
      "  File \"C:\\Users\\donmc\\anaconda3\\envs\\PythonData\\lib\\asyncio\\events.py\", line 145, in _run\n",
      "    self._callback(*self._args)\n",
      "  File \"C:\\Users\\donmc\\anaconda3\\envs\\PythonData\\lib\\asyncio\\selector_events.py\", line 141, in _read_from_self\n",
      "    data = self._ssock.recv(4096)\n",
      "ConnectionResetError: [WinError 10054] An existing connection was forcibly closed by the remote host\n",
      "Exception in callback BaseSelectorEventLoop._read_from_self()\n",
      "handle: <Handle BaseSelectorEventLoop._read_from_self()>\n",
      "Traceback (most recent call last):\n",
      "  File \"C:\\Users\\donmc\\anaconda3\\envs\\PythonData\\lib\\asyncio\\events.py\", line 145, in _run\n",
      "    self._callback(*self._args)\n",
      "  File \"C:\\Users\\donmc\\anaconda3\\envs\\PythonData\\lib\\asyncio\\selector_events.py\", line 141, in _read_from_self\n",
      "    data = self._ssock.recv(4096)\n",
      "ConnectionResetError: [WinError 10054] An existing connection was forcibly closed by the remote host\n",
      "Exception in callback BaseSelectorEventLoop._read_from_self()\n",
      "handle: <Handle BaseSelectorEventLoop._read_from_self()>\n",
      "Traceback (most recent call last):\n",
      "  File \"C:\\Users\\donmc\\anaconda3\\envs\\PythonData\\lib\\asyncio\\events.py\", line 145, in _run\n",
      "    self._callback(*self._args)\n",
      "  File \"C:\\Users\\donmc\\anaconda3\\envs\\PythonData\\lib\\asyncio\\selector_events.py\", line 141, in _read_from_self\n",
      "    data = self._ssock.recv(4096)\n",
      "ConnectionResetError: [WinError 10054] An existing connection was forcibly closed by the remote host\n",
      "Exception in callback BaseSelectorEventLoop._read_from_self()\n",
      "handle: <Handle BaseSelectorEventLoop._read_from_self()>\n",
      "Traceback (most recent call last):\n",
      "  File \"C:\\Users\\donmc\\anaconda3\\envs\\PythonData\\lib\\asyncio\\events.py\", line 145, in _run\n",
      "    self._callback(*self._args)\n",
      "  File \"C:\\Users\\donmc\\anaconda3\\envs\\PythonData\\lib\\asyncio\\selector_events.py\", line 141, in _read_from_self\n",
      "    data = self._ssock.recv(4096)\n",
      "ConnectionResetError: [WinError 10054] An existing connection was forcibly closed by the remote host\n",
      "Exception in callback BaseSelectorEventLoop._read_from_self()\n",
      "handle: <Handle BaseSelectorEventLoop._read_from_self()>\n",
      "Traceback (most recent call last):\n",
      "  File \"C:\\Users\\donmc\\anaconda3\\envs\\PythonData\\lib\\asyncio\\events.py\", line 145, in _run\n",
      "    self._callback(*self._args)\n",
      "  File \"C:\\Users\\donmc\\anaconda3\\envs\\PythonData\\lib\\asyncio\\selector_events.py\", line 141, in _read_from_self\n",
      "    data = self._ssock.recv(4096)\n",
      "ConnectionResetError: [WinError 10054] An existing connection was forcibly closed by the remote host\n",
      "Exception in callback BaseSelectorEventLoop._read_from_self()\n",
      "handle: <Handle BaseSelectorEventLoop._read_from_self()>\n",
      "Traceback (most recent call last):\n",
      "  File \"C:\\Users\\donmc\\anaconda3\\envs\\PythonData\\lib\\asyncio\\events.py\", line 145, in _run\n",
      "    self._callback(*self._args)\n",
      "  File \"C:\\Users\\donmc\\anaconda3\\envs\\PythonData\\lib\\asyncio\\selector_events.py\", line 141, in _read_from_self\n",
      "    data = self._ssock.recv(4096)\n",
      "ConnectionResetError: [WinError 10054] An existing connection was forcibly closed by the remote host\n",
      "Exception in callback BaseSelectorEventLoop._read_from_self()\n",
      "handle: <Handle BaseSelectorEventLoop._read_from_self()>\n",
      "Traceback (most recent call last):\n",
      "  File \"C:\\Users\\donmc\\anaconda3\\envs\\PythonData\\lib\\asyncio\\events.py\", line 145, in _run\n",
      "    self._callback(*self._args)\n",
      "  File \"C:\\Users\\donmc\\anaconda3\\envs\\PythonData\\lib\\asyncio\\selector_events.py\", line 141, in _read_from_self\n",
      "    data = self._ssock.recv(4096)\n",
      "ConnectionResetError: [WinError 10054] An existing connection was forcibly closed by the remote host\n",
      "Exception in callback BaseSelectorEventLoop._read_from_self()\n",
      "handle: <Handle BaseSelectorEventLoop._read_from_self()>\n",
      "Traceback (most recent call last):\n",
      "  File \"C:\\Users\\donmc\\anaconda3\\envs\\PythonData\\lib\\asyncio\\events.py\", line 145, in _run\n",
      "    self._callback(*self._args)\n",
      "  File \"C:\\Users\\donmc\\anaconda3\\envs\\PythonData\\lib\\asyncio\\selector_events.py\", line 141, in _read_from_self\n",
      "    data = self._ssock.recv(4096)\n",
      "ConnectionResetError: [WinError 10054] An existing connection was forcibly closed by the remote host\n",
      "Exception in callback BaseSelectorEventLoop._read_from_self()\n",
      "handle: <Handle BaseSelectorEventLoop._read_from_self()>\n",
      "Traceback (most recent call last):\n",
      "  File \"C:\\Users\\donmc\\anaconda3\\envs\\PythonData\\lib\\asyncio\\events.py\", line 145, in _run\n",
      "    self._callback(*self._args)\n",
      "  File \"C:\\Users\\donmc\\anaconda3\\envs\\PythonData\\lib\\asyncio\\selector_events.py\", line 141, in _read_from_self\n",
      "    data = self._ssock.recv(4096)\n",
      "ConnectionResetError: [WinError 10054] An existing connection was forcibly closed by the remote host\n",
      "Exception in callback BaseSelectorEventLoop._read_from_self()\n",
      "handle: <Handle BaseSelectorEventLoop._read_from_self()>\n",
      "Traceback (most recent call last):\n",
      "  File \"C:\\Users\\donmc\\anaconda3\\envs\\PythonData\\lib\\asyncio\\events.py\", line 145, in _run\n",
      "    self._callback(*self._args)\n",
      "  File \"C:\\Users\\donmc\\anaconda3\\envs\\PythonData\\lib\\asyncio\\selector_events.py\", line 141, in _read_from_self\n",
      "    data = self._ssock.recv(4096)\n",
      "ConnectionResetError: [WinError 10054] An existing connection was forcibly closed by the remote host\n"
     ]
    },
    {
     "name": "stderr",
     "output_type": "stream",
     "text": [
      "Exception in callback BaseSelectorEventLoop._read_from_self()\n",
      "handle: <Handle BaseSelectorEventLoop._read_from_self()>\n",
      "Traceback (most recent call last):\n",
      "  File \"C:\\Users\\donmc\\anaconda3\\envs\\PythonData\\lib\\asyncio\\events.py\", line 145, in _run\n",
      "    self._callback(*self._args)\n",
      "  File \"C:\\Users\\donmc\\anaconda3\\envs\\PythonData\\lib\\asyncio\\selector_events.py\", line 141, in _read_from_self\n",
      "    data = self._ssock.recv(4096)\n",
      "ConnectionResetError: [WinError 10054] An existing connection was forcibly closed by the remote host\n",
      "Exception in callback BaseSelectorEventLoop._read_from_self()\n",
      "handle: <Handle BaseSelectorEventLoop._read_from_self()>\n",
      "Traceback (most recent call last):\n",
      "  File \"C:\\Users\\donmc\\anaconda3\\envs\\PythonData\\lib\\asyncio\\events.py\", line 145, in _run\n",
      "    self._callback(*self._args)\n",
      "  File \"C:\\Users\\donmc\\anaconda3\\envs\\PythonData\\lib\\asyncio\\selector_events.py\", line 141, in _read_from_self\n",
      "    data = self._ssock.recv(4096)\n",
      "ConnectionResetError: [WinError 10054] An existing connection was forcibly closed by the remote host\n",
      "Exception in callback BaseSelectorEventLoop._read_from_self()\n",
      "handle: <Handle BaseSelectorEventLoop._read_from_self()>\n",
      "Traceback (most recent call last):\n",
      "  File \"C:\\Users\\donmc\\anaconda3\\envs\\PythonData\\lib\\asyncio\\events.py\", line 145, in _run\n",
      "    self._callback(*self._args)\n",
      "  File \"C:\\Users\\donmc\\anaconda3\\envs\\PythonData\\lib\\asyncio\\selector_events.py\", line 141, in _read_from_self\n",
      "    data = self._ssock.recv(4096)\n",
      "ConnectionResetError: [WinError 10054] An existing connection was forcibly closed by the remote host\n",
      "Exception in callback BaseSelectorEventLoop._read_from_self()\n",
      "handle: <Handle BaseSelectorEventLoop._read_from_self()>\n",
      "Traceback (most recent call last):\n",
      "  File \"C:\\Users\\donmc\\anaconda3\\envs\\PythonData\\lib\\asyncio\\events.py\", line 145, in _run\n",
      "    self._callback(*self._args)\n",
      "  File \"C:\\Users\\donmc\\anaconda3\\envs\\PythonData\\lib\\asyncio\\selector_events.py\", line 141, in _read_from_self\n",
      "    data = self._ssock.recv(4096)\n",
      "ConnectionResetError: [WinError 10054] An existing connection was forcibly closed by the remote host\n",
      "Exception in callback BaseSelectorEventLoop._read_from_self()\n",
      "handle: <Handle BaseSelectorEventLoop._read_from_self()>\n",
      "Traceback (most recent call last):\n",
      "  File \"C:\\Users\\donmc\\anaconda3\\envs\\PythonData\\lib\\asyncio\\events.py\", line 145, in _run\n",
      "    self._callback(*self._args)\n",
      "  File \"C:\\Users\\donmc\\anaconda3\\envs\\PythonData\\lib\\asyncio\\selector_events.py\", line 141, in _read_from_self\n",
      "    data = self._ssock.recv(4096)\n",
      "ConnectionResetError: [WinError 10054] An existing connection was forcibly closed by the remote host\n",
      "Exception in callback BaseSelectorEventLoop._read_from_self()\n",
      "handle: <Handle BaseSelectorEventLoop._read_from_self()>\n",
      "Traceback (most recent call last):\n",
      "  File \"C:\\Users\\donmc\\anaconda3\\envs\\PythonData\\lib\\asyncio\\events.py\", line 145, in _run\n",
      "    self._callback(*self._args)\n",
      "  File \"C:\\Users\\donmc\\anaconda3\\envs\\PythonData\\lib\\asyncio\\selector_events.py\", line 141, in _read_from_self\n",
      "    data = self._ssock.recv(4096)\n",
      "ConnectionResetError: [WinError 10054] An existing connection was forcibly closed by the remote host\n",
      "Exception in callback BaseSelectorEventLoop._read_from_self()\n",
      "handle: <Handle BaseSelectorEventLoop._read_from_self()>\n",
      "Traceback (most recent call last):\n",
      "  File \"C:\\Users\\donmc\\anaconda3\\envs\\PythonData\\lib\\asyncio\\events.py\", line 145, in _run\n",
      "    self._callback(*self._args)\n",
      "  File \"C:\\Users\\donmc\\anaconda3\\envs\\PythonData\\lib\\asyncio\\selector_events.py\", line 141, in _read_from_self\n",
      "    data = self._ssock.recv(4096)\n",
      "ConnectionResetError: [WinError 10054] An existing connection was forcibly closed by the remote host\n",
      "Exception in callback BaseSelectorEventLoop._read_from_self()\n",
      "handle: <Handle BaseSelectorEventLoop._read_from_self()>\n",
      "Traceback (most recent call last):\n",
      "  File \"C:\\Users\\donmc\\anaconda3\\envs\\PythonData\\lib\\asyncio\\events.py\", line 145, in _run\n",
      "    self._callback(*self._args)\n",
      "  File \"C:\\Users\\donmc\\anaconda3\\envs\\PythonData\\lib\\asyncio\\selector_events.py\", line 141, in _read_from_self\n",
      "    data = self._ssock.recv(4096)\n",
      "ConnectionResetError: [WinError 10054] An existing connection was forcibly closed by the remote host\n",
      "Exception in callback BaseSelectorEventLoop._read_from_self()\n",
      "handle: <Handle BaseSelectorEventLoop._read_from_self()>\n",
      "Traceback (most recent call last):\n",
      "  File \"C:\\Users\\donmc\\anaconda3\\envs\\PythonData\\lib\\asyncio\\events.py\", line 145, in _run\n",
      "    self._callback(*self._args)\n",
      "  File \"C:\\Users\\donmc\\anaconda3\\envs\\PythonData\\lib\\asyncio\\selector_events.py\", line 141, in _read_from_self\n",
      "    data = self._ssock.recv(4096)\n",
      "ConnectionResetError: [WinError 10054] An existing connection was forcibly closed by the remote host\n",
      "Exception in callback BaseSelectorEventLoop._read_from_self()\n",
      "handle: <Handle BaseSelectorEventLoop._read_from_self()>\n",
      "Traceback (most recent call last):\n",
      "  File \"C:\\Users\\donmc\\anaconda3\\envs\\PythonData\\lib\\asyncio\\events.py\", line 145, in _run\n",
      "    self._callback(*self._args)\n",
      "  File \"C:\\Users\\donmc\\anaconda3\\envs\\PythonData\\lib\\asyncio\\selector_events.py\", line 141, in _read_from_self\n",
      "    data = self._ssock.recv(4096)\n",
      "ConnectionResetError: [WinError 10054] An existing connection was forcibly closed by the remote host\n",
      "Exception in callback BaseSelectorEventLoop._read_from_self()\n",
      "handle: <Handle BaseSelectorEventLoop._read_from_self()>\n",
      "Traceback (most recent call last):\n",
      "  File \"C:\\Users\\donmc\\anaconda3\\envs\\PythonData\\lib\\asyncio\\events.py\", line 145, in _run\n",
      "    self._callback(*self._args)\n",
      "  File \"C:\\Users\\donmc\\anaconda3\\envs\\PythonData\\lib\\asyncio\\selector_events.py\", line 141, in _read_from_self\n",
      "    data = self._ssock.recv(4096)\n",
      "ConnectionResetError: [WinError 10054] An existing connection was forcibly closed by the remote host\n",
      "Exception in callback BaseSelectorEventLoop._read_from_self()\n",
      "handle: <Handle BaseSelectorEventLoop._read_from_self()>\n",
      "Traceback (most recent call last):\n",
      "  File \"C:\\Users\\donmc\\anaconda3\\envs\\PythonData\\lib\\asyncio\\events.py\", line 145, in _run\n",
      "    self._callback(*self._args)\n",
      "  File \"C:\\Users\\donmc\\anaconda3\\envs\\PythonData\\lib\\asyncio\\selector_events.py\", line 141, in _read_from_self\n",
      "    data = self._ssock.recv(4096)\n",
      "ConnectionResetError: [WinError 10054] An existing connection was forcibly closed by the remote host\n",
      "Exception in callback BaseSelectorEventLoop._read_from_self()\n",
      "handle: <Handle BaseSelectorEventLoop._read_from_self()>\n",
      "Traceback (most recent call last):\n",
      "  File \"C:\\Users\\donmc\\anaconda3\\envs\\PythonData\\lib\\asyncio\\events.py\", line 145, in _run\n",
      "    self._callback(*self._args)\n",
      "  File \"C:\\Users\\donmc\\anaconda3\\envs\\PythonData\\lib\\asyncio\\selector_events.py\", line 141, in _read_from_self\n",
      "    data = self._ssock.recv(4096)\n",
      "ConnectionResetError: [WinError 10054] An existing connection was forcibly closed by the remote host\n",
      "Exception in callback BaseSelectorEventLoop._read_from_self()\n",
      "handle: <Handle BaseSelectorEventLoop._read_from_self()>\n",
      "Traceback (most recent call last):\n",
      "  File \"C:\\Users\\donmc\\anaconda3\\envs\\PythonData\\lib\\asyncio\\events.py\", line 145, in _run\n",
      "    self._callback(*self._args)\n",
      "  File \"C:\\Users\\donmc\\anaconda3\\envs\\PythonData\\lib\\asyncio\\selector_events.py\", line 141, in _read_from_self\n",
      "    data = self._ssock.recv(4096)\n",
      "ConnectionResetError: [WinError 10054] An existing connection was forcibly closed by the remote host\n",
      "Exception in callback BaseSelectorEventLoop._read_from_self()\n",
      "handle: <Handle BaseSelectorEventLoop._read_from_self()>\n",
      "Traceback (most recent call last):\n",
      "  File \"C:\\Users\\donmc\\anaconda3\\envs\\PythonData\\lib\\asyncio\\events.py\", line 145, in _run\n",
      "    self._callback(*self._args)\n",
      "  File \"C:\\Users\\donmc\\anaconda3\\envs\\PythonData\\lib\\asyncio\\selector_events.py\", line 141, in _read_from_self\n",
      "    data = self._ssock.recv(4096)\n",
      "ConnectionResetError: [WinError 10054] An existing connection was forcibly closed by the remote host\n",
      "Exception in callback BaseSelectorEventLoop._read_from_self()\n",
      "handle: <Handle BaseSelectorEventLoop._read_from_self()>\n",
      "Traceback (most recent call last):\n",
      "  File \"C:\\Users\\donmc\\anaconda3\\envs\\PythonData\\lib\\asyncio\\events.py\", line 145, in _run\n",
      "    self._callback(*self._args)\n",
      "  File \"C:\\Users\\donmc\\anaconda3\\envs\\PythonData\\lib\\asyncio\\selector_events.py\", line 141, in _read_from_self\n",
      "    data = self._ssock.recv(4096)\n",
      "ConnectionResetError: [WinError 10054] An existing connection was forcibly closed by the remote host\n"
     ]
    },
    {
     "name": "stderr",
     "output_type": "stream",
     "text": [
      "Exception in callback BaseSelectorEventLoop._read_from_self()\n",
      "handle: <Handle BaseSelectorEventLoop._read_from_self()>\n",
      "Traceback (most recent call last):\n",
      "  File \"C:\\Users\\donmc\\anaconda3\\envs\\PythonData\\lib\\asyncio\\events.py\", line 145, in _run\n",
      "    self._callback(*self._args)\n",
      "  File \"C:\\Users\\donmc\\anaconda3\\envs\\PythonData\\lib\\asyncio\\selector_events.py\", line 141, in _read_from_self\n",
      "    data = self._ssock.recv(4096)\n",
      "ConnectionResetError: [WinError 10054] An existing connection was forcibly closed by the remote host\n",
      "Exception in callback BaseSelectorEventLoop._read_from_self()\n",
      "handle: <Handle BaseSelectorEventLoop._read_from_self()>\n",
      "Traceback (most recent call last):\n",
      "  File \"C:\\Users\\donmc\\anaconda3\\envs\\PythonData\\lib\\asyncio\\events.py\", line 145, in _run\n",
      "    self._callback(*self._args)\n",
      "  File \"C:\\Users\\donmc\\anaconda3\\envs\\PythonData\\lib\\asyncio\\selector_events.py\", line 141, in _read_from_self\n",
      "    data = self._ssock.recv(4096)\n",
      "ConnectionResetError: [WinError 10054] An existing connection was forcibly closed by the remote host\n",
      "Exception in callback BaseSelectorEventLoop._read_from_self()\n",
      "handle: <Handle BaseSelectorEventLoop._read_from_self()>\n",
      "Traceback (most recent call last):\n",
      "  File \"C:\\Users\\donmc\\anaconda3\\envs\\PythonData\\lib\\asyncio\\events.py\", line 145, in _run\n",
      "    self._callback(*self._args)\n",
      "  File \"C:\\Users\\donmc\\anaconda3\\envs\\PythonData\\lib\\asyncio\\selector_events.py\", line 141, in _read_from_self\n",
      "    data = self._ssock.recv(4096)\n",
      "ConnectionResetError: [WinError 10054] An existing connection was forcibly closed by the remote host\n",
      "Exception in callback BaseSelectorEventLoop._read_from_self()\n",
      "handle: <Handle BaseSelectorEventLoop._read_from_self()>\n",
      "Traceback (most recent call last):\n",
      "  File \"C:\\Users\\donmc\\anaconda3\\envs\\PythonData\\lib\\asyncio\\events.py\", line 145, in _run\n",
      "    self._callback(*self._args)\n",
      "  File \"C:\\Users\\donmc\\anaconda3\\envs\\PythonData\\lib\\asyncio\\selector_events.py\", line 141, in _read_from_self\n",
      "    data = self._ssock.recv(4096)\n",
      "ConnectionResetError: [WinError 10054] An existing connection was forcibly closed by the remote host\n",
      "Exception in callback BaseSelectorEventLoop._read_from_self()\n",
      "handle: <Handle BaseSelectorEventLoop._read_from_self()>\n",
      "Traceback (most recent call last):\n",
      "  File \"C:\\Users\\donmc\\anaconda3\\envs\\PythonData\\lib\\asyncio\\events.py\", line 145, in _run\n",
      "    self._callback(*self._args)\n",
      "  File \"C:\\Users\\donmc\\anaconda3\\envs\\PythonData\\lib\\asyncio\\selector_events.py\", line 141, in _read_from_self\n",
      "    data = self._ssock.recv(4096)\n",
      "ConnectionResetError: [WinError 10054] An existing connection was forcibly closed by the remote host\n",
      "Exception in callback BaseSelectorEventLoop._read_from_self()\n",
      "handle: <Handle BaseSelectorEventLoop._read_from_self()>\n",
      "Traceback (most recent call last):\n",
      "  File \"C:\\Users\\donmc\\anaconda3\\envs\\PythonData\\lib\\asyncio\\events.py\", line 145, in _run\n",
      "    self._callback(*self._args)\n",
      "  File \"C:\\Users\\donmc\\anaconda3\\envs\\PythonData\\lib\\asyncio\\selector_events.py\", line 141, in _read_from_self\n",
      "    data = self._ssock.recv(4096)\n",
      "ConnectionResetError: [WinError 10054] An existing connection was forcibly closed by the remote host\n",
      "Exception in callback BaseSelectorEventLoop._read_from_self()\n",
      "handle: <Handle BaseSelectorEventLoop._read_from_self()>\n",
      "Traceback (most recent call last):\n",
      "  File \"C:\\Users\\donmc\\anaconda3\\envs\\PythonData\\lib\\asyncio\\events.py\", line 145, in _run\n",
      "    self._callback(*self._args)\n",
      "  File \"C:\\Users\\donmc\\anaconda3\\envs\\PythonData\\lib\\asyncio\\selector_events.py\", line 141, in _read_from_self\n",
      "    data = self._ssock.recv(4096)\n",
      "ConnectionResetError: [WinError 10054] An existing connection was forcibly closed by the remote host\n",
      "Exception in callback BaseSelectorEventLoop._read_from_self()\n",
      "handle: <Handle BaseSelectorEventLoop._read_from_self()>\n",
      "Traceback (most recent call last):\n",
      "  File \"C:\\Users\\donmc\\anaconda3\\envs\\PythonData\\lib\\asyncio\\events.py\", line 145, in _run\n",
      "    self._callback(*self._args)\n",
      "  File \"C:\\Users\\donmc\\anaconda3\\envs\\PythonData\\lib\\asyncio\\selector_events.py\", line 141, in _read_from_self\n",
      "    data = self._ssock.recv(4096)\n",
      "ConnectionResetError: [WinError 10054] An existing connection was forcibly closed by the remote host\n",
      "Exception in callback BaseSelectorEventLoop._read_from_self()\n",
      "handle: <Handle BaseSelectorEventLoop._read_from_self()>\n",
      "Traceback (most recent call last):\n",
      "  File \"C:\\Users\\donmc\\anaconda3\\envs\\PythonData\\lib\\asyncio\\events.py\", line 145, in _run\n",
      "    self._callback(*self._args)\n",
      "  File \"C:\\Users\\donmc\\anaconda3\\envs\\PythonData\\lib\\asyncio\\selector_events.py\", line 141, in _read_from_self\n",
      "    data = self._ssock.recv(4096)\n",
      "ConnectionResetError: [WinError 10054] An existing connection was forcibly closed by the remote host\n",
      "Exception in callback BaseSelectorEventLoop._read_from_self()\n",
      "handle: <Handle BaseSelectorEventLoop._read_from_self()>\n",
      "Traceback (most recent call last):\n",
      "  File \"C:\\Users\\donmc\\anaconda3\\envs\\PythonData\\lib\\asyncio\\events.py\", line 145, in _run\n",
      "    self._callback(*self._args)\n",
      "  File \"C:\\Users\\donmc\\anaconda3\\envs\\PythonData\\lib\\asyncio\\selector_events.py\", line 141, in _read_from_self\n",
      "    data = self._ssock.recv(4096)\n",
      "ConnectionResetError: [WinError 10054] An existing connection was forcibly closed by the remote host\n",
      "Exception in callback BaseSelectorEventLoop._read_from_self()\n",
      "handle: <Handle BaseSelectorEventLoop._read_from_self()>\n",
      "Traceback (most recent call last):\n",
      "  File \"C:\\Users\\donmc\\anaconda3\\envs\\PythonData\\lib\\asyncio\\events.py\", line 145, in _run\n",
      "    self._callback(*self._args)\n",
      "  File \"C:\\Users\\donmc\\anaconda3\\envs\\PythonData\\lib\\asyncio\\selector_events.py\", line 141, in _read_from_self\n",
      "    data = self._ssock.recv(4096)\n",
      "ConnectionResetError: [WinError 10054] An existing connection was forcibly closed by the remote host\n",
      "Exception in callback BaseSelectorEventLoop._read_from_self()\n",
      "handle: <Handle BaseSelectorEventLoop._read_from_self()>\n",
      "Traceback (most recent call last):\n",
      "  File \"C:\\Users\\donmc\\anaconda3\\envs\\PythonData\\lib\\asyncio\\events.py\", line 145, in _run\n",
      "    self._callback(*self._args)\n",
      "  File \"C:\\Users\\donmc\\anaconda3\\envs\\PythonData\\lib\\asyncio\\selector_events.py\", line 141, in _read_from_self\n",
      "    data = self._ssock.recv(4096)\n",
      "ConnectionResetError: [WinError 10054] An existing connection was forcibly closed by the remote host\n",
      "Exception in callback BaseSelectorEventLoop._read_from_self()\n",
      "handle: <Handle BaseSelectorEventLoop._read_from_self()>\n",
      "Traceback (most recent call last):\n",
      "  File \"C:\\Users\\donmc\\anaconda3\\envs\\PythonData\\lib\\asyncio\\events.py\", line 145, in _run\n",
      "    self._callback(*self._args)\n",
      "  File \"C:\\Users\\donmc\\anaconda3\\envs\\PythonData\\lib\\asyncio\\selector_events.py\", line 141, in _read_from_self\n",
      "    data = self._ssock.recv(4096)\n",
      "ConnectionResetError: [WinError 10054] An existing connection was forcibly closed by the remote host\n",
      "Exception in callback BaseSelectorEventLoop._read_from_self()\n",
      "handle: <Handle BaseSelectorEventLoop._read_from_self()>\n",
      "Traceback (most recent call last):\n",
      "  File \"C:\\Users\\donmc\\anaconda3\\envs\\PythonData\\lib\\asyncio\\events.py\", line 145, in _run\n",
      "    self._callback(*self._args)\n",
      "  File \"C:\\Users\\donmc\\anaconda3\\envs\\PythonData\\lib\\asyncio\\selector_events.py\", line 141, in _read_from_self\n",
      "    data = self._ssock.recv(4096)\n",
      "ConnectionResetError: [WinError 10054] An existing connection was forcibly closed by the remote host\n",
      "Exception in callback BaseSelectorEventLoop._read_from_self()\n",
      "handle: <Handle BaseSelectorEventLoop._read_from_self()>\n",
      "Traceback (most recent call last):\n",
      "  File \"C:\\Users\\donmc\\anaconda3\\envs\\PythonData\\lib\\asyncio\\events.py\", line 145, in _run\n",
      "    self._callback(*self._args)\n",
      "  File \"C:\\Users\\donmc\\anaconda3\\envs\\PythonData\\lib\\asyncio\\selector_events.py\", line 141, in _read_from_self\n",
      "    data = self._ssock.recv(4096)\n",
      "ConnectionResetError: [WinError 10054] An existing connection was forcibly closed by the remote host\n",
      "Exception in callback BaseSelectorEventLoop._read_from_self()\n",
      "handle: <Handle BaseSelectorEventLoop._read_from_self()>\n",
      "Traceback (most recent call last):\n",
      "  File \"C:\\Users\\donmc\\anaconda3\\envs\\PythonData\\lib\\asyncio\\events.py\", line 145, in _run\n",
      "    self._callback(*self._args)\n",
      "  File \"C:\\Users\\donmc\\anaconda3\\envs\\PythonData\\lib\\asyncio\\selector_events.py\", line 141, in _read_from_self\n",
      "    data = self._ssock.recv(4096)\n",
      "ConnectionResetError: [WinError 10054] An existing connection was forcibly closed by the remote host\n"
     ]
    },
    {
     "name": "stderr",
     "output_type": "stream",
     "text": [
      "Exception in callback BaseSelectorEventLoop._read_from_self()\n",
      "handle: <Handle BaseSelectorEventLoop._read_from_self()>\n",
      "Traceback (most recent call last):\n",
      "  File \"C:\\Users\\donmc\\anaconda3\\envs\\PythonData\\lib\\asyncio\\events.py\", line 145, in _run\n",
      "    self._callback(*self._args)\n",
      "  File \"C:\\Users\\donmc\\anaconda3\\envs\\PythonData\\lib\\asyncio\\selector_events.py\", line 141, in _read_from_self\n",
      "    data = self._ssock.recv(4096)\n",
      "ConnectionResetError: [WinError 10054] An existing connection was forcibly closed by the remote host\n",
      "Exception in callback BaseSelectorEventLoop._read_from_self()\n",
      "handle: <Handle BaseSelectorEventLoop._read_from_self()>\n",
      "Traceback (most recent call last):\n",
      "  File \"C:\\Users\\donmc\\anaconda3\\envs\\PythonData\\lib\\asyncio\\events.py\", line 145, in _run\n",
      "    self._callback(*self._args)\n",
      "  File \"C:\\Users\\donmc\\anaconda3\\envs\\PythonData\\lib\\asyncio\\selector_events.py\", line 141, in _read_from_self\n",
      "    data = self._ssock.recv(4096)\n",
      "ConnectionResetError: [WinError 10054] An existing connection was forcibly closed by the remote host\n",
      "Exception in callback BaseSelectorEventLoop._read_from_self()\n",
      "handle: <Handle BaseSelectorEventLoop._read_from_self()>\n",
      "Traceback (most recent call last):\n",
      "  File \"C:\\Users\\donmc\\anaconda3\\envs\\PythonData\\lib\\asyncio\\events.py\", line 145, in _run\n",
      "    self._callback(*self._args)\n",
      "  File \"C:\\Users\\donmc\\anaconda3\\envs\\PythonData\\lib\\asyncio\\selector_events.py\", line 141, in _read_from_self\n",
      "    data = self._ssock.recv(4096)\n",
      "ConnectionResetError: [WinError 10054] An existing connection was forcibly closed by the remote host\n",
      "Exception in callback BaseSelectorEventLoop._read_from_self()\n",
      "handle: <Handle BaseSelectorEventLoop._read_from_self()>\n",
      "Traceback (most recent call last):\n",
      "  File \"C:\\Users\\donmc\\anaconda3\\envs\\PythonData\\lib\\asyncio\\events.py\", line 145, in _run\n",
      "    self._callback(*self._args)\n",
      "  File \"C:\\Users\\donmc\\anaconda3\\envs\\PythonData\\lib\\asyncio\\selector_events.py\", line 141, in _read_from_self\n",
      "    data = self._ssock.recv(4096)\n",
      "ConnectionResetError: [WinError 10054] An existing connection was forcibly closed by the remote host\n",
      "Exception in callback BaseSelectorEventLoop._read_from_self()\n",
      "handle: <Handle BaseSelectorEventLoop._read_from_self()>\n",
      "Traceback (most recent call last):\n",
      "  File \"C:\\Users\\donmc\\anaconda3\\envs\\PythonData\\lib\\asyncio\\events.py\", line 145, in _run\n",
      "    self._callback(*self._args)\n",
      "  File \"C:\\Users\\donmc\\anaconda3\\envs\\PythonData\\lib\\asyncio\\selector_events.py\", line 141, in _read_from_self\n",
      "    data = self._ssock.recv(4096)\n",
      "ConnectionResetError: [WinError 10054] An existing connection was forcibly closed by the remote host\n",
      "Exception in callback BaseSelectorEventLoop._read_from_self()\n",
      "handle: <Handle BaseSelectorEventLoop._read_from_self()>\n",
      "Traceback (most recent call last):\n",
      "  File \"C:\\Users\\donmc\\anaconda3\\envs\\PythonData\\lib\\asyncio\\events.py\", line 145, in _run\n",
      "    self._callback(*self._args)\n",
      "  File \"C:\\Users\\donmc\\anaconda3\\envs\\PythonData\\lib\\asyncio\\selector_events.py\", line 141, in _read_from_self\n",
      "    data = self._ssock.recv(4096)\n",
      "ConnectionResetError: [WinError 10054] An existing connection was forcibly closed by the remote host\n",
      "Exception in callback BaseSelectorEventLoop._read_from_self()\n",
      "handle: <Handle BaseSelectorEventLoop._read_from_self()>\n",
      "Traceback (most recent call last):\n",
      "  File \"C:\\Users\\donmc\\anaconda3\\envs\\PythonData\\lib\\asyncio\\events.py\", line 145, in _run\n",
      "    self._callback(*self._args)\n",
      "  File \"C:\\Users\\donmc\\anaconda3\\envs\\PythonData\\lib\\asyncio\\selector_events.py\", line 141, in _read_from_self\n",
      "    data = self._ssock.recv(4096)\n",
      "ConnectionResetError: [WinError 10054] An existing connection was forcibly closed by the remote host\n",
      "Exception in callback BaseSelectorEventLoop._read_from_self()\n",
      "handle: <Handle BaseSelectorEventLoop._read_from_self()>\n",
      "Traceback (most recent call last):\n",
      "  File \"C:\\Users\\donmc\\anaconda3\\envs\\PythonData\\lib\\asyncio\\events.py\", line 145, in _run\n",
      "    self._callback(*self._args)\n",
      "  File \"C:\\Users\\donmc\\anaconda3\\envs\\PythonData\\lib\\asyncio\\selector_events.py\", line 141, in _read_from_self\n",
      "    data = self._ssock.recv(4096)\n",
      "ConnectionResetError: [WinError 10054] An existing connection was forcibly closed by the remote host\n",
      "Exception in callback BaseSelectorEventLoop._read_from_self()\n",
      "handle: <Handle BaseSelectorEventLoop._read_from_self()>\n",
      "Traceback (most recent call last):\n",
      "  File \"C:\\Users\\donmc\\anaconda3\\envs\\PythonData\\lib\\asyncio\\events.py\", line 145, in _run\n",
      "    self._callback(*self._args)\n",
      "  File \"C:\\Users\\donmc\\anaconda3\\envs\\PythonData\\lib\\asyncio\\selector_events.py\", line 141, in _read_from_self\n",
      "    data = self._ssock.recv(4096)\n",
      "ConnectionResetError: [WinError 10054] An existing connection was forcibly closed by the remote host\n",
      "Exception in callback BaseSelectorEventLoop._read_from_self()\n",
      "handle: <Handle BaseSelectorEventLoop._read_from_self()>\n",
      "Traceback (most recent call last):\n",
      "  File \"C:\\Users\\donmc\\anaconda3\\envs\\PythonData\\lib\\asyncio\\events.py\", line 145, in _run\n",
      "    self._callback(*self._args)\n",
      "  File \"C:\\Users\\donmc\\anaconda3\\envs\\PythonData\\lib\\asyncio\\selector_events.py\", line 141, in _read_from_self\n",
      "    data = self._ssock.recv(4096)\n",
      "ConnectionResetError: [WinError 10054] An existing connection was forcibly closed by the remote host\n",
      "Exception in callback BaseSelectorEventLoop._read_from_self()\n",
      "handle: <Handle BaseSelectorEventLoop._read_from_self()>\n",
      "Traceback (most recent call last):\n",
      "  File \"C:\\Users\\donmc\\anaconda3\\envs\\PythonData\\lib\\asyncio\\events.py\", line 145, in _run\n",
      "    self._callback(*self._args)\n",
      "  File \"C:\\Users\\donmc\\anaconda3\\envs\\PythonData\\lib\\asyncio\\selector_events.py\", line 141, in _read_from_self\n",
      "    data = self._ssock.recv(4096)\n",
      "ConnectionResetError: [WinError 10054] An existing connection was forcibly closed by the remote host\n",
      "Exception in callback BaseSelectorEventLoop._read_from_self()\n",
      "handle: <Handle BaseSelectorEventLoop._read_from_self()>\n",
      "Traceback (most recent call last):\n",
      "  File \"C:\\Users\\donmc\\anaconda3\\envs\\PythonData\\lib\\asyncio\\events.py\", line 145, in _run\n",
      "    self._callback(*self._args)\n",
      "  File \"C:\\Users\\donmc\\anaconda3\\envs\\PythonData\\lib\\asyncio\\selector_events.py\", line 141, in _read_from_self\n",
      "    data = self._ssock.recv(4096)\n",
      "ConnectionResetError: [WinError 10054] An existing connection was forcibly closed by the remote host\n",
      "Exception in callback BaseSelectorEventLoop._read_from_self()\n",
      "handle: <Handle BaseSelectorEventLoop._read_from_self()>\n",
      "Traceback (most recent call last):\n",
      "  File \"C:\\Users\\donmc\\anaconda3\\envs\\PythonData\\lib\\asyncio\\events.py\", line 145, in _run\n",
      "    self._callback(*self._args)\n",
      "  File \"C:\\Users\\donmc\\anaconda3\\envs\\PythonData\\lib\\asyncio\\selector_events.py\", line 141, in _read_from_self\n",
      "    data = self._ssock.recv(4096)\n",
      "ConnectionResetError: [WinError 10054] An existing connection was forcibly closed by the remote host\n",
      "Exception in callback BaseSelectorEventLoop._read_from_self()\n",
      "handle: <Handle BaseSelectorEventLoop._read_from_self()>\n",
      "Traceback (most recent call last):\n",
      "  File \"C:\\Users\\donmc\\anaconda3\\envs\\PythonData\\lib\\asyncio\\events.py\", line 145, in _run\n",
      "    self._callback(*self._args)\n",
      "  File \"C:\\Users\\donmc\\anaconda3\\envs\\PythonData\\lib\\asyncio\\selector_events.py\", line 141, in _read_from_self\n",
      "    data = self._ssock.recv(4096)\n",
      "ConnectionResetError: [WinError 10054] An existing connection was forcibly closed by the remote host\n",
      "Exception in callback BaseSelectorEventLoop._read_from_self()\n",
      "handle: <Handle BaseSelectorEventLoop._read_from_self()>\n",
      "Traceback (most recent call last):\n",
      "  File \"C:\\Users\\donmc\\anaconda3\\envs\\PythonData\\lib\\asyncio\\events.py\", line 145, in _run\n",
      "    self._callback(*self._args)\n",
      "  File \"C:\\Users\\donmc\\anaconda3\\envs\\PythonData\\lib\\asyncio\\selector_events.py\", line 141, in _read_from_self\n",
      "    data = self._ssock.recv(4096)\n",
      "ConnectionResetError: [WinError 10054] An existing connection was forcibly closed by the remote host\n",
      "Exception in callback BaseSelectorEventLoop._read_from_self()\n",
      "handle: <Handle BaseSelectorEventLoop._read_from_self()>\n",
      "Traceback (most recent call last):\n",
      "  File \"C:\\Users\\donmc\\anaconda3\\envs\\PythonData\\lib\\asyncio\\events.py\", line 145, in _run\n",
      "    self._callback(*self._args)\n",
      "  File \"C:\\Users\\donmc\\anaconda3\\envs\\PythonData\\lib\\asyncio\\selector_events.py\", line 141, in _read_from_self\n",
      "    data = self._ssock.recv(4096)\n",
      "ConnectionResetError: [WinError 10054] An existing connection was forcibly closed by the remote host\n"
     ]
    },
    {
     "name": "stderr",
     "output_type": "stream",
     "text": [
      "Exception in callback BaseSelectorEventLoop._read_from_self()\n",
      "handle: <Handle BaseSelectorEventLoop._read_from_self()>\n",
      "Traceback (most recent call last):\n",
      "  File \"C:\\Users\\donmc\\anaconda3\\envs\\PythonData\\lib\\asyncio\\events.py\", line 145, in _run\n",
      "    self._callback(*self._args)\n",
      "  File \"C:\\Users\\donmc\\anaconda3\\envs\\PythonData\\lib\\asyncio\\selector_events.py\", line 141, in _read_from_self\n",
      "    data = self._ssock.recv(4096)\n",
      "ConnectionResetError: [WinError 10054] An existing connection was forcibly closed by the remote host\n",
      "Exception in callback BaseSelectorEventLoop._read_from_self()\n",
      "handle: <Handle BaseSelectorEventLoop._read_from_self()>\n",
      "Traceback (most recent call last):\n",
      "  File \"C:\\Users\\donmc\\anaconda3\\envs\\PythonData\\lib\\asyncio\\events.py\", line 145, in _run\n",
      "    self._callback(*self._args)\n",
      "  File \"C:\\Users\\donmc\\anaconda3\\envs\\PythonData\\lib\\asyncio\\selector_events.py\", line 141, in _read_from_self\n",
      "    data = self._ssock.recv(4096)\n",
      "ConnectionResetError: [WinError 10054] An existing connection was forcibly closed by the remote host\n",
      "Exception in callback BaseSelectorEventLoop._read_from_self()\n",
      "handle: <Handle BaseSelectorEventLoop._read_from_self()>\n",
      "Traceback (most recent call last):\n",
      "  File \"C:\\Users\\donmc\\anaconda3\\envs\\PythonData\\lib\\asyncio\\events.py\", line 145, in _run\n",
      "    self._callback(*self._args)\n",
      "  File \"C:\\Users\\donmc\\anaconda3\\envs\\PythonData\\lib\\asyncio\\selector_events.py\", line 141, in _read_from_self\n",
      "    data = self._ssock.recv(4096)\n",
      "ConnectionResetError: [WinError 10054] An existing connection was forcibly closed by the remote host\n",
      "Exception in callback BaseSelectorEventLoop._read_from_self()\n",
      "handle: <Handle BaseSelectorEventLoop._read_from_self()>\n",
      "Traceback (most recent call last):\n",
      "  File \"C:\\Users\\donmc\\anaconda3\\envs\\PythonData\\lib\\asyncio\\events.py\", line 145, in _run\n",
      "    self._callback(*self._args)\n",
      "  File \"C:\\Users\\donmc\\anaconda3\\envs\\PythonData\\lib\\asyncio\\selector_events.py\", line 141, in _read_from_self\n",
      "    data = self._ssock.recv(4096)\n",
      "ConnectionResetError: [WinError 10054] An existing connection was forcibly closed by the remote host\n",
      "Exception in callback BaseSelectorEventLoop._read_from_self()\n",
      "handle: <Handle BaseSelectorEventLoop._read_from_self()>\n",
      "Traceback (most recent call last):\n",
      "  File \"C:\\Users\\donmc\\anaconda3\\envs\\PythonData\\lib\\asyncio\\events.py\", line 145, in _run\n",
      "    self._callback(*self._args)\n",
      "  File \"C:\\Users\\donmc\\anaconda3\\envs\\PythonData\\lib\\asyncio\\selector_events.py\", line 141, in _read_from_self\n",
      "    data = self._ssock.recv(4096)\n",
      "ConnectionResetError: [WinError 10054] An existing connection was forcibly closed by the remote host\n",
      "Exception in callback BaseSelectorEventLoop._read_from_self()\n",
      "handle: <Handle BaseSelectorEventLoop._read_from_self()>\n",
      "Traceback (most recent call last):\n",
      "  File \"C:\\Users\\donmc\\anaconda3\\envs\\PythonData\\lib\\asyncio\\events.py\", line 145, in _run\n",
      "    self._callback(*self._args)\n",
      "  File \"C:\\Users\\donmc\\anaconda3\\envs\\PythonData\\lib\\asyncio\\selector_events.py\", line 141, in _read_from_self\n",
      "    data = self._ssock.recv(4096)\n",
      "ConnectionResetError: [WinError 10054] An existing connection was forcibly closed by the remote host\n",
      "Exception in callback BaseSelectorEventLoop._read_from_self()\n",
      "handle: <Handle BaseSelectorEventLoop._read_from_self()>\n",
      "Traceback (most recent call last):\n",
      "  File \"C:\\Users\\donmc\\anaconda3\\envs\\PythonData\\lib\\asyncio\\events.py\", line 145, in _run\n",
      "    self._callback(*self._args)\n",
      "  File \"C:\\Users\\donmc\\anaconda3\\envs\\PythonData\\lib\\asyncio\\selector_events.py\", line 141, in _read_from_self\n",
      "    data = self._ssock.recv(4096)\n",
      "ConnectionResetError: [WinError 10054] An existing connection was forcibly closed by the remote host\n",
      "Exception in callback BaseSelectorEventLoop._read_from_self()\n",
      "handle: <Handle BaseSelectorEventLoop._read_from_self()>\n",
      "Traceback (most recent call last):\n",
      "  File \"C:\\Users\\donmc\\anaconda3\\envs\\PythonData\\lib\\asyncio\\events.py\", line 145, in _run\n",
      "    self._callback(*self._args)\n",
      "  File \"C:\\Users\\donmc\\anaconda3\\envs\\PythonData\\lib\\asyncio\\selector_events.py\", line 141, in _read_from_self\n",
      "    data = self._ssock.recv(4096)\n",
      "ConnectionResetError: [WinError 10054] An existing connection was forcibly closed by the remote host\n",
      "Exception in callback BaseSelectorEventLoop._read_from_self()\n",
      "handle: <Handle BaseSelectorEventLoop._read_from_self()>\n",
      "Traceback (most recent call last):\n",
      "  File \"C:\\Users\\donmc\\anaconda3\\envs\\PythonData\\lib\\asyncio\\events.py\", line 145, in _run\n",
      "    self._callback(*self._args)\n",
      "  File \"C:\\Users\\donmc\\anaconda3\\envs\\PythonData\\lib\\asyncio\\selector_events.py\", line 141, in _read_from_self\n",
      "    data = self._ssock.recv(4096)\n",
      "ConnectionResetError: [WinError 10054] An existing connection was forcibly closed by the remote host\n",
      "Exception in callback BaseSelectorEventLoop._read_from_self()\n",
      "handle: <Handle BaseSelectorEventLoop._read_from_self()>\n",
      "Traceback (most recent call last):\n",
      "  File \"C:\\Users\\donmc\\anaconda3\\envs\\PythonData\\lib\\asyncio\\events.py\", line 145, in _run\n",
      "    self._callback(*self._args)\n",
      "  File \"C:\\Users\\donmc\\anaconda3\\envs\\PythonData\\lib\\asyncio\\selector_events.py\", line 141, in _read_from_self\n",
      "    data = self._ssock.recv(4096)\n",
      "ConnectionResetError: [WinError 10054] An existing connection was forcibly closed by the remote host\n",
      "Exception in callback BaseSelectorEventLoop._read_from_self()\n",
      "handle: <Handle BaseSelectorEventLoop._read_from_self()>\n",
      "Traceback (most recent call last):\n",
      "  File \"C:\\Users\\donmc\\anaconda3\\envs\\PythonData\\lib\\asyncio\\events.py\", line 145, in _run\n",
      "    self._callback(*self._args)\n",
      "  File \"C:\\Users\\donmc\\anaconda3\\envs\\PythonData\\lib\\asyncio\\selector_events.py\", line 141, in _read_from_self\n",
      "    data = self._ssock.recv(4096)\n",
      "ConnectionResetError: [WinError 10054] An existing connection was forcibly closed by the remote host\n",
      "Exception in callback BaseSelectorEventLoop._read_from_self()\n",
      "handle: <Handle BaseSelectorEventLoop._read_from_self()>\n",
      "Traceback (most recent call last):\n",
      "  File \"C:\\Users\\donmc\\anaconda3\\envs\\PythonData\\lib\\asyncio\\events.py\", line 145, in _run\n",
      "    self._callback(*self._args)\n",
      "  File \"C:\\Users\\donmc\\anaconda3\\envs\\PythonData\\lib\\asyncio\\selector_events.py\", line 141, in _read_from_self\n",
      "    data = self._ssock.recv(4096)\n",
      "ConnectionResetError: [WinError 10054] An existing connection was forcibly closed by the remote host\n",
      "Exception in callback BaseSelectorEventLoop._read_from_self()\n",
      "handle: <Handle BaseSelectorEventLoop._read_from_self()>\n",
      "Traceback (most recent call last):\n",
      "  File \"C:\\Users\\donmc\\anaconda3\\envs\\PythonData\\lib\\asyncio\\events.py\", line 145, in _run\n",
      "    self._callback(*self._args)\n",
      "  File \"C:\\Users\\donmc\\anaconda3\\envs\\PythonData\\lib\\asyncio\\selector_events.py\", line 141, in _read_from_self\n",
      "    data = self._ssock.recv(4096)\n",
      "ConnectionResetError: [WinError 10054] An existing connection was forcibly closed by the remote host\n",
      "Exception in callback BaseSelectorEventLoop._read_from_self()\n",
      "handle: <Handle BaseSelectorEventLoop._read_from_self()>\n",
      "Traceback (most recent call last):\n",
      "  File \"C:\\Users\\donmc\\anaconda3\\envs\\PythonData\\lib\\asyncio\\events.py\", line 145, in _run\n",
      "    self._callback(*self._args)\n",
      "  File \"C:\\Users\\donmc\\anaconda3\\envs\\PythonData\\lib\\asyncio\\selector_events.py\", line 141, in _read_from_self\n",
      "    data = self._ssock.recv(4096)\n",
      "ConnectionResetError: [WinError 10054] An existing connection was forcibly closed by the remote host\n",
      "Exception in callback BaseSelectorEventLoop._read_from_self()\n",
      "handle: <Handle BaseSelectorEventLoop._read_from_self()>\n",
      "Traceback (most recent call last):\n",
      "  File \"C:\\Users\\donmc\\anaconda3\\envs\\PythonData\\lib\\asyncio\\events.py\", line 145, in _run\n",
      "    self._callback(*self._args)\n",
      "  File \"C:\\Users\\donmc\\anaconda3\\envs\\PythonData\\lib\\asyncio\\selector_events.py\", line 141, in _read_from_self\n",
      "    data = self._ssock.recv(4096)\n",
      "ConnectionResetError: [WinError 10054] An existing connection was forcibly closed by the remote host\n",
      "Exception in callback BaseSelectorEventLoop._read_from_self()\n",
      "handle: <Handle BaseSelectorEventLoop._read_from_self()>\n",
      "Traceback (most recent call last):\n",
      "  File \"C:\\Users\\donmc\\anaconda3\\envs\\PythonData\\lib\\asyncio\\events.py\", line 145, in _run\n",
      "    self._callback(*self._args)\n",
      "  File \"C:\\Users\\donmc\\anaconda3\\envs\\PythonData\\lib\\asyncio\\selector_events.py\", line 141, in _read_from_self\n",
      "    data = self._ssock.recv(4096)\n",
      "ConnectionResetError: [WinError 10054] An existing connection was forcibly closed by the remote host\n"
     ]
    },
    {
     "name": "stderr",
     "output_type": "stream",
     "text": [
      "Exception in callback BaseSelectorEventLoop._read_from_self()\n",
      "handle: <Handle BaseSelectorEventLoop._read_from_self()>\n",
      "Traceback (most recent call last):\n",
      "  File \"C:\\Users\\donmc\\anaconda3\\envs\\PythonData\\lib\\asyncio\\events.py\", line 145, in _run\n",
      "    self._callback(*self._args)\n",
      "  File \"C:\\Users\\donmc\\anaconda3\\envs\\PythonData\\lib\\asyncio\\selector_events.py\", line 141, in _read_from_self\n",
      "    data = self._ssock.recv(4096)\n",
      "ConnectionResetError: [WinError 10054] An existing connection was forcibly closed by the remote host\n",
      "Exception in callback BaseSelectorEventLoop._read_from_self()\n",
      "handle: <Handle BaseSelectorEventLoop._read_from_self()>\n",
      "Traceback (most recent call last):\n",
      "  File \"C:\\Users\\donmc\\anaconda3\\envs\\PythonData\\lib\\asyncio\\events.py\", line 145, in _run\n",
      "    self._callback(*self._args)\n",
      "  File \"C:\\Users\\donmc\\anaconda3\\envs\\PythonData\\lib\\asyncio\\selector_events.py\", line 141, in _read_from_self\n",
      "    data = self._ssock.recv(4096)\n",
      "ConnectionResetError: [WinError 10054] An existing connection was forcibly closed by the remote host\n",
      "Exception in callback BaseSelectorEventLoop._read_from_self()\n",
      "handle: <Handle BaseSelectorEventLoop._read_from_self()>\n",
      "Traceback (most recent call last):\n",
      "  File \"C:\\Users\\donmc\\anaconda3\\envs\\PythonData\\lib\\asyncio\\events.py\", line 145, in _run\n",
      "    self._callback(*self._args)\n",
      "  File \"C:\\Users\\donmc\\anaconda3\\envs\\PythonData\\lib\\asyncio\\selector_events.py\", line 141, in _read_from_self\n",
      "    data = self._ssock.recv(4096)\n",
      "ConnectionResetError: [WinError 10054] An existing connection was forcibly closed by the remote host\n",
      "Exception in callback BaseSelectorEventLoop._read_from_self()\n",
      "handle: <Handle BaseSelectorEventLoop._read_from_self()>\n",
      "Traceback (most recent call last):\n",
      "  File \"C:\\Users\\donmc\\anaconda3\\envs\\PythonData\\lib\\asyncio\\events.py\", line 145, in _run\n",
      "    self._callback(*self._args)\n",
      "  File \"C:\\Users\\donmc\\anaconda3\\envs\\PythonData\\lib\\asyncio\\selector_events.py\", line 141, in _read_from_self\n",
      "    data = self._ssock.recv(4096)\n",
      "ConnectionResetError: [WinError 10054] An existing connection was forcibly closed by the remote host\n",
      "Exception in callback BaseSelectorEventLoop._read_from_self()\n",
      "handle: <Handle BaseSelectorEventLoop._read_from_self()>\n",
      "Traceback (most recent call last):\n",
      "  File \"C:\\Users\\donmc\\anaconda3\\envs\\PythonData\\lib\\asyncio\\events.py\", line 145, in _run\n",
      "    self._callback(*self._args)\n",
      "  File \"C:\\Users\\donmc\\anaconda3\\envs\\PythonData\\lib\\asyncio\\selector_events.py\", line 141, in _read_from_self\n",
      "    data = self._ssock.recv(4096)\n",
      "ConnectionResetError: [WinError 10054] An existing connection was forcibly closed by the remote host\n",
      "Exception in callback BaseSelectorEventLoop._read_from_self()\n",
      "handle: <Handle BaseSelectorEventLoop._read_from_self()>\n",
      "Traceback (most recent call last):\n",
      "  File \"C:\\Users\\donmc\\anaconda3\\envs\\PythonData\\lib\\asyncio\\events.py\", line 145, in _run\n",
      "    self._callback(*self._args)\n",
      "  File \"C:\\Users\\donmc\\anaconda3\\envs\\PythonData\\lib\\asyncio\\selector_events.py\", line 141, in _read_from_self\n",
      "    data = self._ssock.recv(4096)\n",
      "ConnectionResetError: [WinError 10054] An existing connection was forcibly closed by the remote host\n",
      "Exception in callback BaseSelectorEventLoop._read_from_self()\n",
      "handle: <Handle BaseSelectorEventLoop._read_from_self()>\n",
      "Traceback (most recent call last):\n",
      "  File \"C:\\Users\\donmc\\anaconda3\\envs\\PythonData\\lib\\asyncio\\events.py\", line 145, in _run\n",
      "    self._callback(*self._args)\n",
      "  File \"C:\\Users\\donmc\\anaconda3\\envs\\PythonData\\lib\\asyncio\\selector_events.py\", line 141, in _read_from_self\n",
      "    data = self._ssock.recv(4096)\n",
      "ConnectionResetError: [WinError 10054] An existing connection was forcibly closed by the remote host\n",
      "Exception in callback BaseSelectorEventLoop._read_from_self()\n",
      "handle: <Handle BaseSelectorEventLoop._read_from_self()>\n",
      "Traceback (most recent call last):\n",
      "  File \"C:\\Users\\donmc\\anaconda3\\envs\\PythonData\\lib\\asyncio\\events.py\", line 145, in _run\n",
      "    self._callback(*self._args)\n",
      "  File \"C:\\Users\\donmc\\anaconda3\\envs\\PythonData\\lib\\asyncio\\selector_events.py\", line 141, in _read_from_self\n",
      "    data = self._ssock.recv(4096)\n",
      "ConnectionResetError: [WinError 10054] An existing connection was forcibly closed by the remote host\n",
      "Exception in callback BaseSelectorEventLoop._read_from_self()\n",
      "handle: <Handle BaseSelectorEventLoop._read_from_self()>\n",
      "Traceback (most recent call last):\n",
      "  File \"C:\\Users\\donmc\\anaconda3\\envs\\PythonData\\lib\\asyncio\\events.py\", line 145, in _run\n",
      "    self._callback(*self._args)\n",
      "  File \"C:\\Users\\donmc\\anaconda3\\envs\\PythonData\\lib\\asyncio\\selector_events.py\", line 141, in _read_from_self\n",
      "    data = self._ssock.recv(4096)\n",
      "ConnectionResetError: [WinError 10054] An existing connection was forcibly closed by the remote host\n",
      "Exception in callback BaseSelectorEventLoop._read_from_self()\n",
      "handle: <Handle BaseSelectorEventLoop._read_from_self()>\n",
      "Traceback (most recent call last):\n",
      "  File \"C:\\Users\\donmc\\anaconda3\\envs\\PythonData\\lib\\asyncio\\events.py\", line 145, in _run\n",
      "    self._callback(*self._args)\n",
      "  File \"C:\\Users\\donmc\\anaconda3\\envs\\PythonData\\lib\\asyncio\\selector_events.py\", line 141, in _read_from_self\n",
      "    data = self._ssock.recv(4096)\n",
      "ConnectionResetError: [WinError 10054] An existing connection was forcibly closed by the remote host\n",
      "Exception in callback BaseSelectorEventLoop._read_from_self()\n",
      "handle: <Handle BaseSelectorEventLoop._read_from_self()>\n",
      "Traceback (most recent call last):\n",
      "  File \"C:\\Users\\donmc\\anaconda3\\envs\\PythonData\\lib\\asyncio\\events.py\", line 145, in _run\n",
      "    self._callback(*self._args)\n",
      "  File \"C:\\Users\\donmc\\anaconda3\\envs\\PythonData\\lib\\asyncio\\selector_events.py\", line 141, in _read_from_self\n",
      "    data = self._ssock.recv(4096)\n",
      "ConnectionResetError: [WinError 10054] An existing connection was forcibly closed by the remote host\n",
      "Exception in callback BaseSelectorEventLoop._read_from_self()\n",
      "handle: <Handle BaseSelectorEventLoop._read_from_self()>\n",
      "Traceback (most recent call last):\n",
      "  File \"C:\\Users\\donmc\\anaconda3\\envs\\PythonData\\lib\\asyncio\\events.py\", line 145, in _run\n",
      "    self._callback(*self._args)\n",
      "  File \"C:\\Users\\donmc\\anaconda3\\envs\\PythonData\\lib\\asyncio\\selector_events.py\", line 141, in _read_from_self\n",
      "    data = self._ssock.recv(4096)\n",
      "ConnectionResetError: [WinError 10054] An existing connection was forcibly closed by the remote host\n",
      "Exception in callback BaseSelectorEventLoop._read_from_self()\n",
      "handle: <Handle BaseSelectorEventLoop._read_from_self()>\n",
      "Traceback (most recent call last):\n",
      "  File \"C:\\Users\\donmc\\anaconda3\\envs\\PythonData\\lib\\asyncio\\events.py\", line 145, in _run\n",
      "    self._callback(*self._args)\n",
      "  File \"C:\\Users\\donmc\\anaconda3\\envs\\PythonData\\lib\\asyncio\\selector_events.py\", line 141, in _read_from_self\n",
      "    data = self._ssock.recv(4096)\n",
      "ConnectionResetError: [WinError 10054] An existing connection was forcibly closed by the remote host\n",
      "Exception in callback BaseSelectorEventLoop._read_from_self()\n",
      "handle: <Handle BaseSelectorEventLoop._read_from_self()>\n",
      "Traceback (most recent call last):\n",
      "  File \"C:\\Users\\donmc\\anaconda3\\envs\\PythonData\\lib\\asyncio\\events.py\", line 145, in _run\n",
      "    self._callback(*self._args)\n",
      "  File \"C:\\Users\\donmc\\anaconda3\\envs\\PythonData\\lib\\asyncio\\selector_events.py\", line 141, in _read_from_self\n",
      "    data = self._ssock.recv(4096)\n",
      "ConnectionResetError: [WinError 10054] An existing connection was forcibly closed by the remote host\n",
      "Exception in callback BaseSelectorEventLoop._read_from_self()\n",
      "handle: <Handle BaseSelectorEventLoop._read_from_self()>\n",
      "Traceback (most recent call last):\n",
      "  File \"C:\\Users\\donmc\\anaconda3\\envs\\PythonData\\lib\\asyncio\\events.py\", line 145, in _run\n",
      "    self._callback(*self._args)\n",
      "  File \"C:\\Users\\donmc\\anaconda3\\envs\\PythonData\\lib\\asyncio\\selector_events.py\", line 141, in _read_from_self\n",
      "    data = self._ssock.recv(4096)\n",
      "ConnectionResetError: [WinError 10054] An existing connection was forcibly closed by the remote host\n",
      "Exception in callback BaseSelectorEventLoop._read_from_self()\n",
      "handle: <Handle BaseSelectorEventLoop._read_from_self()>\n",
      "Traceback (most recent call last):\n",
      "  File \"C:\\Users\\donmc\\anaconda3\\envs\\PythonData\\lib\\asyncio\\events.py\", line 145, in _run\n",
      "    self._callback(*self._args)\n",
      "  File \"C:\\Users\\donmc\\anaconda3\\envs\\PythonData\\lib\\asyncio\\selector_events.py\", line 141, in _read_from_self\n",
      "    data = self._ssock.recv(4096)\n",
      "ConnectionResetError: [WinError 10054] An existing connection was forcibly closed by the remote host\n"
     ]
    },
    {
     "name": "stderr",
     "output_type": "stream",
     "text": [
      "Exception in callback BaseSelectorEventLoop._read_from_self()\n",
      "handle: <Handle BaseSelectorEventLoop._read_from_self()>\n",
      "Traceback (most recent call last):\n",
      "  File \"C:\\Users\\donmc\\anaconda3\\envs\\PythonData\\lib\\asyncio\\events.py\", line 145, in _run\n",
      "    self._callback(*self._args)\n",
      "  File \"C:\\Users\\donmc\\anaconda3\\envs\\PythonData\\lib\\asyncio\\selector_events.py\", line 141, in _read_from_self\n",
      "    data = self._ssock.recv(4096)\n",
      "ConnectionResetError: [WinError 10054] An existing connection was forcibly closed by the remote host\n",
      "Exception in callback BaseSelectorEventLoop._read_from_self()\n",
      "handle: <Handle BaseSelectorEventLoop._read_from_self()>\n",
      "Traceback (most recent call last):\n",
      "  File \"C:\\Users\\donmc\\anaconda3\\envs\\PythonData\\lib\\asyncio\\events.py\", line 145, in _run\n",
      "    self._callback(*self._args)\n",
      "  File \"C:\\Users\\donmc\\anaconda3\\envs\\PythonData\\lib\\asyncio\\selector_events.py\", line 141, in _read_from_self\n",
      "    data = self._ssock.recv(4096)\n",
      "ConnectionResetError: [WinError 10054] An existing connection was forcibly closed by the remote host\n",
      "Exception in callback BaseSelectorEventLoop._read_from_self()\n",
      "handle: <Handle BaseSelectorEventLoop._read_from_self()>\n",
      "Traceback (most recent call last):\n",
      "  File \"C:\\Users\\donmc\\anaconda3\\envs\\PythonData\\lib\\asyncio\\events.py\", line 145, in _run\n",
      "    self._callback(*self._args)\n",
      "  File \"C:\\Users\\donmc\\anaconda3\\envs\\PythonData\\lib\\asyncio\\selector_events.py\", line 141, in _read_from_self\n",
      "    data = self._ssock.recv(4096)\n",
      "ConnectionResetError: [WinError 10054] An existing connection was forcibly closed by the remote host\n",
      "Exception in callback BaseSelectorEventLoop._read_from_self()\n",
      "handle: <Handle BaseSelectorEventLoop._read_from_self()>\n",
      "Traceback (most recent call last):\n",
      "  File \"C:\\Users\\donmc\\anaconda3\\envs\\PythonData\\lib\\asyncio\\events.py\", line 145, in _run\n",
      "    self._callback(*self._args)\n",
      "  File \"C:\\Users\\donmc\\anaconda3\\envs\\PythonData\\lib\\asyncio\\selector_events.py\", line 141, in _read_from_self\n",
      "    data = self._ssock.recv(4096)\n",
      "ConnectionResetError: [WinError 10054] An existing connection was forcibly closed by the remote host\n",
      "Exception in callback BaseSelectorEventLoop._read_from_self()\n",
      "handle: <Handle BaseSelectorEventLoop._read_from_self()>\n",
      "Traceback (most recent call last):\n",
      "  File \"C:\\Users\\donmc\\anaconda3\\envs\\PythonData\\lib\\asyncio\\events.py\", line 145, in _run\n",
      "    self._callback(*self._args)\n",
      "  File \"C:\\Users\\donmc\\anaconda3\\envs\\PythonData\\lib\\asyncio\\selector_events.py\", line 141, in _read_from_self\n",
      "    data = self._ssock.recv(4096)\n",
      "ConnectionResetError: [WinError 10054] An existing connection was forcibly closed by the remote host\n",
      "Exception in callback BaseSelectorEventLoop._read_from_self()\n",
      "handle: <Handle BaseSelectorEventLoop._read_from_self()>\n",
      "Traceback (most recent call last):\n",
      "  File \"C:\\Users\\donmc\\anaconda3\\envs\\PythonData\\lib\\asyncio\\events.py\", line 145, in _run\n",
      "    self._callback(*self._args)\n",
      "  File \"C:\\Users\\donmc\\anaconda3\\envs\\PythonData\\lib\\asyncio\\selector_events.py\", line 141, in _read_from_self\n",
      "    data = self._ssock.recv(4096)\n",
      "ConnectionResetError: [WinError 10054] An existing connection was forcibly closed by the remote host\n",
      "Exception in callback BaseSelectorEventLoop._read_from_self()\n",
      "handle: <Handle BaseSelectorEventLoop._read_from_self()>\n",
      "Traceback (most recent call last):\n",
      "  File \"C:\\Users\\donmc\\anaconda3\\envs\\PythonData\\lib\\asyncio\\events.py\", line 145, in _run\n",
      "    self._callback(*self._args)\n",
      "  File \"C:\\Users\\donmc\\anaconda3\\envs\\PythonData\\lib\\asyncio\\selector_events.py\", line 141, in _read_from_self\n",
      "    data = self._ssock.recv(4096)\n",
      "ConnectionResetError: [WinError 10054] An existing connection was forcibly closed by the remote host\n",
      "Exception in callback BaseSelectorEventLoop._read_from_self()\n",
      "handle: <Handle BaseSelectorEventLoop._read_from_self()>\n",
      "Traceback (most recent call last):\n",
      "  File \"C:\\Users\\donmc\\anaconda3\\envs\\PythonData\\lib\\asyncio\\events.py\", line 145, in _run\n",
      "    self._callback(*self._args)\n",
      "  File \"C:\\Users\\donmc\\anaconda3\\envs\\PythonData\\lib\\asyncio\\selector_events.py\", line 141, in _read_from_self\n",
      "    data = self._ssock.recv(4096)\n",
      "ConnectionResetError: [WinError 10054] An existing connection was forcibly closed by the remote host\n",
      "Exception in callback BaseSelectorEventLoop._read_from_self()\n",
      "handle: <Handle BaseSelectorEventLoop._read_from_self()>\n",
      "Traceback (most recent call last):\n",
      "  File \"C:\\Users\\donmc\\anaconda3\\envs\\PythonData\\lib\\asyncio\\events.py\", line 145, in _run\n",
      "    self._callback(*self._args)\n",
      "  File \"C:\\Users\\donmc\\anaconda3\\envs\\PythonData\\lib\\asyncio\\selector_events.py\", line 141, in _read_from_self\n",
      "    data = self._ssock.recv(4096)\n",
      "ConnectionResetError: [WinError 10054] An existing connection was forcibly closed by the remote host\n",
      "Exception in callback BaseSelectorEventLoop._read_from_self()\n",
      "handle: <Handle BaseSelectorEventLoop._read_from_self()>\n",
      "Traceback (most recent call last):\n",
      "  File \"C:\\Users\\donmc\\anaconda3\\envs\\PythonData\\lib\\asyncio\\events.py\", line 145, in _run\n",
      "    self._callback(*self._args)\n",
      "  File \"C:\\Users\\donmc\\anaconda3\\envs\\PythonData\\lib\\asyncio\\selector_events.py\", line 141, in _read_from_self\n",
      "    data = self._ssock.recv(4096)\n",
      "ConnectionResetError: [WinError 10054] An existing connection was forcibly closed by the remote host\n",
      "Exception in callback BaseSelectorEventLoop._read_from_self()\n",
      "handle: <Handle BaseSelectorEventLoop._read_from_self()>\n",
      "Traceback (most recent call last):\n",
      "  File \"C:\\Users\\donmc\\anaconda3\\envs\\PythonData\\lib\\asyncio\\events.py\", line 145, in _run\n",
      "    self._callback(*self._args)\n",
      "  File \"C:\\Users\\donmc\\anaconda3\\envs\\PythonData\\lib\\asyncio\\selector_events.py\", line 141, in _read_from_self\n",
      "    data = self._ssock.recv(4096)\n",
      "ConnectionResetError: [WinError 10054] An existing connection was forcibly closed by the remote host\n",
      "Exception in callback BaseSelectorEventLoop._read_from_self()\n",
      "handle: <Handle BaseSelectorEventLoop._read_from_self()>\n",
      "Traceback (most recent call last):\n",
      "  File \"C:\\Users\\donmc\\anaconda3\\envs\\PythonData\\lib\\asyncio\\events.py\", line 145, in _run\n",
      "    self._callback(*self._args)\n",
      "  File \"C:\\Users\\donmc\\anaconda3\\envs\\PythonData\\lib\\asyncio\\selector_events.py\", line 141, in _read_from_self\n",
      "    data = self._ssock.recv(4096)\n",
      "ConnectionResetError: [WinError 10054] An existing connection was forcibly closed by the remote host\n",
      "Exception in callback BaseSelectorEventLoop._read_from_self()\n",
      "handle: <Handle BaseSelectorEventLoop._read_from_self()>\n",
      "Traceback (most recent call last):\n",
      "  File \"C:\\Users\\donmc\\anaconda3\\envs\\PythonData\\lib\\asyncio\\events.py\", line 145, in _run\n",
      "    self._callback(*self._args)\n",
      "  File \"C:\\Users\\donmc\\anaconda3\\envs\\PythonData\\lib\\asyncio\\selector_events.py\", line 141, in _read_from_self\n",
      "    data = self._ssock.recv(4096)\n",
      "ConnectionResetError: [WinError 10054] An existing connection was forcibly closed by the remote host\n",
      "Exception in callback BaseSelectorEventLoop._read_from_self()\n",
      "handle: <Handle BaseSelectorEventLoop._read_from_self()>\n",
      "Traceback (most recent call last):\n",
      "  File \"C:\\Users\\donmc\\anaconda3\\envs\\PythonData\\lib\\asyncio\\events.py\", line 145, in _run\n",
      "    self._callback(*self._args)\n",
      "  File \"C:\\Users\\donmc\\anaconda3\\envs\\PythonData\\lib\\asyncio\\selector_events.py\", line 141, in _read_from_self\n",
      "    data = self._ssock.recv(4096)\n",
      "ConnectionResetError: [WinError 10054] An existing connection was forcibly closed by the remote host\n",
      "Exception in callback BaseSelectorEventLoop._read_from_self()\n",
      "handle: <Handle BaseSelectorEventLoop._read_from_self()>\n",
      "Traceback (most recent call last):\n",
      "  File \"C:\\Users\\donmc\\anaconda3\\envs\\PythonData\\lib\\asyncio\\events.py\", line 145, in _run\n",
      "    self._callback(*self._args)\n",
      "  File \"C:\\Users\\donmc\\anaconda3\\envs\\PythonData\\lib\\asyncio\\selector_events.py\", line 141, in _read_from_self\n",
      "    data = self._ssock.recv(4096)\n",
      "ConnectionResetError: [WinError 10054] An existing connection was forcibly closed by the remote host\n",
      "Exception in callback BaseSelectorEventLoop._read_from_self()\n",
      "handle: <Handle BaseSelectorEventLoop._read_from_self()>\n",
      "Traceback (most recent call last):\n",
      "  File \"C:\\Users\\donmc\\anaconda3\\envs\\PythonData\\lib\\asyncio\\events.py\", line 145, in _run\n",
      "    self._callback(*self._args)\n",
      "  File \"C:\\Users\\donmc\\anaconda3\\envs\\PythonData\\lib\\asyncio\\selector_events.py\", line 141, in _read_from_self\n",
      "    data = self._ssock.recv(4096)\n",
      "ConnectionResetError: [WinError 10054] An existing connection was forcibly closed by the remote host\n"
     ]
    },
    {
     "name": "stderr",
     "output_type": "stream",
     "text": [
      "Exception in callback BaseSelectorEventLoop._read_from_self()\n",
      "handle: <Handle BaseSelectorEventLoop._read_from_self()>\n",
      "Traceback (most recent call last):\n",
      "  File \"C:\\Users\\donmc\\anaconda3\\envs\\PythonData\\lib\\asyncio\\events.py\", line 145, in _run\n",
      "    self._callback(*self._args)\n",
      "  File \"C:\\Users\\donmc\\anaconda3\\envs\\PythonData\\lib\\asyncio\\selector_events.py\", line 141, in _read_from_self\n",
      "    data = self._ssock.recv(4096)\n",
      "ConnectionResetError: [WinError 10054] An existing connection was forcibly closed by the remote host\n",
      "Exception in callback BaseSelectorEventLoop._read_from_self()\n",
      "handle: <Handle BaseSelectorEventLoop._read_from_self()>\n",
      "Traceback (most recent call last):\n",
      "  File \"C:\\Users\\donmc\\anaconda3\\envs\\PythonData\\lib\\asyncio\\events.py\", line 145, in _run\n",
      "    self._callback(*self._args)\n",
      "  File \"C:\\Users\\donmc\\anaconda3\\envs\\PythonData\\lib\\asyncio\\selector_events.py\", line 141, in _read_from_self\n",
      "    data = self._ssock.recv(4096)\n",
      "ConnectionResetError: [WinError 10054] An existing connection was forcibly closed by the remote host\n",
      "Exception in callback BaseSelectorEventLoop._read_from_self()\n",
      "handle: <Handle BaseSelectorEventLoop._read_from_self()>\n",
      "Traceback (most recent call last):\n",
      "  File \"C:\\Users\\donmc\\anaconda3\\envs\\PythonData\\lib\\asyncio\\events.py\", line 145, in _run\n",
      "    self._callback(*self._args)\n",
      "  File \"C:\\Users\\donmc\\anaconda3\\envs\\PythonData\\lib\\asyncio\\selector_events.py\", line 141, in _read_from_self\n",
      "    data = self._ssock.recv(4096)\n",
      "ConnectionResetError: [WinError 10054] An existing connection was forcibly closed by the remote host\n",
      "Exception in callback BaseSelectorEventLoop._read_from_self()\n",
      "handle: <Handle BaseSelectorEventLoop._read_from_self()>\n",
      "Traceback (most recent call last):\n",
      "  File \"C:\\Users\\donmc\\anaconda3\\envs\\PythonData\\lib\\asyncio\\events.py\", line 145, in _run\n",
      "    self._callback(*self._args)\n",
      "  File \"C:\\Users\\donmc\\anaconda3\\envs\\PythonData\\lib\\asyncio\\selector_events.py\", line 141, in _read_from_self\n",
      "    data = self._ssock.recv(4096)\n",
      "ConnectionResetError: [WinError 10054] An existing connection was forcibly closed by the remote host\n",
      "Exception in callback BaseSelectorEventLoop._read_from_self()\n",
      "handle: <Handle BaseSelectorEventLoop._read_from_self()>\n",
      "Traceback (most recent call last):\n",
      "  File \"C:\\Users\\donmc\\anaconda3\\envs\\PythonData\\lib\\asyncio\\events.py\", line 145, in _run\n",
      "    self._callback(*self._args)\n",
      "  File \"C:\\Users\\donmc\\anaconda3\\envs\\PythonData\\lib\\asyncio\\selector_events.py\", line 141, in _read_from_self\n",
      "    data = self._ssock.recv(4096)\n",
      "ConnectionResetError: [WinError 10054] An existing connection was forcibly closed by the remote host\n",
      "Exception in callback BaseSelectorEventLoop._read_from_self()\n",
      "handle: <Handle BaseSelectorEventLoop._read_from_self()>\n",
      "Traceback (most recent call last):\n",
      "  File \"C:\\Users\\donmc\\anaconda3\\envs\\PythonData\\lib\\asyncio\\events.py\", line 145, in _run\n",
      "    self._callback(*self._args)\n",
      "  File \"C:\\Users\\donmc\\anaconda3\\envs\\PythonData\\lib\\asyncio\\selector_events.py\", line 141, in _read_from_self\n",
      "    data = self._ssock.recv(4096)\n",
      "ConnectionResetError: [WinError 10054] An existing connection was forcibly closed by the remote host\n",
      "Exception in callback BaseSelectorEventLoop._read_from_self()\n",
      "handle: <Handle BaseSelectorEventLoop._read_from_self()>\n",
      "Traceback (most recent call last):\n",
      "  File \"C:\\Users\\donmc\\anaconda3\\envs\\PythonData\\lib\\asyncio\\events.py\", line 145, in _run\n",
      "    self._callback(*self._args)\n",
      "  File \"C:\\Users\\donmc\\anaconda3\\envs\\PythonData\\lib\\asyncio\\selector_events.py\", line 141, in _read_from_self\n",
      "    data = self._ssock.recv(4096)\n",
      "ConnectionResetError: [WinError 10054] An existing connection was forcibly closed by the remote host\n",
      "Exception in callback BaseSelectorEventLoop._read_from_self()\n",
      "handle: <Handle BaseSelectorEventLoop._read_from_self()>\n",
      "Traceback (most recent call last):\n",
      "  File \"C:\\Users\\donmc\\anaconda3\\envs\\PythonData\\lib\\asyncio\\events.py\", line 145, in _run\n",
      "    self._callback(*self._args)\n",
      "  File \"C:\\Users\\donmc\\anaconda3\\envs\\PythonData\\lib\\asyncio\\selector_events.py\", line 141, in _read_from_self\n",
      "    data = self._ssock.recv(4096)\n",
      "ConnectionResetError: [WinError 10054] An existing connection was forcibly closed by the remote host\n",
      "Exception in callback BaseSelectorEventLoop._read_from_self()\n",
      "handle: <Handle BaseSelectorEventLoop._read_from_self()>\n",
      "Traceback (most recent call last):\n",
      "  File \"C:\\Users\\donmc\\anaconda3\\envs\\PythonData\\lib\\asyncio\\events.py\", line 145, in _run\n",
      "    self._callback(*self._args)\n",
      "  File \"C:\\Users\\donmc\\anaconda3\\envs\\PythonData\\lib\\asyncio\\selector_events.py\", line 141, in _read_from_self\n",
      "    data = self._ssock.recv(4096)\n",
      "ConnectionResetError: [WinError 10054] An existing connection was forcibly closed by the remote host\n",
      "Exception in callback BaseSelectorEventLoop._read_from_self()\n",
      "handle: <Handle BaseSelectorEventLoop._read_from_self()>\n",
      "Traceback (most recent call last):\n",
      "  File \"C:\\Users\\donmc\\anaconda3\\envs\\PythonData\\lib\\asyncio\\events.py\", line 145, in _run\n",
      "    self._callback(*self._args)\n",
      "  File \"C:\\Users\\donmc\\anaconda3\\envs\\PythonData\\lib\\asyncio\\selector_events.py\", line 141, in _read_from_self\n",
      "    data = self._ssock.recv(4096)\n",
      "ConnectionResetError: [WinError 10054] An existing connection was forcibly closed by the remote host\n",
      "Exception in callback BaseSelectorEventLoop._read_from_self()\n",
      "handle: <Handle BaseSelectorEventLoop._read_from_self()>\n",
      "Traceback (most recent call last):\n",
      "  File \"C:\\Users\\donmc\\anaconda3\\envs\\PythonData\\lib\\asyncio\\events.py\", line 145, in _run\n",
      "    self._callback(*self._args)\n",
      "  File \"C:\\Users\\donmc\\anaconda3\\envs\\PythonData\\lib\\asyncio\\selector_events.py\", line 141, in _read_from_self\n",
      "    data = self._ssock.recv(4096)\n",
      "ConnectionResetError: [WinError 10054] An existing connection was forcibly closed by the remote host\n",
      "Exception in callback BaseSelectorEventLoop._read_from_self()\n",
      "handle: <Handle BaseSelectorEventLoop._read_from_self()>\n",
      "Traceback (most recent call last):\n",
      "  File \"C:\\Users\\donmc\\anaconda3\\envs\\PythonData\\lib\\asyncio\\events.py\", line 145, in _run\n",
      "    self._callback(*self._args)\n",
      "  File \"C:\\Users\\donmc\\anaconda3\\envs\\PythonData\\lib\\asyncio\\selector_events.py\", line 141, in _read_from_self\n",
      "    data = self._ssock.recv(4096)\n",
      "ConnectionResetError: [WinError 10054] An existing connection was forcibly closed by the remote host\n",
      "Exception in callback BaseSelectorEventLoop._read_from_self()\n",
      "handle: <Handle BaseSelectorEventLoop._read_from_self()>\n",
      "Traceback (most recent call last):\n",
      "  File \"C:\\Users\\donmc\\anaconda3\\envs\\PythonData\\lib\\asyncio\\events.py\", line 145, in _run\n",
      "    self._callback(*self._args)\n",
      "  File \"C:\\Users\\donmc\\anaconda3\\envs\\PythonData\\lib\\asyncio\\selector_events.py\", line 141, in _read_from_self\n",
      "    data = self._ssock.recv(4096)\n",
      "ConnectionResetError: [WinError 10054] An existing connection was forcibly closed by the remote host\n",
      "Exception in callback BaseSelectorEventLoop._read_from_self()\n",
      "handle: <Handle BaseSelectorEventLoop._read_from_self()>\n",
      "Traceback (most recent call last):\n",
      "  File \"C:\\Users\\donmc\\anaconda3\\envs\\PythonData\\lib\\asyncio\\events.py\", line 145, in _run\n",
      "    self._callback(*self._args)\n",
      "  File \"C:\\Users\\donmc\\anaconda3\\envs\\PythonData\\lib\\asyncio\\selector_events.py\", line 141, in _read_from_self\n",
      "    data = self._ssock.recv(4096)\n",
      "ConnectionResetError: [WinError 10054] An existing connection was forcibly closed by the remote host\n",
      "Exception in callback BaseSelectorEventLoop._read_from_self()\n",
      "handle: <Handle BaseSelectorEventLoop._read_from_self()>\n",
      "Traceback (most recent call last):\n",
      "  File \"C:\\Users\\donmc\\anaconda3\\envs\\PythonData\\lib\\asyncio\\events.py\", line 145, in _run\n",
      "    self._callback(*self._args)\n",
      "  File \"C:\\Users\\donmc\\anaconda3\\envs\\PythonData\\lib\\asyncio\\selector_events.py\", line 141, in _read_from_self\n",
      "    data = self._ssock.recv(4096)\n",
      "ConnectionResetError: [WinError 10054] An existing connection was forcibly closed by the remote host\n",
      "Exception in callback BaseSelectorEventLoop._read_from_self()\n",
      "handle: <Handle BaseSelectorEventLoop._read_from_self()>\n",
      "Traceback (most recent call last):\n",
      "  File \"C:\\Users\\donmc\\anaconda3\\envs\\PythonData\\lib\\asyncio\\events.py\", line 145, in _run\n",
      "    self._callback(*self._args)\n",
      "  File \"C:\\Users\\donmc\\anaconda3\\envs\\PythonData\\lib\\asyncio\\selector_events.py\", line 141, in _read_from_self\n",
      "    data = self._ssock.recv(4096)\n",
      "ConnectionResetError: [WinError 10054] An existing connection was forcibly closed by the remote host\n"
     ]
    },
    {
     "name": "stderr",
     "output_type": "stream",
     "text": [
      "Exception in callback BaseSelectorEventLoop._read_from_self()\n",
      "handle: <Handle BaseSelectorEventLoop._read_from_self()>\n",
      "Traceback (most recent call last):\n",
      "  File \"C:\\Users\\donmc\\anaconda3\\envs\\PythonData\\lib\\asyncio\\events.py\", line 145, in _run\n",
      "    self._callback(*self._args)\n",
      "  File \"C:\\Users\\donmc\\anaconda3\\envs\\PythonData\\lib\\asyncio\\selector_events.py\", line 141, in _read_from_self\n",
      "    data = self._ssock.recv(4096)\n",
      "ConnectionResetError: [WinError 10054] An existing connection was forcibly closed by the remote host\n",
      "Exception in callback BaseSelectorEventLoop._read_from_self()\n",
      "handle: <Handle BaseSelectorEventLoop._read_from_self()>\n",
      "Traceback (most recent call last):\n",
      "  File \"C:\\Users\\donmc\\anaconda3\\envs\\PythonData\\lib\\asyncio\\events.py\", line 145, in _run\n",
      "    self._callback(*self._args)\n",
      "  File \"C:\\Users\\donmc\\anaconda3\\envs\\PythonData\\lib\\asyncio\\selector_events.py\", line 141, in _read_from_self\n",
      "    data = self._ssock.recv(4096)\n",
      "ConnectionResetError: [WinError 10054] An existing connection was forcibly closed by the remote host\n",
      "Exception in callback BaseSelectorEventLoop._read_from_self()\n",
      "handle: <Handle BaseSelectorEventLoop._read_from_self()>\n",
      "Traceback (most recent call last):\n",
      "  File \"C:\\Users\\donmc\\anaconda3\\envs\\PythonData\\lib\\asyncio\\events.py\", line 145, in _run\n",
      "    self._callback(*self._args)\n",
      "  File \"C:\\Users\\donmc\\anaconda3\\envs\\PythonData\\lib\\asyncio\\selector_events.py\", line 141, in _read_from_self\n",
      "    data = self._ssock.recv(4096)\n",
      "ConnectionResetError: [WinError 10054] An existing connection was forcibly closed by the remote host\n",
      "Exception in callback BaseSelectorEventLoop._read_from_self()\n",
      "handle: <Handle BaseSelectorEventLoop._read_from_self()>\n",
      "Traceback (most recent call last):\n",
      "  File \"C:\\Users\\donmc\\anaconda3\\envs\\PythonData\\lib\\asyncio\\events.py\", line 145, in _run\n",
      "    self._callback(*self._args)\n",
      "  File \"C:\\Users\\donmc\\anaconda3\\envs\\PythonData\\lib\\asyncio\\selector_events.py\", line 141, in _read_from_self\n",
      "    data = self._ssock.recv(4096)\n",
      "ConnectionResetError: [WinError 10054] An existing connection was forcibly closed by the remote host\n",
      "Exception in callback BaseSelectorEventLoop._read_from_self()\n",
      "handle: <Handle BaseSelectorEventLoop._read_from_self()>\n",
      "Traceback (most recent call last):\n",
      "  File \"C:\\Users\\donmc\\anaconda3\\envs\\PythonData\\lib\\asyncio\\events.py\", line 145, in _run\n",
      "    self._callback(*self._args)\n",
      "  File \"C:\\Users\\donmc\\anaconda3\\envs\\PythonData\\lib\\asyncio\\selector_events.py\", line 141, in _read_from_self\n",
      "    data = self._ssock.recv(4096)\n",
      "ConnectionResetError: [WinError 10054] An existing connection was forcibly closed by the remote host\n",
      "Exception in callback BaseSelectorEventLoop._read_from_self()\n",
      "handle: <Handle BaseSelectorEventLoop._read_from_self()>\n",
      "Traceback (most recent call last):\n",
      "  File \"C:\\Users\\donmc\\anaconda3\\envs\\PythonData\\lib\\asyncio\\events.py\", line 145, in _run\n",
      "    self._callback(*self._args)\n",
      "  File \"C:\\Users\\donmc\\anaconda3\\envs\\PythonData\\lib\\asyncio\\selector_events.py\", line 141, in _read_from_self\n",
      "    data = self._ssock.recv(4096)\n",
      "ConnectionResetError: [WinError 10054] An existing connection was forcibly closed by the remote host\n",
      "Exception in callback BaseSelectorEventLoop._read_from_self()\n",
      "handle: <Handle BaseSelectorEventLoop._read_from_self()>\n",
      "Traceback (most recent call last):\n",
      "  File \"C:\\Users\\donmc\\anaconda3\\envs\\PythonData\\lib\\asyncio\\events.py\", line 145, in _run\n",
      "    self._callback(*self._args)\n",
      "  File \"C:\\Users\\donmc\\anaconda3\\envs\\PythonData\\lib\\asyncio\\selector_events.py\", line 141, in _read_from_self\n",
      "    data = self._ssock.recv(4096)\n",
      "ConnectionResetError: [WinError 10054] An existing connection was forcibly closed by the remote host\n",
      "Exception in callback BaseSelectorEventLoop._read_from_self()\n",
      "handle: <Handle BaseSelectorEventLoop._read_from_self()>\n",
      "Traceback (most recent call last):\n",
      "  File \"C:\\Users\\donmc\\anaconda3\\envs\\PythonData\\lib\\asyncio\\events.py\", line 145, in _run\n",
      "    self._callback(*self._args)\n",
      "  File \"C:\\Users\\donmc\\anaconda3\\envs\\PythonData\\lib\\asyncio\\selector_events.py\", line 141, in _read_from_self\n",
      "    data = self._ssock.recv(4096)\n",
      "ConnectionResetError: [WinError 10054] An existing connection was forcibly closed by the remote host\n",
      "Exception in callback BaseSelectorEventLoop._read_from_self()\n",
      "handle: <Handle BaseSelectorEventLoop._read_from_self()>\n",
      "Traceback (most recent call last):\n",
      "  File \"C:\\Users\\donmc\\anaconda3\\envs\\PythonData\\lib\\asyncio\\events.py\", line 145, in _run\n",
      "    self._callback(*self._args)\n",
      "  File \"C:\\Users\\donmc\\anaconda3\\envs\\PythonData\\lib\\asyncio\\selector_events.py\", line 141, in _read_from_self\n",
      "    data = self._ssock.recv(4096)\n",
      "ConnectionResetError: [WinError 10054] An existing connection was forcibly closed by the remote host\n",
      "Exception in callback BaseSelectorEventLoop._read_from_self()\n",
      "handle: <Handle BaseSelectorEventLoop._read_from_self()>\n",
      "Traceback (most recent call last):\n",
      "  File \"C:\\Users\\donmc\\anaconda3\\envs\\PythonData\\lib\\asyncio\\events.py\", line 145, in _run\n",
      "    self._callback(*self._args)\n",
      "  File \"C:\\Users\\donmc\\anaconda3\\envs\\PythonData\\lib\\asyncio\\selector_events.py\", line 141, in _read_from_self\n",
      "    data = self._ssock.recv(4096)\n",
      "ConnectionResetError: [WinError 10054] An existing connection was forcibly closed by the remote host\n",
      "Exception in callback BaseSelectorEventLoop._read_from_self()\n",
      "handle: <Handle BaseSelectorEventLoop._read_from_self()>\n",
      "Traceback (most recent call last):\n",
      "  File \"C:\\Users\\donmc\\anaconda3\\envs\\PythonData\\lib\\asyncio\\events.py\", line 145, in _run\n",
      "    self._callback(*self._args)\n",
      "  File \"C:\\Users\\donmc\\anaconda3\\envs\\PythonData\\lib\\asyncio\\selector_events.py\", line 141, in _read_from_self\n",
      "    data = self._ssock.recv(4096)\n",
      "ConnectionResetError: [WinError 10054] An existing connection was forcibly closed by the remote host\n",
      "Exception in callback BaseSelectorEventLoop._read_from_self()\n",
      "handle: <Handle BaseSelectorEventLoop._read_from_self()>\n",
      "Traceback (most recent call last):\n",
      "  File \"C:\\Users\\donmc\\anaconda3\\envs\\PythonData\\lib\\asyncio\\events.py\", line 145, in _run\n",
      "    self._callback(*self._args)\n",
      "  File \"C:\\Users\\donmc\\anaconda3\\envs\\PythonData\\lib\\asyncio\\selector_events.py\", line 141, in _read_from_self\n",
      "    data = self._ssock.recv(4096)\n",
      "ConnectionResetError: [WinError 10054] An existing connection was forcibly closed by the remote host\n",
      "Exception in callback BaseSelectorEventLoop._read_from_self()\n",
      "handle: <Handle BaseSelectorEventLoop._read_from_self()>\n",
      "Traceback (most recent call last):\n",
      "  File \"C:\\Users\\donmc\\anaconda3\\envs\\PythonData\\lib\\asyncio\\events.py\", line 145, in _run\n",
      "    self._callback(*self._args)\n",
      "  File \"C:\\Users\\donmc\\anaconda3\\envs\\PythonData\\lib\\asyncio\\selector_events.py\", line 141, in _read_from_self\n",
      "    data = self._ssock.recv(4096)\n",
      "ConnectionResetError: [WinError 10054] An existing connection was forcibly closed by the remote host\n",
      "Exception in callback BaseSelectorEventLoop._read_from_self()\n",
      "handle: <Handle BaseSelectorEventLoop._read_from_self()>\n",
      "Traceback (most recent call last):\n",
      "  File \"C:\\Users\\donmc\\anaconda3\\envs\\PythonData\\lib\\asyncio\\events.py\", line 145, in _run\n",
      "    self._callback(*self._args)\n",
      "  File \"C:\\Users\\donmc\\anaconda3\\envs\\PythonData\\lib\\asyncio\\selector_events.py\", line 141, in _read_from_self\n",
      "    data = self._ssock.recv(4096)\n",
      "ConnectionResetError: [WinError 10054] An existing connection was forcibly closed by the remote host\n",
      "Exception in callback BaseSelectorEventLoop._read_from_self()\n",
      "handle: <Handle BaseSelectorEventLoop._read_from_self()>\n",
      "Traceback (most recent call last):\n",
      "  File \"C:\\Users\\donmc\\anaconda3\\envs\\PythonData\\lib\\asyncio\\events.py\", line 145, in _run\n",
      "    self._callback(*self._args)\n",
      "  File \"C:\\Users\\donmc\\anaconda3\\envs\\PythonData\\lib\\asyncio\\selector_events.py\", line 141, in _read_from_self\n",
      "    data = self._ssock.recv(4096)\n",
      "ConnectionResetError: [WinError 10054] An existing connection was forcibly closed by the remote host\n",
      "Exception in callback BaseSelectorEventLoop._read_from_self()\n",
      "handle: <Handle BaseSelectorEventLoop._read_from_self()>\n",
      "Traceback (most recent call last):\n",
      "  File \"C:\\Users\\donmc\\anaconda3\\envs\\PythonData\\lib\\asyncio\\events.py\", line 145, in _run\n",
      "    self._callback(*self._args)\n",
      "  File \"C:\\Users\\donmc\\anaconda3\\envs\\PythonData\\lib\\asyncio\\selector_events.py\", line 141, in _read_from_self\n",
      "    data = self._ssock.recv(4096)\n",
      "ConnectionResetError: [WinError 10054] An existing connection was forcibly closed by the remote host\n"
     ]
    },
    {
     "name": "stderr",
     "output_type": "stream",
     "text": [
      "Exception in callback BaseSelectorEventLoop._read_from_self()\n",
      "handle: <Handle BaseSelectorEventLoop._read_from_self()>\n",
      "Traceback (most recent call last):\n",
      "  File \"C:\\Users\\donmc\\anaconda3\\envs\\PythonData\\lib\\asyncio\\events.py\", line 145, in _run\n",
      "    self._callback(*self._args)\n",
      "  File \"C:\\Users\\donmc\\anaconda3\\envs\\PythonData\\lib\\asyncio\\selector_events.py\", line 141, in _read_from_self\n",
      "    data = self._ssock.recv(4096)\n",
      "ConnectionResetError: [WinError 10054] An existing connection was forcibly closed by the remote host\n",
      "Exception in callback BaseSelectorEventLoop._read_from_self()\n",
      "handle: <Handle BaseSelectorEventLoop._read_from_self()>\n",
      "Traceback (most recent call last):\n",
      "  File \"C:\\Users\\donmc\\anaconda3\\envs\\PythonData\\lib\\asyncio\\events.py\", line 145, in _run\n",
      "    self._callback(*self._args)\n",
      "  File \"C:\\Users\\donmc\\anaconda3\\envs\\PythonData\\lib\\asyncio\\selector_events.py\", line 141, in _read_from_self\n",
      "    data = self._ssock.recv(4096)\n",
      "ConnectionResetError: [WinError 10054] An existing connection was forcibly closed by the remote host\n",
      "Exception in callback BaseSelectorEventLoop._read_from_self()\n",
      "handle: <Handle BaseSelectorEventLoop._read_from_self()>\n",
      "Traceback (most recent call last):\n",
      "  File \"C:\\Users\\donmc\\anaconda3\\envs\\PythonData\\lib\\asyncio\\events.py\", line 145, in _run\n",
      "    self._callback(*self._args)\n",
      "  File \"C:\\Users\\donmc\\anaconda3\\envs\\PythonData\\lib\\asyncio\\selector_events.py\", line 141, in _read_from_self\n",
      "    data = self._ssock.recv(4096)\n",
      "ConnectionResetError: [WinError 10054] An existing connection was forcibly closed by the remote host\n",
      "Exception in callback BaseSelectorEventLoop._read_from_self()\n",
      "handle: <Handle BaseSelectorEventLoop._read_from_self()>\n",
      "Traceback (most recent call last):\n",
      "  File \"C:\\Users\\donmc\\anaconda3\\envs\\PythonData\\lib\\asyncio\\events.py\", line 145, in _run\n",
      "    self._callback(*self._args)\n",
      "  File \"C:\\Users\\donmc\\anaconda3\\envs\\PythonData\\lib\\asyncio\\selector_events.py\", line 141, in _read_from_self\n",
      "    data = self._ssock.recv(4096)\n",
      "ConnectionResetError: [WinError 10054] An existing connection was forcibly closed by the remote host\n",
      "Exception in callback BaseSelectorEventLoop._read_from_self()\n",
      "handle: <Handle BaseSelectorEventLoop._read_from_self()>\n",
      "Traceback (most recent call last):\n",
      "  File \"C:\\Users\\donmc\\anaconda3\\envs\\PythonData\\lib\\asyncio\\events.py\", line 145, in _run\n",
      "    self._callback(*self._args)\n",
      "  File \"C:\\Users\\donmc\\anaconda3\\envs\\PythonData\\lib\\asyncio\\selector_events.py\", line 141, in _read_from_self\n",
      "    data = self._ssock.recv(4096)\n",
      "ConnectionResetError: [WinError 10054] An existing connection was forcibly closed by the remote host\n",
      "Exception in callback BaseSelectorEventLoop._read_from_self()\n",
      "handle: <Handle BaseSelectorEventLoop._read_from_self()>\n",
      "Traceback (most recent call last):\n",
      "  File \"C:\\Users\\donmc\\anaconda3\\envs\\PythonData\\lib\\asyncio\\events.py\", line 145, in _run\n",
      "    self._callback(*self._args)\n",
      "  File \"C:\\Users\\donmc\\anaconda3\\envs\\PythonData\\lib\\asyncio\\selector_events.py\", line 141, in _read_from_self\n",
      "    data = self._ssock.recv(4096)\n",
      "ConnectionResetError: [WinError 10054] An existing connection was forcibly closed by the remote host\n",
      "Exception in callback BaseSelectorEventLoop._read_from_self()\n",
      "handle: <Handle BaseSelectorEventLoop._read_from_self()>\n",
      "Traceback (most recent call last):\n",
      "  File \"C:\\Users\\donmc\\anaconda3\\envs\\PythonData\\lib\\asyncio\\events.py\", line 145, in _run\n",
      "    self._callback(*self._args)\n",
      "  File \"C:\\Users\\donmc\\anaconda3\\envs\\PythonData\\lib\\asyncio\\selector_events.py\", line 141, in _read_from_self\n",
      "    data = self._ssock.recv(4096)\n",
      "ConnectionResetError: [WinError 10054] An existing connection was forcibly closed by the remote host\n",
      "Exception in callback BaseSelectorEventLoop._read_from_self()\n",
      "handle: <Handle BaseSelectorEventLoop._read_from_self()>\n",
      "Traceback (most recent call last):\n",
      "  File \"C:\\Users\\donmc\\anaconda3\\envs\\PythonData\\lib\\asyncio\\events.py\", line 145, in _run\n",
      "    self._callback(*self._args)\n",
      "  File \"C:\\Users\\donmc\\anaconda3\\envs\\PythonData\\lib\\asyncio\\selector_events.py\", line 141, in _read_from_self\n",
      "    data = self._ssock.recv(4096)\n",
      "ConnectionResetError: [WinError 10054] An existing connection was forcibly closed by the remote host\n",
      "Exception in callback BaseSelectorEventLoop._read_from_self()\n",
      "handle: <Handle BaseSelectorEventLoop._read_from_self()>\n",
      "Traceback (most recent call last):\n",
      "  File \"C:\\Users\\donmc\\anaconda3\\envs\\PythonData\\lib\\asyncio\\events.py\", line 145, in _run\n",
      "    self._callback(*self._args)\n",
      "  File \"C:\\Users\\donmc\\anaconda3\\envs\\PythonData\\lib\\asyncio\\selector_events.py\", line 141, in _read_from_self\n",
      "    data = self._ssock.recv(4096)\n",
      "ConnectionResetError: [WinError 10054] An existing connection was forcibly closed by the remote host\n",
      "Exception in callback BaseSelectorEventLoop._read_from_self()\n",
      "handle: <Handle BaseSelectorEventLoop._read_from_self()>\n",
      "Traceback (most recent call last):\n",
      "  File \"C:\\Users\\donmc\\anaconda3\\envs\\PythonData\\lib\\asyncio\\events.py\", line 145, in _run\n",
      "    self._callback(*self._args)\n",
      "  File \"C:\\Users\\donmc\\anaconda3\\envs\\PythonData\\lib\\asyncio\\selector_events.py\", line 141, in _read_from_self\n",
      "    data = self._ssock.recv(4096)\n",
      "ConnectionResetError: [WinError 10054] An existing connection was forcibly closed by the remote host\n",
      "Exception in callback BaseSelectorEventLoop._read_from_self()\n",
      "handle: <Handle BaseSelectorEventLoop._read_from_self()>\n",
      "Traceback (most recent call last):\n",
      "  File \"C:\\Users\\donmc\\anaconda3\\envs\\PythonData\\lib\\asyncio\\events.py\", line 145, in _run\n",
      "    self._callback(*self._args)\n",
      "  File \"C:\\Users\\donmc\\anaconda3\\envs\\PythonData\\lib\\asyncio\\selector_events.py\", line 141, in _read_from_self\n",
      "    data = self._ssock.recv(4096)\n",
      "ConnectionResetError: [WinError 10054] An existing connection was forcibly closed by the remote host\n",
      "Exception in callback BaseSelectorEventLoop._read_from_self()\n",
      "handle: <Handle BaseSelectorEventLoop._read_from_self()>\n",
      "Traceback (most recent call last):\n",
      "  File \"C:\\Users\\donmc\\anaconda3\\envs\\PythonData\\lib\\asyncio\\events.py\", line 145, in _run\n",
      "    self._callback(*self._args)\n",
      "  File \"C:\\Users\\donmc\\anaconda3\\envs\\PythonData\\lib\\asyncio\\selector_events.py\", line 141, in _read_from_self\n",
      "    data = self._ssock.recv(4096)\n",
      "ConnectionResetError: [WinError 10054] An existing connection was forcibly closed by the remote host\n",
      "Exception in callback BaseSelectorEventLoop._read_from_self()\n",
      "handle: <Handle BaseSelectorEventLoop._read_from_self()>\n",
      "Traceback (most recent call last):\n",
      "  File \"C:\\Users\\donmc\\anaconda3\\envs\\PythonData\\lib\\asyncio\\events.py\", line 145, in _run\n",
      "    self._callback(*self._args)\n",
      "  File \"C:\\Users\\donmc\\anaconda3\\envs\\PythonData\\lib\\asyncio\\selector_events.py\", line 141, in _read_from_self\n",
      "    data = self._ssock.recv(4096)\n",
      "ConnectionResetError: [WinError 10054] An existing connection was forcibly closed by the remote host\n",
      "Exception in callback BaseSelectorEventLoop._read_from_self()\n",
      "handle: <Handle BaseSelectorEventLoop._read_from_self()>\n",
      "Traceback (most recent call last):\n",
      "  File \"C:\\Users\\donmc\\anaconda3\\envs\\PythonData\\lib\\asyncio\\events.py\", line 145, in _run\n",
      "    self._callback(*self._args)\n",
      "  File \"C:\\Users\\donmc\\anaconda3\\envs\\PythonData\\lib\\asyncio\\selector_events.py\", line 141, in _read_from_self\n",
      "    data = self._ssock.recv(4096)\n",
      "ConnectionResetError: [WinError 10054] An existing connection was forcibly closed by the remote host\n",
      "Exception in callback BaseSelectorEventLoop._read_from_self()\n",
      "handle: <Handle BaseSelectorEventLoop._read_from_self()>\n",
      "Traceback (most recent call last):\n",
      "  File \"C:\\Users\\donmc\\anaconda3\\envs\\PythonData\\lib\\asyncio\\events.py\", line 145, in _run\n",
      "    self._callback(*self._args)\n",
      "  File \"C:\\Users\\donmc\\anaconda3\\envs\\PythonData\\lib\\asyncio\\selector_events.py\", line 141, in _read_from_self\n",
      "    data = self._ssock.recv(4096)\n",
      "ConnectionResetError: [WinError 10054] An existing connection was forcibly closed by the remote host\n",
      "Exception in callback BaseSelectorEventLoop._read_from_self()\n",
      "handle: <Handle BaseSelectorEventLoop._read_from_self()>\n",
      "Traceback (most recent call last):\n",
      "  File \"C:\\Users\\donmc\\anaconda3\\envs\\PythonData\\lib\\asyncio\\events.py\", line 145, in _run\n",
      "    self._callback(*self._args)\n",
      "  File \"C:\\Users\\donmc\\anaconda3\\envs\\PythonData\\lib\\asyncio\\selector_events.py\", line 141, in _read_from_self\n",
      "    data = self._ssock.recv(4096)\n",
      "ConnectionResetError: [WinError 10054] An existing connection was forcibly closed by the remote host\n"
     ]
    },
    {
     "name": "stderr",
     "output_type": "stream",
     "text": [
      "Exception in callback BaseSelectorEventLoop._read_from_self()\n",
      "handle: <Handle BaseSelectorEventLoop._read_from_self()>\n",
      "Traceback (most recent call last):\n",
      "  File \"C:\\Users\\donmc\\anaconda3\\envs\\PythonData\\lib\\asyncio\\events.py\", line 145, in _run\n",
      "    self._callback(*self._args)\n",
      "  File \"C:\\Users\\donmc\\anaconda3\\envs\\PythonData\\lib\\asyncio\\selector_events.py\", line 141, in _read_from_self\n",
      "    data = self._ssock.recv(4096)\n",
      "ConnectionResetError: [WinError 10054] An existing connection was forcibly closed by the remote host\n",
      "Exception in callback BaseSelectorEventLoop._read_from_self()\n",
      "handle: <Handle BaseSelectorEventLoop._read_from_self()>\n",
      "Traceback (most recent call last):\n",
      "  File \"C:\\Users\\donmc\\anaconda3\\envs\\PythonData\\lib\\asyncio\\events.py\", line 145, in _run\n",
      "    self._callback(*self._args)\n",
      "  File \"C:\\Users\\donmc\\anaconda3\\envs\\PythonData\\lib\\asyncio\\selector_events.py\", line 141, in _read_from_self\n",
      "    data = self._ssock.recv(4096)\n",
      "ConnectionResetError: [WinError 10054] An existing connection was forcibly closed by the remote host\n",
      "Exception in callback BaseSelectorEventLoop._read_from_self()\n",
      "handle: <Handle BaseSelectorEventLoop._read_from_self()>\n",
      "Traceback (most recent call last):\n",
      "  File \"C:\\Users\\donmc\\anaconda3\\envs\\PythonData\\lib\\asyncio\\events.py\", line 145, in _run\n",
      "    self._callback(*self._args)\n",
      "  File \"C:\\Users\\donmc\\anaconda3\\envs\\PythonData\\lib\\asyncio\\selector_events.py\", line 141, in _read_from_self\n",
      "    data = self._ssock.recv(4096)\n",
      "ConnectionResetError: [WinError 10054] An existing connection was forcibly closed by the remote host\n",
      "Exception in callback BaseSelectorEventLoop._read_from_self()\n",
      "handle: <Handle BaseSelectorEventLoop._read_from_self()>\n",
      "Traceback (most recent call last):\n",
      "  File \"C:\\Users\\donmc\\anaconda3\\envs\\PythonData\\lib\\asyncio\\events.py\", line 145, in _run\n",
      "    self._callback(*self._args)\n",
      "  File \"C:\\Users\\donmc\\anaconda3\\envs\\PythonData\\lib\\asyncio\\selector_events.py\", line 141, in _read_from_self\n",
      "    data = self._ssock.recv(4096)\n",
      "ConnectionResetError: [WinError 10054] An existing connection was forcibly closed by the remote host\n",
      "Exception in callback BaseSelectorEventLoop._read_from_self()\n",
      "handle: <Handle BaseSelectorEventLoop._read_from_self()>\n",
      "Traceback (most recent call last):\n",
      "  File \"C:\\Users\\donmc\\anaconda3\\envs\\PythonData\\lib\\asyncio\\events.py\", line 145, in _run\n",
      "    self._callback(*self._args)\n",
      "  File \"C:\\Users\\donmc\\anaconda3\\envs\\PythonData\\lib\\asyncio\\selector_events.py\", line 141, in _read_from_self\n",
      "    data = self._ssock.recv(4096)\n",
      "ConnectionResetError: [WinError 10054] An existing connection was forcibly closed by the remote host\n",
      "Exception in callback BaseSelectorEventLoop._read_from_self()\n",
      "handle: <Handle BaseSelectorEventLoop._read_from_self()>\n",
      "Traceback (most recent call last):\n",
      "  File \"C:\\Users\\donmc\\anaconda3\\envs\\PythonData\\lib\\asyncio\\events.py\", line 145, in _run\n",
      "    self._callback(*self._args)\n",
      "  File \"C:\\Users\\donmc\\anaconda3\\envs\\PythonData\\lib\\asyncio\\selector_events.py\", line 141, in _read_from_self\n",
      "    data = self._ssock.recv(4096)\n",
      "ConnectionResetError: [WinError 10054] An existing connection was forcibly closed by the remote host\n",
      "Exception in callback BaseSelectorEventLoop._read_from_self()\n",
      "handle: <Handle BaseSelectorEventLoop._read_from_self()>\n",
      "Traceback (most recent call last):\n",
      "  File \"C:\\Users\\donmc\\anaconda3\\envs\\PythonData\\lib\\asyncio\\events.py\", line 145, in _run\n",
      "    self._callback(*self._args)\n",
      "  File \"C:\\Users\\donmc\\anaconda3\\envs\\PythonData\\lib\\asyncio\\selector_events.py\", line 141, in _read_from_self\n",
      "    data = self._ssock.recv(4096)\n",
      "ConnectionResetError: [WinError 10054] An existing connection was forcibly closed by the remote host\n",
      "Exception in callback BaseSelectorEventLoop._read_from_self()\n",
      "handle: <Handle BaseSelectorEventLoop._read_from_self()>\n",
      "Traceback (most recent call last):\n",
      "  File \"C:\\Users\\donmc\\anaconda3\\envs\\PythonData\\lib\\asyncio\\events.py\", line 145, in _run\n",
      "    self._callback(*self._args)\n",
      "  File \"C:\\Users\\donmc\\anaconda3\\envs\\PythonData\\lib\\asyncio\\selector_events.py\", line 141, in _read_from_self\n",
      "    data = self._ssock.recv(4096)\n",
      "ConnectionResetError: [WinError 10054] An existing connection was forcibly closed by the remote host\n",
      "Exception in callback BaseSelectorEventLoop._read_from_self()\n",
      "handle: <Handle BaseSelectorEventLoop._read_from_self()>\n",
      "Traceback (most recent call last):\n",
      "  File \"C:\\Users\\donmc\\anaconda3\\envs\\PythonData\\lib\\asyncio\\events.py\", line 145, in _run\n",
      "    self._callback(*self._args)\n",
      "  File \"C:\\Users\\donmc\\anaconda3\\envs\\PythonData\\lib\\asyncio\\selector_events.py\", line 141, in _read_from_self\n",
      "    data = self._ssock.recv(4096)\n",
      "ConnectionResetError: [WinError 10054] An existing connection was forcibly closed by the remote host\n",
      "Exception in callback BaseSelectorEventLoop._read_from_self()\n",
      "handle: <Handle BaseSelectorEventLoop._read_from_self()>\n",
      "Traceback (most recent call last):\n",
      "  File \"C:\\Users\\donmc\\anaconda3\\envs\\PythonData\\lib\\asyncio\\events.py\", line 145, in _run\n",
      "    self._callback(*self._args)\n",
      "  File \"C:\\Users\\donmc\\anaconda3\\envs\\PythonData\\lib\\asyncio\\selector_events.py\", line 141, in _read_from_self\n",
      "    data = self._ssock.recv(4096)\n",
      "ConnectionResetError: [WinError 10054] An existing connection was forcibly closed by the remote host\n",
      "Exception in callback BaseSelectorEventLoop._read_from_self()\n",
      "handle: <Handle BaseSelectorEventLoop._read_from_self()>\n",
      "Traceback (most recent call last):\n",
      "  File \"C:\\Users\\donmc\\anaconda3\\envs\\PythonData\\lib\\asyncio\\events.py\", line 145, in _run\n",
      "    self._callback(*self._args)\n",
      "  File \"C:\\Users\\donmc\\anaconda3\\envs\\PythonData\\lib\\asyncio\\selector_events.py\", line 141, in _read_from_self\n",
      "    data = self._ssock.recv(4096)\n",
      "ConnectionResetError: [WinError 10054] An existing connection was forcibly closed by the remote host\n",
      "Exception in callback BaseSelectorEventLoop._read_from_self()\n",
      "handle: <Handle BaseSelectorEventLoop._read_from_self()>\n",
      "Traceback (most recent call last):\n",
      "  File \"C:\\Users\\donmc\\anaconda3\\envs\\PythonData\\lib\\asyncio\\events.py\", line 145, in _run\n",
      "    self._callback(*self._args)\n",
      "  File \"C:\\Users\\donmc\\anaconda3\\envs\\PythonData\\lib\\asyncio\\selector_events.py\", line 141, in _read_from_self\n",
      "    data = self._ssock.recv(4096)\n",
      "ConnectionResetError: [WinError 10054] An existing connection was forcibly closed by the remote host\n",
      "Exception in callback BaseSelectorEventLoop._read_from_self()\n",
      "handle: <Handle BaseSelectorEventLoop._read_from_self()>\n",
      "Traceback (most recent call last):\n",
      "  File \"C:\\Users\\donmc\\anaconda3\\envs\\PythonData\\lib\\asyncio\\events.py\", line 145, in _run\n",
      "    self._callback(*self._args)\n",
      "  File \"C:\\Users\\donmc\\anaconda3\\envs\\PythonData\\lib\\asyncio\\selector_events.py\", line 141, in _read_from_self\n",
      "    data = self._ssock.recv(4096)\n",
      "ConnectionResetError: [WinError 10054] An existing connection was forcibly closed by the remote host\n",
      "Exception in callback BaseSelectorEventLoop._read_from_self()\n",
      "handle: <Handle BaseSelectorEventLoop._read_from_self()>\n",
      "Traceback (most recent call last):\n",
      "  File \"C:\\Users\\donmc\\anaconda3\\envs\\PythonData\\lib\\asyncio\\events.py\", line 145, in _run\n",
      "    self._callback(*self._args)\n",
      "  File \"C:\\Users\\donmc\\anaconda3\\envs\\PythonData\\lib\\asyncio\\selector_events.py\", line 141, in _read_from_self\n",
      "    data = self._ssock.recv(4096)\n",
      "ConnectionResetError: [WinError 10054] An existing connection was forcibly closed by the remote host\n",
      "Exception in callback BaseSelectorEventLoop._read_from_self()\n",
      "handle: <Handle BaseSelectorEventLoop._read_from_self()>\n",
      "Traceback (most recent call last):\n",
      "  File \"C:\\Users\\donmc\\anaconda3\\envs\\PythonData\\lib\\asyncio\\events.py\", line 145, in _run\n",
      "    self._callback(*self._args)\n",
      "  File \"C:\\Users\\donmc\\anaconda3\\envs\\PythonData\\lib\\asyncio\\selector_events.py\", line 141, in _read_from_self\n",
      "    data = self._ssock.recv(4096)\n",
      "ConnectionResetError: [WinError 10054] An existing connection was forcibly closed by the remote host\n",
      "Exception in callback BaseSelectorEventLoop._read_from_self()\n",
      "handle: <Handle BaseSelectorEventLoop._read_from_self()>\n",
      "Traceback (most recent call last):\n",
      "  File \"C:\\Users\\donmc\\anaconda3\\envs\\PythonData\\lib\\asyncio\\events.py\", line 145, in _run\n",
      "    self._callback(*self._args)\n",
      "  File \"C:\\Users\\donmc\\anaconda3\\envs\\PythonData\\lib\\asyncio\\selector_events.py\", line 141, in _read_from_self\n",
      "    data = self._ssock.recv(4096)\n",
      "ConnectionResetError: [WinError 10054] An existing connection was forcibly closed by the remote host\n"
     ]
    },
    {
     "name": "stderr",
     "output_type": "stream",
     "text": [
      "Exception in callback BaseSelectorEventLoop._read_from_self()\n",
      "handle: <Handle BaseSelectorEventLoop._read_from_self()>\n",
      "Traceback (most recent call last):\n",
      "  File \"C:\\Users\\donmc\\anaconda3\\envs\\PythonData\\lib\\asyncio\\events.py\", line 145, in _run\n",
      "    self._callback(*self._args)\n",
      "  File \"C:\\Users\\donmc\\anaconda3\\envs\\PythonData\\lib\\asyncio\\selector_events.py\", line 141, in _read_from_self\n",
      "    data = self._ssock.recv(4096)\n",
      "ConnectionResetError: [WinError 10054] An existing connection was forcibly closed by the remote host\n",
      "Exception in callback BaseSelectorEventLoop._read_from_self()\n",
      "handle: <Handle BaseSelectorEventLoop._read_from_self()>\n",
      "Traceback (most recent call last):\n",
      "  File \"C:\\Users\\donmc\\anaconda3\\envs\\PythonData\\lib\\asyncio\\events.py\", line 145, in _run\n",
      "    self._callback(*self._args)\n",
      "  File \"C:\\Users\\donmc\\anaconda3\\envs\\PythonData\\lib\\asyncio\\selector_events.py\", line 141, in _read_from_self\n",
      "    data = self._ssock.recv(4096)\n",
      "ConnectionResetError: [WinError 10054] An existing connection was forcibly closed by the remote host\n",
      "Exception in callback BaseSelectorEventLoop._read_from_self()\n",
      "handle: <Handle BaseSelectorEventLoop._read_from_self()>\n",
      "Traceback (most recent call last):\n",
      "  File \"C:\\Users\\donmc\\anaconda3\\envs\\PythonData\\lib\\asyncio\\events.py\", line 145, in _run\n",
      "    self._callback(*self._args)\n",
      "  File \"C:\\Users\\donmc\\anaconda3\\envs\\PythonData\\lib\\asyncio\\selector_events.py\", line 141, in _read_from_self\n",
      "    data = self._ssock.recv(4096)\n",
      "ConnectionResetError: [WinError 10054] An existing connection was forcibly closed by the remote host\n",
      "Exception in callback BaseSelectorEventLoop._read_from_self()\n",
      "handle: <Handle BaseSelectorEventLoop._read_from_self()>\n",
      "Traceback (most recent call last):\n",
      "  File \"C:\\Users\\donmc\\anaconda3\\envs\\PythonData\\lib\\asyncio\\events.py\", line 145, in _run\n",
      "    self._callback(*self._args)\n",
      "  File \"C:\\Users\\donmc\\anaconda3\\envs\\PythonData\\lib\\asyncio\\selector_events.py\", line 141, in _read_from_self\n",
      "    data = self._ssock.recv(4096)\n",
      "ConnectionResetError: [WinError 10054] An existing connection was forcibly closed by the remote host\n",
      "Exception in callback BaseSelectorEventLoop._read_from_self()\n",
      "handle: <Handle BaseSelectorEventLoop._read_from_self()>\n",
      "Traceback (most recent call last):\n",
      "  File \"C:\\Users\\donmc\\anaconda3\\envs\\PythonData\\lib\\asyncio\\events.py\", line 145, in _run\n",
      "    self._callback(*self._args)\n",
      "  File \"C:\\Users\\donmc\\anaconda3\\envs\\PythonData\\lib\\asyncio\\selector_events.py\", line 141, in _read_from_self\n",
      "    data = self._ssock.recv(4096)\n",
      "ConnectionResetError: [WinError 10054] An existing connection was forcibly closed by the remote host\n",
      "Exception in callback BaseSelectorEventLoop._read_from_self()\n",
      "handle: <Handle BaseSelectorEventLoop._read_from_self()>\n",
      "Traceback (most recent call last):\n",
      "  File \"C:\\Users\\donmc\\anaconda3\\envs\\PythonData\\lib\\asyncio\\events.py\", line 145, in _run\n",
      "    self._callback(*self._args)\n",
      "  File \"C:\\Users\\donmc\\anaconda3\\envs\\PythonData\\lib\\asyncio\\selector_events.py\", line 141, in _read_from_self\n",
      "    data = self._ssock.recv(4096)\n",
      "ConnectionResetError: [WinError 10054] An existing connection was forcibly closed by the remote host\n",
      "Exception in callback BaseSelectorEventLoop._read_from_self()\n",
      "handle: <Handle BaseSelectorEventLoop._read_from_self()>\n",
      "Traceback (most recent call last):\n",
      "  File \"C:\\Users\\donmc\\anaconda3\\envs\\PythonData\\lib\\asyncio\\events.py\", line 145, in _run\n",
      "    self._callback(*self._args)\n",
      "  File \"C:\\Users\\donmc\\anaconda3\\envs\\PythonData\\lib\\asyncio\\selector_events.py\", line 141, in _read_from_self\n",
      "    data = self._ssock.recv(4096)\n",
      "ConnectionResetError: [WinError 10054] An existing connection was forcibly closed by the remote host\n",
      "Exception in callback BaseSelectorEventLoop._read_from_self()\n",
      "handle: <Handle BaseSelectorEventLoop._read_from_self()>\n",
      "Traceback (most recent call last):\n",
      "  File \"C:\\Users\\donmc\\anaconda3\\envs\\PythonData\\lib\\asyncio\\events.py\", line 145, in _run\n",
      "    self._callback(*self._args)\n",
      "  File \"C:\\Users\\donmc\\anaconda3\\envs\\PythonData\\lib\\asyncio\\selector_events.py\", line 141, in _read_from_self\n",
      "    data = self._ssock.recv(4096)\n",
      "ConnectionResetError: [WinError 10054] An existing connection was forcibly closed by the remote host\n"
     ]
    }
   ],
   "source": [
    "# 9. Calculate and print out the summary statistics for the Decemeber temperature DataFrame.\n",
    "december_df.describe()"
   ]
  },
  {
   "cell_type": "code",
   "execution_count": null,
   "metadata": {},
   "outputs": [],
   "source": []
  }
 ],
 "metadata": {
  "kernelspec": {
   "display_name": "PythonData",
   "language": "python",
   "name": "pythondata"
  },
  "language_info": {
   "codemirror_mode": {
    "name": "ipython",
    "version": 3
   },
   "file_extension": ".py",
   "mimetype": "text/x-python",
   "name": "python",
   "nbconvert_exporter": "python",
   "pygments_lexer": "ipython3",
   "version": "3.6.7"
  }
 },
 "nbformat": 4,
 "nbformat_minor": 2
}
